Workbook

Sheet Iluminacion y ventilacion
A1: PLANILLA DE ILUMINACION Y VENTILACION
A2: Local | B2: (a) Medidas | C2: (b) Medidas | D2: (Area) Medidas | E2: Iluminacion | H2: Ventilacion | K2: VERIFICACION | L2: OBSERVACIONES
E3: Coef. | F3: Area requerida | G3: Area proyectada | H3: Coef. | I3: Area requerida | J3: Area proyectada
A4: PB
A5: 01 - Cocina / comedor | B5: 7.63 | C5: 3.56 | D5: =B5*C5 -> 27.1628 | E5: 9 | F5: =D5/E5 -> 3.0180889 | G5: 16.95 | H5: i/3 | I5: =F5/3 -> 1.0060296 | J5: 8.48 | K5: =IF(OR(G5="COND",J5="COND"),"COND",IF(AND(G5>=F5,J5>=I5),"CUMPLE","NO CUMPLE")) -> CUMPLE
A6: 02 - Deposito | B6: 3.8 | C6: 3.1 | D6: =B6*C6 -> 11.78 | E6: - | F6: - | G6: - | H6: - | I6: - | J6: - | K6: NO EXIGIBLE | L6: Local no habitable: el codigo no le exige iluminacion ni ventilacion natural. Si se lo considera habitable, hay que preverle conducto.
A7: 03 - Lavadero | B7: 3.5 | C7: 1.7 | D7: =B7*C7 -> 5.95 | E7: 9 | F7: =D7/E7 -> 0.66111111 | G7: 10.5 | H7: i/3 | I7: =F7/3 -> 0.22037037 | J7: 1.6 | K7: =IF(OR(G7="COND",J7="COND"),"COND",IF(AND(G7>=F7,J7>=I7),"CUMPLE","NO CUMPLE")) -> CUMPLE
A8: 06 - Living / comedor | B8: 8.66 | C8: 4.06 | D8: =B8*C8 -> 35.1596 | E8: 9 | F8: =D8/E8 -> 3.9066222 | G8: 34.05 | H8: i/3 | I8: =F8/3 -> 1.3022074 | J8: 15 | K8: =IF(OR(G8="COND",J8="COND"),"COND",IF(AND(G8>=F8,J8>=I8),"CUMPLE","NO CUMPLE")) -> CUMPLE
A9: 07 - Hall / ingreso | B9: 4 | C9: 2.15 | D9: =B9*C9 -> 8.6 | E9: 9 | F9: =D9/E9 -> 0.95555556 | G9: 10.5 | H9: i/3 | I9: =F9/3 -> 0.31851852 | J9: 1.6 | K9: =IF(OR(G9="COND",J9="COND"),"COND",IF(AND(G9>=F9,J9>=I9),"CUMPLE","NO CUMPLE")) -> CUMPLE | L9: CORREGIDO: la planilla original repetia los valores del local 03 (0,66 y 0,22). Con 4,00 x 2,15 = 8,60 m2 corresponden 0,96 y 0,32. Cumple igual.
A10: 09 - Dormitorio suite | B10: 3.5 | C10: 3.5 | D10: =B10*C10 -> 12.25 | E10: 9 | F10: =D10/E10 -> 1.3611111 | G10: 6 | H10: i/3 | I10: =F10/3 -> 0.4537037 | J10: 3 | K10: =IF(OR(G10="COND",J10="COND"),"COND",IF(AND(G10>=F10,J10>=I10),"CUMPLE","NO CUMPLE")) -> CUMPLE
A11: 10 - Bano suite | B11: 3.38 | C11: 1.72 | D11: =B11*C11 -> 5.8136 | E11: 9 | F11: =D11/E11 -> 0.64595556 | G11: COND | H11: i/3 | I11: =F11/3 -> 0.21531852 | J11: COND | K11: =IF(OR(G11="COND",J11="COND"),"COND",IF(AND(G11>=F11,J11>=I11),"CUMPLE","NO CUMPLE")) -> COND | L11: Sin ventana al exterior: se ventila por conducto o extraccion mecanica.
A12: 11 - Bano visita | B12: 2.4 | C12: 1.3 | D12: =B12*C12 -> 3.12 | E12: 9 | F12: =D12/E12 -> 0.34666667 | G12: COND | H12: i/3 | I12: =F12/3 -> 0.11555556 | J12: COND | K12: =IF(OR(G12="COND",J12="COND"),"COND",IF(AND(G12>=F12,J12>=I12),"CUMPLE","NO CUMPLE")) -> COND | L12: Sin ventana al exterior: se ventila por conducto o extraccion mecanica.
A13: 12 - Bano exterior | B13: 1.9 | C13: 0.95 | D13: =B13*C13 -> 1.805 | E13: 9 | F13: =D13/E13 -> 0.20055556 | G13: COND | H13: i/3 | I13: =F13/3 -> 0.066851852 | J13: COND | K13: =IF(OR(G13="COND",J13="COND"),"COND",IF(AND(G13>=F13,J13>=I13),"CUMPLE","NO CUMPLE")) -> COND | L13: Sin ventana al exterior: se ventila por conducto o extraccion mecanica.
A14: PA
A15: 13 - Dormitorio 1 | B15: 4.25 | C15: 4 | D15: =B15*C15 -> 17 | E15: 9 | F15: =D15/E15 -> 1.8888889 | G15: 8.75 | H15: i/3 | I15: =F15/3 -> 0.62962963 | J15: 4.38 | K15: =IF(OR(G15="COND",J15="COND"),"COND",IF(AND(G15>=F15,J15>=I15),"CUMPLE","NO CUMPLE")) -> CUMPLE
A16: 14 - Estar / Playroom | B16: 4.13 | C16: 4.08 | D16: =B16*C16 -> 16.8504 | E16: 9 | F16: =D16/E16 -> 1.8722667 | G16: 5 | H16: i/3 | I16: =F16/3 -> 0.62408889 | J16: 5 | K16: =IF(OR(G16="COND",J16="COND"),"COND",IF(AND(G16>=F16,J16>=I16),"CUMPLE","NO CUMPLE")) -> CUMPLE | L16: La superficie abrible declarada iguala a la vidriada: supondria una carpinteria 100% abrible. En el resto de los locales la relacion es del 50%. Verificar.
A17: 15 - Dormitorio 2 | B17: 3.5 | C17: 4.05 | D17: =B17*C17 -> 14.175 | E17: 9 | F17: =D17/E17 -> 1.575 | G17: 3.75 | H17: i/3 | I17: =F17/3 -> 0.525 | J17: 1.88 | K17: =IF(OR(G17="COND",J17="COND"),"COND",IF(AND(G17>=F17,J17>=I17),"CUMPLE","NO CUMPLE")) -> CUMPLE
A18: 17 - Bano | B18: 2.2 | C18: 1.6 | D18: =B18*C18 -> 3.52 | E18: 9 | F18: =D18/E18 -> 0.39111111 | G18: 1.875 | H18: i/3 | I18: =F18/3 -> 0.13037037 | J18: 0.94 | K18: =IF(OR(G18="COND",J18="COND"),"COND",IF(AND(G18>=F18,J18>=I18),"CUMPLE","NO CUMPLE")) -> CUMPLE
A20: En amarillo, las medidas corregidas al relevar los locales para el balance termico.

Sheet Planilla 3 higrotermica
B1: Municipalidad de Rosario | M1: ORDENANZA N 8757/11
B2: Secretaria de Planeamiento - Programa de Construcciones Sustentables y Eficiencia Energetica
B3: Solicitud del Certificado de Aspectos Higrotermicos y Eficiencia Energetica de las Construcciones
A4: PLANILLA 3: Verificacion de transmitancia termica y factor de exposicion solar de cerramientos transparentes.
A5: Descripcion | B5: Altura del vano | C5: Ancho del vano | D5: Area del vano | E5: Area total vanos (m2) | F5: Porcentaje sup. de vanos | G5: Transmit. Max. [W/m2K] | H5: Tipo de vidrio | I5: Tipo de proteccion | J5: Transmit. [W/m2K] | K5: Orientacion | L5: Factor de Expos. Solar | M5: VERIFICACION
A6: Plano: Fachada Noreste
A7: PA02 | B7: 3 | C7: 0.75 | D7: =IF(COUNT(B7,C7)<2,"",B7*C7) -> 2.25 | E7: =SUM(D7:D13) -> 12.9225 | F7: =IF(OR(D7="",$E$7=""),"",D7/$E$7) -> 0.17411492 | G7: =IF(A7="","",Datos_higro!$B$4) -> 2.9 | H7: DVH 6+9+3+3 (aluminio linea A30) | I7: Sin Proteccion | J7: 2.8 | K7: Noreste | L7: =IF(I7="","",IFERROR(VLOOKUP(I7,Datos_higro!$A$21:$B$28,2,0),"")) -> 0.88 | M7: =IF(OR(D7="",J7=""),"",IF(J7<=G7,"CUMPLE","NO CUMPLE")) -> CUMPLE
A8: VA02 | B8: 2.15 | C8: 0.75 | D8: =IF(COUNT(B8,C8)<2,"",B8*C8) -> 1.6125 | F8: =IF(OR(D8="",$E$7=""),"",D8/$E$7) -> 0.12478236 | G8: =IF(A8="","",Datos_higro!$B$4) -> 2.9 | H8: DVH 6+9+3+3 (aluminio linea A30) | I8: Sin Proteccion | J8: 2.8 | K8: Noreste | L8: =IF(I8="","",IFERROR(VLOOKUP(I8,Datos_higro!$A$21:$B$28,2,0),"")) -> 0.88 | M8: =IF(OR(D8="",J8=""),"",IF(J8<=G8,"CUMPLE","NO CUMPLE")) -> CUMPLE
A9: PV03 | B9: 3 | C9: 1.76 | D9: =IF(COUNT(B9,C9)<2,"",B9*C9) -> 5.28 | F9: =IF(OR(D9="",$E$7=""),"",D9/$E$7) -> 0.40858967 | G9: =IF(A9="","",Datos_higro!$B$4) -> 2.9 | H9: DVH 6+9+3+3 (aluminio linea A30) | I9: Sin Proteccion | J9: 2.8 | K9: Noreste | L9: =IF(I9="","",IFERROR(VLOOKUP(I9,Datos_higro!$A$21:$B$28,2,0),"")) -> 0.88 | M9: =IF(OR(D9="",J9=""),"",IF(J9<=G9,"CUMPLE","NO CUMPLE")) -> CUMPLE
A10: VA03 | B10: 2.52 | C10: 0.75 | D10: =IF(COUNT(B10,C10)<2,"",B10*C10) -> 1.89 | F10: =IF(OR(D10="",$E$7=""),"",D10/$E$7) -> 0.14625653 | G10: =IF(A10="","",Datos_higro!$B$4) -> 2.9 | H10: DVH 6+9+3+3 (aluminio linea A30) | I10: Sin Proteccion | J10: 2.8 | K10: Noreste | L10: =IF(I10="","",IFERROR(VLOOKUP(I10,Datos_higro!$A$21:$B$28,2,0),"")) -> 0.88 | M10: =IF(OR(D10="",J10=""),"",IF(J10<=G10,"CUMPLE","NO CUMPLE")) -> CUMPLE
A11: PF05 | B11: 2.52 | C11: 0.75 | D11: =IF(COUNT(B11,C11)<2,"",B11*C11) -> 1.89 | F11: =IF(OR(D11="",$E$7=""),"",D11/$E$7) -> 0.14625653 | G11: =IF(A11="","",Datos_higro!$B$4) -> 2.9 | H11: DVH 6+9+3+3 (aluminio linea A30) | I11: Sin Proteccion | J11: 2.8 | K11: Noreste | L11: =IF(I11="","",IFERROR(VLOOKUP(I11,Datos_higro!$A$21:$B$28,2,0),"")) -> 0.88 | M11: =IF(OR(D11="",J11=""),"",IF(J11<=G11,"CUMPLE","NO CUMPLE")) -> CUMPLE
D12: =IF(COUNT(B12,C12)<2,"",B12*C12) | F12: =IF(OR(D12="",$E$7=""),"",D12/$E$7) | G12: =IF(A12="","",Datos_higro!$B$4) | L12: =IF(I12="","",IFERROR(VLOOKUP(I12,Datos_higro!$A$21:$B$28,2,0),"")) | M12: =IF(OR(D12="",J12=""),"",IF(J12<=G12,"CUMPLE","NO CUMPLE"))
D13: =IF(COUNT(B13,C13)<2,"",B13*C13) | F13: =IF(OR(D13="",$E$7=""),"",D13/$E$7) | G13: =IF(A13="","",Datos_higro!$B$4) | L13: =IF(I13="","",IFERROR(VLOOKUP(I13,Datos_higro!$A$21:$B$28,2,0),"")) | M13: =IF(OR(D13="",J13=""),"",IF(J13<=G13,"CUMPLE","NO CUMPLE"))
A14: Plano: Fachada Sudoeste
A15: PA01 | B15: 3 | C15: 1 | D15: =IF(COUNT(B15,C15)<2,"",B15*C15) -> 3 | E15: =SUM(D15:D21) -> 19.77 | F15: =IF(OR(D15="",$E$15=""),"",D15/$E$15) -> 0.15174507 | G15: =IF(A15="","",Datos_higro!$B$4) -> 2.9 | H15: DVH 6+9+3+3 (aluminio linea A30) | I15: Sin Proteccion | J15: 2.8 | K15: Sudoeste | L15: =IF(I15="","",IFERROR(VLOOKUP(I15,Datos_higro!$A$21:$B$28,2,0),"")) -> 0.88 | M15: =IF(OR(D15="",J15=""),"",IF(J15<=G15,"CUMPLE","NO CUMPLE")) -> CUMPLE
A16: PF01 | B16: 3 | C16: 3.55 | D16: =IF(COUNT(B16,C16)<2,"",B16*C16) -> 10.65 | F16: =IF(OR(D16="",$E$15=""),"",D16/$E$15) -> 0.53869499 | G16: =IF(A16="","",Datos_higro!$B$4) -> 2.9 | H16: DVH 6+9+3+3 (aluminio linea A30) | I16: Sin Proteccion | J16: 2.8 | K16: Sudoeste | L16: =IF(I16="","",IFERROR(VLOOKUP(I16,Datos_higro!$A$21:$B$28,2,0),"")) -> 0.88 | M16: =IF(OR(D16="",J16=""),"",IF(J16<=G16,"CUMPLE","NO CUMPLE")) -> CUMPLE
A17: PF04 | B17: 0.6 | C17: 2.7 | D17: =IF(COUNT(B17,C17)<2,"",B17*C17) -> 1.62 | F17: =IF(OR(D17="",$E$15=""),"",D17/$E$15) -> 0.081942337 | G17: =IF(A17="","",Datos_higro!$B$4) -> 2.9 | H17: DVH 6+9+3+3 (aluminio linea A30) | I17: Sin Proteccion | J17: 2.8 | K17: Sudoeste | L17: =IF(I17="","",IFERROR(VLOOKUP(I17,Datos_higro!$A$21:$B$28,2,0),"")) -> 0.88 | M17: =IF(OR(D17="",J17=""),"",IF(J17<=G17,"CUMPLE","NO CUMPLE")) -> CUMPLE
A18: VA01 | B18: 3 | C18: 0.75 | D18: =IF(COUNT(B18,C18)<2,"",B18*C18) -> 2.25 | F18: =IF(OR(D18="",$E$15=""),"",D18/$E$15) -> 0.1138088 | G18: =IF(A18="","",Datos_higro!$B$4) -> 2.9 | H18: DVH 6+9+3+3 (aluminio linea A30) | I18: Sin Proteccion | J18: 2.8 | K18: Sudoeste | L18: =IF(I18="","",IFERROR(VLOOKUP(I18,Datos_higro!$A$21:$B$28,2,0),"")) -> 0.88 | M18: =IF(OR(D18="",J18=""),"",IF(J18<=G18,"CUMPLE","NO CUMPLE")) -> CUMPLE
A19: VA01 | B19: 3 | C19: 0.75 | D19: =IF(COUNT(B19,C19)<2,"",B19*C19) -> 2.25 | F19: =IF(OR(D19="",$E$15=""),"",D19/$E$15) -> 0.1138088 | G19: =IF(A19="","",Datos_higro!$B$4) -> 2.9 | H19: DVH 6+9+3+3 (aluminio linea A30) | I19: Sin Proteccion | J19: 2.8 | K19: Sudoeste | L19: =IF(I19="","",IFERROR(VLOOKUP(I19,Datos_higro!$A$21:$B$28,2,0),"")) -> 0.88 | M19: =IF(OR(D19="",J19=""),"",IF(J19<=G19,"CUMPLE","NO CUMPLE")) -> CUMPLE
D20: =IF(COUNT(B20,C20)<2,"",B20*C20) | F20: =IF(OR(D20="",$E$15=""),"",D20/$E$15) | G20: =IF(A20="","",Datos_higro!$B$4) | L20: =IF(I20="","",IFERROR(VLOOKUP(I20,Datos_higro!$A$21:$B$28,2,0),"")) | M20: =IF(OR(D20="",J20=""),"",IF(J20<=G20,"CUMPLE","NO CUMPLE"))
D21: =IF(COUNT(B21,C21)<2,"",B21*C21) | F21: =IF(OR(D21="",$E$15=""),"",D21/$E$15) | G21: =IF(A21="","",Datos_higro!$B$4) | L21: =IF(I21="","",IFERROR(VLOOKUP(I21,Datos_higro!$A$21:$B$28,2,0),"")) | M21: =IF(OR(D21="",J21=""),"",IF(J21<=G21,"CUMPLE","NO CUMPLE"))
A22: Plano: Fachada Sudeste
A23: PF02 | B23: 3 | C23: 3.75 | D23: =IF(COUNT(B23,C23)<2,"",B23*C23) -> 11.25 | E23: =SUM(D23:D27) -> 20.958 | F23: =IF(OR(D23="",$E$23=""),"",D23/$E$23) -> 0.53678786 | G23: =IF(A23="","",Datos_higro!$B$4) -> 2.9 | H23: DVH 6+9+3+3 (aluminio linea A30) | I23: Sin Proteccion | J23: 2.8 | K23: Sudeste | L23: =IF(I23="","",IFERROR(VLOOKUP(I23,Datos_higro!$A$21:$B$28,2,0),"")) -> 0.88 | M23: =IF(OR(D23="",J23=""),"",IF(J23<=G23,"CUMPLE","NO CUMPLE")) -> CUMPLE
A24: PV04 | B24: 3 | C24: 2.06 | D24: =IF(COUNT(B24,C24)<2,"",B24*C24) -> 6.18 | F24: =IF(OR(D24="",$E$23=""),"",D24/$E$23) -> 0.29487547 | G24: =IF(A24="","",Datos_higro!$B$4) -> 2.9 | H24: DVH 6+9+3+3 (aluminio linea A30) | I24: Sin Proteccion | J24: 2.8 | K24: Sudeste | L24: =IF(I24="","",IFERROR(VLOOKUP(I24,Datos_higro!$A$21:$B$28,2,0),"")) -> 0.88 | M24: =IF(OR(D24="",J24=""),"",IF(J24<=G24,"CUMPLE","NO CUMPLE")) -> CUMPLE
A25: VA05 | B25: 2.52 | C25: 1.4 | D25: =IF(COUNT(B25,C25)<2,"",B25*C25) -> 3.528 | F25: =IF(OR(D25="",$E$23=""),"",D25/$E$23) -> 0.16833667 | G25: =IF(A25="","",Datos_higro!$B$4) -> 2.9 | H25: DVH 6+9+3+3 (aluminio linea A30) | I25: Sin Proteccion | J25: 2.8 | K25: Sudeste | L25: =IF(I25="","",IFERROR(VLOOKUP(I25,Datos_higro!$A$21:$B$28,2,0),"")) -> 0.88 | M25: =IF(OR(D25="",J25=""),"",IF(J25<=G25,"CUMPLE","NO CUMPLE")) -> CUMPLE
D26: =IF(COUNT(B26,C26)<2,"",B26*C26) | F26: =IF(OR(D26="",$E$23=""),"",D26/$E$23) | G26: =IF(A26="","",Datos_higro!$B$4) | L26: =IF(I26="","",IFERROR(VLOOKUP(I26,Datos_higro!$A$21:$B$28,2,0),"")) | M26: =IF(OR(D26="",J26=""),"",IF(J26<=G26,"CUMPLE","NO CUMPLE"))
D27: =IF(COUNT(B27,C27)<2,"",B27*C27) | F27: =IF(OR(D27="",$E$23=""),"",D27/$E$23) | G27: =IF(A27="","",Datos_higro!$B$4) | L27: =IF(I27="","",IFERROR(VLOOKUP(I27,Datos_higro!$A$21:$B$28,2,0),"")) | M27: =IF(OR(D27="",J27=""),"",IF(J27<=G27,"CUMPLE","NO CUMPLE"))
A28: Plano: Fachada Noroeste
A29: PF03 | B29: 3 | C29: 2.88 | D29: =IF(COUNT(B29,C29)<2,"",B29*C29) -> 8.64 | E29: =SUM(D29:D36) -> 59.91 | F29: =IF(OR(D29="",$E$29=""),"",D29/$E$29) -> 0.14421632 | G29: =IF(A29="","",Datos_higro!$B$4) -> 2.9 | H29: DVH 6+9+3+3 (aluminio linea A30) | I29: Sin Proteccion | J29: 2.8 | K29: Noroeste | L29: =IF(I29="","",IFERROR(VLOOKUP(I29,Datos_higro!$A$21:$B$28,2,0),"")) -> 0.88 | M29: =IF(OR(D29="",J29=""),"",IF(J29<=G29,"CUMPLE","NO CUMPLE")) -> CUMPLE
A30: PF01 | B30: 3 | C30: 3.55 | D30: =IF(COUNT(B30,C30)<2,"",B30*C30) -> 10.65 | F30: =IF(OR(D30="",$E$29=""),"",D30/$E$29) -> 0.17776665 | G30: =IF(A30="","",Datos_higro!$B$4) -> 2.9 | H30: DVH 6+9+3+3 (aluminio linea A30) | I30: Sin Proteccion | J30: 2.8 | K30: Noroeste | L30: =IF(I30="","",IFERROR(VLOOKUP(I30,Datos_higro!$A$21:$B$28,2,0),"")) -> 0.88 | M30: =IF(OR(D30="",J30=""),"",IF(J30<=G30,"CUMPLE","NO CUMPLE")) -> CUMPLE
A31: PV01 | B31: 3 | C31: 7.7 | D31: =IF(COUNT(B31,C31)<2,"",B31*C31) -> 23.1 | F31: =IF(OR(D31="",$E$29=""),"",D31/$E$29) -> 0.38557837 | G31: =IF(A31="","",Datos_higro!$B$4) -> 2.9 | H31: DVH 6+9+3+3 (aluminio linea A30) | I31: Sin Proteccion | J31: 2.8 | K31: Noroeste | L31: =IF(I31="","",IFERROR(VLOOKUP(I31,Datos_higro!$A$21:$B$28,2,0),"")) -> 0.88 | M31: =IF(OR(D31="",J31=""),"",IF(J31<=G31,"CUMPLE","NO CUMPLE")) -> CUMPLE
A32: PV02 | B32: 3 | C32: 2.48 | D32: =IF(COUNT(B32,C32)<2,"",B32*C32) -> 7.44 | F32: =IF(OR(D32="",$E$29=""),"",D32/$E$29) -> 0.12418628 | G32: =IF(A32="","",Datos_higro!$B$4) -> 2.9 | H32: DVH 6+9+3+3 (aluminio linea A30) | I32: Sin Proteccion | J32: 2.8 | K32: Noroeste | L32: =IF(I32="","",IFERROR(VLOOKUP(I32,Datos_higro!$A$21:$B$28,2,0),"")) -> 0.88 | M32: =IF(OR(D32="",J32=""),"",IF(J32<=G32,"CUMPLE","NO CUMPLE")) -> CUMPLE
A33: VA04 | B33: 2.52 | C33: 2 | D33: =IF(COUNT(B33,C33)<2,"",B33*C33) -> 5.04 | F33: =IF(OR(D33="",$E$29=""),"",D33/$E$29) -> 0.084126189 | G33: =IF(A33="","",Datos_higro!$B$4) -> 2.9 | H33: DVH 6+9+3+3 (aluminio linea A30) | I33: Sin Proteccion | J33: 2.8 | K33: Noroeste | L33: =IF(I33="","",IFERROR(VLOOKUP(I33,Datos_higro!$A$21:$B$28,2,0),"")) -> 0.88 | M33: =IF(OR(D33="",J33=""),"",IF(J33<=G33,"CUMPLE","NO CUMPLE")) -> CUMPLE
A34: VA04 | B34: 2.52 | C34: 2 | D34: =IF(COUNT(B34,C34)<2,"",B34*C34) -> 5.04 | F34: =IF(OR(D34="",$E$29=""),"",D34/$E$29) -> 0.084126189 | G34: =IF(A34="","",Datos_higro!$B$4) -> 2.9 | H34: DVH 6+9+3+3 (aluminio linea A30) | I34: Sin Proteccion | J34: 2.8 | K34: Noroeste | L34: =IF(I34="","",IFERROR(VLOOKUP(I34,Datos_higro!$A$21:$B$28,2,0),"")) -> 0.88 | M34: =IF(OR(D34="",J34=""),"",IF(J34<=G34,"CUMPLE","NO CUMPLE")) -> CUMPLE
D35: =IF(COUNT(B35,C35)<2,"",B35*C35) | F35: =IF(OR(D35="",$E$29=""),"",D35/$E$29) | G35: =IF(A35="","",Datos_higro!$B$4) | L35: =IF(I35="","",IFERROR(VLOOKUP(I35,Datos_higro!$A$21:$B$28,2,0),"")) | M35: =IF(OR(D35="",J35=""),"",IF(J35<=G35,"CUMPLE","NO CUMPLE"))
D36: =IF(COUNT(B36,C36)<2,"",B36*C36) | F36: =IF(OR(D36="",$E$29=""),"",D36/$E$29) | G36: =IF(A36="","",Datos_higro!$B$4) | L36: =IF(I36="","",IFERROR(VLOOKUP(I36,Datos_higro!$A$21:$B$28,2,0),"")) | M36: =IF(OR(D36="",J36=""),"",IF(J36<=G36,"CUMPLE","NO CUMPLE"))
A37: HOJA REHECHA: las orientaciones se tomaron del plano de fachadas y cambiaron casi todas. Hay que reemplazar la planilla entera, no alcanza con retocar celdas.
A38: COMO SE COMPLETA
A39: Descripcion, altura y ancho del vano: de la planilla de carpinterias.
A40: Area del vano, area total por plano y porcentaje: se calculan solos.
...

Sheet Planilla vigas
A1: VIGAS H°A° H-21 ACERO 42/50
A2: NIVEL | B2: POSICION | C2: LUZ (m) | D2: CARGAS (kg/m) | F2: REACCIONES | H2: MOMENTO TRAMO (kgm) | I2: MOMENTO APOYO (kgm) | J2: DIMENSIONES | M2: ARMADURA TRAMO | P2: ARMADURA APOYO | S2: T (kg/cm2) | V2: ESTRIBOS | W2: VERIFICACION | X2: OBSERVACIONES | Y2: DATOS AUXILIARES
D3: p | E3: diagrama | F3: RA | G3: RB | J3: b | K3: h | L3: d | M3: cm2 | N3: n | O3: o | P3: cm2 | Q3: n | R3: o | S3: A | T3: B | U3: o | V3: SEPAR | Y3: esquema | Z3: tipo | AA3: hf losa | AB3: b ef tramo | AC3: b ef apoyo | AD3: P punt. (kg) | AE3: a (m) | AF3: B trib. | AG3: h muro | AH3: rec.
A4: PA | B4: VI 01a | C4: 9.9 | D4: =(Datos_vigas!$B$10*(VLOOKUP($A$4,Datos_vigas!$A$14:$E$15,2,0)*AF4+Datos_vigas!$B$7*J4*L4/10000+Datos_vigas!$B$16*AG4)+Datos_vigas!$B$11*VLOOKUP($A$4,Datos_vigas!$A$14:$E$15,3,0)*AF4) -> 1082.4 | F4: =VLOOKUP(Y4,Datos_vigas!$A$19:$E$23,4,0)*D4*C4+IF(OR(AD4="",AE4=""),0,AD4*MAX(AE4,C4-AE4)/C4) -> 6161.562 | G4: =F4 -> 6161.562 | H4: =VLOOKUP(Y4,Datos_vigas!$A$19:$E$23,2,0)*D4*C4^2+0.75*1000*IF(OR(AD4="",AE4=""),0,AD4*AE4*(C4-AE4)/C4/1000) -> 7577.7247 | I4: =IF(VLOOKUP(Y4,Datos_vigas!$A$19:$E$23,3,0)=0,"---",VLOOKUP(Y4,Datos_vigas!$A$19:$E$23,3,0)*D4*C4^2+0.5*1000*IF(OR(AD4="",AE4=""),0,AD4*AE4*(C4-AE4)/C4/1000)) -> 10608.602 | J4: 15 | K4: =L4-AH4 -> 67 | L4: 70 | M4: =IF(NOT(ISNUMBER(H4)),"---",IF(H4<=0,"---",IF(H4*100/(Datos_vigas!$B$8*AB4*K4^2*Datos_vigas!$B$5)>=0.5,"REVISAR",MAX((1-SQRT(1-2*H4*100/(Datos_vigas!$B$8*AB4*K4^2*Datos_vigas!$B$5)))*AB4*K4*Datos_vigas!$B$5/Datos_vigas!$B$6,0.0033*J4*K4)))) -> 3.3165 | N4: 3 | O4: 12 | P4: =IF(NOT(ISNUMBER(I4)),"---",IF(I4<=0,"---",IF(I4*100/(Datos_vigas!$B$8*AC4*K4^2*Datos_vigas!$B$5)>=0.5,"REVISAR",MAX((1-SQRT(1-2*I4*100/(Datos_vigas!$B$8*AC4*K4^2*Datos_vigas!$B$5)))*AC4*K4*Datos_vigas!$B$5/Datos_vigas!$B$6,0.0033*J4*K4)))) -> 4.2015471 | Q4: 2 | R4: 20 | S4: =F4/(J4*0.85*K4) -> 7.2128323 | T4: =G4/(J4*0.85*K4) -> 7.2128323 | U4: 6 | V4: 30 | W4: =IF(OR(M4="REVISAR",P4="REVISAR"),"SECCION INSUF.",IF(NOT(AND(M4<>"REVISAR",P4<>"REVISAR",IF(ISNUMBER(M4),N4*PI()*(O4/10)^2/4>=M4,TRUE()),IF(ISNUMBER(P4),Q4*PI()*(R4/10)^2/4>=P4,TRUE()),IF(ISNUMBER(M4),M4<=0.0163*AB4*K4,TRUE()),IF(ISNUMBER(P4),P4<=0.0163*AC4*K4,TRUE()))),"NO VERIFICA FLEX.",IF(NOT(F4<=Datos_vigas!$B$9*(0.53*SQRT(Datos_vigas!$B$5)*J4*K4+2*PI()*(U4/10)^2/4*Datos_vigas!$B$6*K4/V4)),"NO VERIF. CORTE",IF(NOT(L4>=C4*100/VLOOKUP(Y4,Datos_vigas!$A$19:$E$23,5,0)),"VERIFICAR FLECHA","VERIFICA")))) -> VERIFICA | X4: Viga de borde sobre la medianera: NO recibe losa. Solo peso propio y mamposteria. Apoya en el tabique T01a y en la columna COL 01 de 10x10. Viga de borde: recibe la reaccion de la losa excentrica y queda sometida a TORSION, no verificada en esta planilla. | Y4: Continua | Z4: Invertida | AA4: 12 | AB4: =IF(Z4="Colgante",MIN(C4*100/4,J4+16*AA4),J4) -> 15 | AC4: =IF(Z4="Invertida",MIN(C4*100/4,J4+16*AA4),J4) -> 207 | AF4: 0 | AG4: 2.6 | AH4: 3
B5: VI 01b | C5: 3.95 | D5: =(Datos_vigas!$B$10*(VLOOKUP($A$4,Datos_vigas!$A$14:$E$15,2,0)*AF5+Datos_vigas!$B$7*J5*L5/10000+Datos_vigas!$B$16*AG5)+Datos_vigas!$B$11*VLOOKUP($A$4,Datos_vigas!$A$14:$E$15,3,0)*AF5) -> 1082.4 | F5: =VLOOKUP(Y5,Datos_vigas!$A$19:$E$23,4,0)*D5*C5+IF(OR(AD5="",AE5=""),0,AD5*MAX(AE5,C5-AE5)/C5) -> 2458.401 | G5: =F5 -> 2458.401 | H5: =VLOOKUP(Y5,Datos_vigas!$A$19:$E$23,2,0)*D5*C5^2+0.75*1000*IF(OR(AD5="",AE5=""),0,AD5*AE5*(C5-AE5)/C5/1000) -> 1206.3203 | I5: =IF(VLOOKUP(Y5,Datos_vigas!$A$19:$E$23,3,0)=0,"---",VLOOKUP(Y5,Datos_vigas!$A$19:$E$23,3,0)*D5*C5^2+0.5*1000*IF(OR(AD5="",AE5=""),0,AD5*AE5*(C5-AE5)/C5/1000)) -> 1688.8146 | J5: 15 | K5: =L5-AH5 -> 67 | L5: 70 | M5: =IF(NOT(ISNUMBER(H5)),"---",IF(H5<=0,"---",IF(H5*100/(Datos_vigas!$B$8*AB5*K5^2*Datos_vigas!$B$5)>=0.5,"REVISAR",MAX((1-SQRT(1-2*H5*100/(Datos_vigas!$B$8*AB5*K5^2*Datos_vigas!$B$5)))*AB5*K5*Datos_vigas!$B$5/Datos_vigas!$B$6,0.0033*J5*K5)))) -> 3.3165 | N5: 3 | O5: 12 | P5: =IF(NOT(ISNUMBER(I5)),"---",IF(I5<=0,"---",IF(I5*100/(Datos_vigas!$B$8*AC5*K5^2*Datos_vigas!$B$5)>=0.5,"REVISAR",MAX((1-SQRT(1-2*I5*100/(Datos_vigas!$B$8*AC5*K5^2*Datos_vigas!$B$5)))*AC5*K5*Datos_vigas!$B$5/Datos_vigas!$B$6,0.0033*J5*K5)))) -> 3.3165 | Q5: 3 | R5: 12 | S5: =F5/(J5*0.85*K5) -> 2.8778472 | T5: =G5/(J5*0.85*K5) -> 2.8778472 | U5: 6 | V5: 30 | W5: =IF(OR(M5="REVISAR",P5="REVISAR"),"SECCION INSUF.",IF(NOT(AND(M5<>"REVISAR",P5<>"REVISAR",IF(ISNUMBER(M5),N5*PI()*(O5/10)^2/4>=M5,TRUE()),IF(ISNUMBER(P5),Q5*PI()*(R5/10)^2/4>=P5,TRUE()),IF(ISNUMBER(M5),M5<=0.0163*AB5*K5,TRUE()),IF(ISNUMBER(P5),P5<=0.0163*AC5*K5,TRUE()))),"NO VERIFICA FLEX.",IF(NOT(F5<=Datos_vigas!$B$9*(0.53*SQRT(Datos_vigas!$B$5)*J5*K5+2*PI()*(U5/10)^2/4*Datos_vigas!$B$6*K5/V5)),"NO VERIF. CORTE",IF(NOT(L5>=C5*100/VLOOKUP(Y5,Datos_vigas!$A$19:$E$23,5,0)),"VERIFICAR FLECHA","VERIFICA")))) -> VERIFICA | X5: Viga de borde: recibe la reaccion de la losa excentrica y queda sometida a TORSION, no verificada en esta planilla. | Y5: Continua | Z5: Invertida | AA5: 12 | AB5: =IF(Z5="Colgante",MIN(C5*100/4,J5+16*AA5),J5) -> 15 | AC5: =IF(Z5="Invertida",MIN(C5*100/4,J5+16*AA5),J5) -> 98.75 | AF5: 0 | AG5: 2.6 | AH5: 3
B6: VI 02 | C6: 9.88 | D6: =(Datos_vigas!$B$10*(VLOOKUP($A$4,Datos_vigas!$A$14:$E$15,2,0)*AF6+Datos_vigas!$B$7*J6*L6/10000+Datos_vigas!$B$16*AG6)+Datos_vigas!$B$11*VLOOKUP($A$4,Datos_vigas!$A$14:$E$15,3,0)*AF6) -> 3717.62 | F6: =VLOOKUP(Y6,Datos_vigas!$A$19:$E$23,4,0)*D6*C6+IF(OR(AD6="",AE6=""),0,AD6*MAX(AE6,C6-AE6)/C6) -> 21119.799 | G6: =F6 -> 21119.799 | H6: =VLOOKUP(Y6,Datos_vigas!$A$19:$E$23,2,0)*D6*C6^2+0.75*1000*IF(OR(AD6="",AE6=""),0,AD6*AE6*(C6-AE6)/C6/1000) -> 25921.465 | I6: =IF(VLOOKUP(Y6,Datos_vigas!$A$19:$E$23,3,0)=0,"---",VLOOKUP(Y6,Datos_vigas!$A$19:$E$23,3,0)*D6*C6^2+0.5*1000*IF(OR(AD6="",AE6=""),0,AD6*AE6*(C6-AE6)/C6/1000)) -> 36289.325 | J6: 15 | K6: =L6-AH6 -> 64 | L6: 70 | M6: =IF(NOT(ISNUMBER(H6)),"---",IF(H6<=0,"---",IF(H6*100/(Datos_vigas!$B$8*AB6*K6^2*Datos_vigas!$B$5)>=0.5,"REVISAR",MAX((1-SQRT(1-2*H6*100/(Datos_vigas!$B$8*AB6*K6^2*Datos_vigas!$B$5)))*AB6*K6*Datos_vigas!$B$5/Datos_vigas!$B$6,0.0033*J6*K6)))) -> 12.287671 | N6: 4 | O6: 20 | P6: =IF(NOT(ISNUMBER(I6)),"---",IF(I6<=0,"---",IF(I6*100/(Datos_vigas!$B$8*AC6*K6^2*Datos_vigas!$B$5)>=0.5,"REVISAR",MAX((1-SQRT(1-2*I6*100/(Datos_vigas!$B$8*AC6*K6^2*Datos_vigas!$B$5)))*AC6*K6*Datos_vigas!$B$5/Datos_vigas!$B$6,0.0033*J6*K6)))) -> 15.174356 | Q6: 4 | R6: 25 | S6: =F6/(J6*0.85*K6) -> 25.882107 | T6: =G6/(J6*0.85*K6) -> 25.882107 | U6: 8 | V6: 10 | W6: =IF(OR(M6="REVISAR",P6="REVISAR"),"SECCION INSUF.",IF(NOT(AND(M6<>"REVISAR",P6<>"REVISAR",IF(ISNUMBER(M6),N6*PI()*(O6/10)^2/4>=M6,TRUE()),IF(ISNUMBER(P6),Q6*PI()*(R6/10)^2/4>=P6,TRUE()),IF(ISNUMBER(M6),M6<=0.0163*AB6*K6,TRUE()),IF(ISNUMBER(P6),P6<=0.0163*AC6*K6,TRUE()))),"NO VERIFICA FLEX.",IF(NOT(F6<=Datos_vigas!$B$9*(0.53*SQRT(Datos_vigas!$B$5)*J6*K6+2*PI()*(U6/10)^2/4*Datos_vigas!$B$6*K6/V6)),"NO VERIF. CORTE",IF(NOT(L6>=C6*100/VLOOKUP(Y6,Datos_vigas!$A$19:$E$23,5,0)),"VERIFICAR FLECHA","VERIFICA")))) -> VERIFICA | X6: Armadura en 2 capas (rec. 6 cm). NO USAR TEXTO VIEJO. Recibe L03 (2,08 m) y el alero L02, computado como 0,59 m equivalentes por tener menor carga que un entrepiso. Con 9,88 m de luz y 15x60 la armadura de apoyo necesaria (25,5 cm2) supera la cuantia maxima (13,2). Apoyos confirmados en obra: tabique T07 perpendicular en el extremo superior y COL 02 en el inferior, sin apoyo intermedio. Para esta carga harian falta 15x75 (As 16,2 cm2). Verificar la seccion real construida. | Y6: Continua | Z6: Invertida | AA6: 12 | AB6: =IF(Z6="Colgante",MIN(C6*100/4,J6+16*AA6),J6) -> 15 | AC6: =IF(Z6="Invertida",MIN(C6*100/4,J6+16*AA6),J6) -> 207 | AF6: 2.689 | AG6: 2.6 | AH6: 6
B7: VI 03c | C7: 3.75 | D7: =(Datos_vigas!$B$10*(VLOOKUP($A$4,Datos_vigas!$A$14:$E$15,2,0)*AF7+Datos_vigas!$B$7*J7*L7/10000+Datos_vigas!$B$16*AG7)+Datos_vigas!$B$11*VLOOKUP($A$4,Datos_vigas!$A$14:$E$15,3,0)*AF7) -> 3140.4 | F7: =VLOOKUP(Y7,Datos_vigas!$A$19:$E$23,4,0)*D7*C7+IF(OR(AD7="",AE7=""),0,AD7*MAX(AE7,C7-AE7)/C7) -> 6771.4875 | G7: =F7 -> 6771.4875 | H7: =VLOOKUP(Y7,Datos_vigas!$A$19:$E$23,2,0)*D7*C7^2+0.75*1000*IF(OR(AD7="",AE7=""),0,AD7*AE7*(C7-AE7)/C7/1000) -> 3154.4827 | I7: =IF(VLOOKUP(Y7,Datos_vigas!$A$19:$E$23,3,0)=0,"---",VLOOKUP(Y7,Datos_vigas!$A$19:$E$23,3,0)*D7*C7^2+0.5*1000*IF(OR(AD7="",AE7=""),0,AD7*AE7*(C7-AE7)/C7/1000)) -> 4416.1875 | J7: 15 | K7: =L7-AH7 -> 67 | L7: 70 | M7: =IF(NOT(ISNUMBER(H7)),"---",IF(H7<=0,"---",IF(H7*100/(Datos_vigas!$B$8*AB7*K7^2*Datos_vigas!$B$5)>=0.5,"REVISAR",MAX((1-SQRT(1-2*H7*100/(Datos_vigas!$B$8*AB7*K7^2*Datos_vigas!$B$5)))*AB7*K7*Datos_vigas!$B$5/Datos_vigas!$B$6,0.0033*J7*K7)))) -> 3.3165 | N7: 3 | O7: 12 | P7: =IF(NOT(ISNUMBER(I7)),"---",IF(I7<=0,"---",IF(I7*100/(Datos_vigas!$B$8*AC7*K7^2*Datos_vigas!$B$5)>=0.5,"REVISAR",MAX((1-SQRT(1-2*I7*100/(Datos_vigas!$B$8*AC7*K7^2*Datos_vigas!$B$5)))*AC7*K7*Datos_vigas!$B$5/Datos_vigas!$B$6,0.0033*J7*K7)))) -> 3.3165 | Q7: 3 | R7: 12 | S7: =F7/(J7*0.85*K7) -> 7.9268218 | T7: =G7/(J7*0.85*K7) -> 7.9268218 | U7: 6 | V7: 30 | W7: =IF(OR(M7="REVISAR",P7="REVISAR"),"SECCION INSUF.",IF(NOT(AND(M7<>"REVISAR",P7<>"REVISAR",IF(ISNUMBER(M7),N7*PI()*(O7/10)^2/4>=M7,TRUE()),IF(ISNUMBER(P7),Q7*PI()*(R7/10)^2/4>=P7,TRUE()),IF(ISNUMBER(M7),M7<=0.0163*AB7*K7,TRUE()),IF(ISNUMBER(P7),P7<=0.0163*AC7*K7,TRUE()))),"NO VERIFICA FLEX.",IF(NOT(F7<=Datos_vigas!$B$9*(0.53*SQRT(Datos_vigas!$B$5)*J7*K7+2*PI()*(U7/10)^2/4*Datos_vigas!$B$6*K7/V7)),"NO VERIF. CORTE",IF(NOT(L7>=C7*100/VLOOKUP(Y7,Datos_vigas!$A$19:$E$23,5,0)),"VERIFICAR FLECHA","VERIFICA")))) -> VERIFICA | Y7: Continua | Z7: Invertida | AA7: 12 | AB7: =IF(Z7="Colgante",MIN(C7*100/4,J7+16*AA7),J7) -> 15 | AC7: =IF(Z7="Invertida",MIN(C7*100/4,J7+16*AA7),J7) -> 93.75 | AF7: 2.1 | AG7: 2.6 | AH7: 3
B8: VI 04a | C8: 3.75 | D8: =(Datos_vigas!$B$10*(VLOOKUP($A$4,Datos_vigas!$A$14:$E$15,2,0)*AF8+Datos_vigas!$B$7*J8*L8/10000+Datos_vigas!$B$16*AG8)+Datos_vigas!$B$11*VLOOKUP($A$4,Datos_vigas!$A$14:$E$15,3,0)*AF8) -> 1082.4 | F8: =VLOOKUP(Y8,Datos_vigas!$A$19:$E$23,4,0)*D8*C8+IF(OR(AD8="",AE8=""),0,AD8*MAX(AE8,C8-AE8)/C8) -> 5626.565 | G8: =F8 -> 5626.565 | H8: =VLOOKUP(Y8,Datos_vigas!$A$19:$E$23,2,0)*D8*C8^2+0.75*1000*IF(OR(AD8="",AE8=""),0,AD8*AE8*(C8-AE8)/C8/1000) -> 5532.3179 | I8: =IF(VLOOKUP(Y8,Datos_vigas!$A$19:$E$23,3,0)=0,"---",VLOOKUP(Y8,Datos_vigas!$A$19:$E$23,3,0)*D8*C8^2+0.5*1000*IF(OR(AD8="",AE8=""),0,AD8*AE8*(C8-AE8)/C8/1000)) -> 4485.501 | J8: 15 | K8: =L8-AH8 -> 67 | L8: 70 | M8: =IF(NOT(ISNUMBER(H8)),"---",IF(H8<=0,"---",IF(H8*100/(Datos_vigas!$B$8*AB8*K8^2*Datos_vigas!$B$5)>=0.5,"REVISAR",MAX((1-SQRT(1-2*H8*100/(Datos_vigas!$B$8*AB8*K8^2*Datos_vigas!$B$5)))*AB8*K8*Datos_vigas!$B$5/Datos_vigas!$B$6,0.0033*J8*K8)))) -> 3.3165 | N8: 3 | O8: 12 | P8: =IF(NOT(ISNUMBER(I8)),"---",IF(I8<=0,"---",IF(I8*100/(Datos_vigas!$B$8*AC8*K8^2*Datos_vigas!$B$5)>=0.5,"REVISAR",MAX((1-SQRT(1-2*I8*100/(Datos_vigas!$B$8*AC8*K8^2*Datos_vigas!$B$5)))*AC8*K8*Datos_vigas!$B$5/Datos_vigas!$B$6,0.0033*J8*K8)))) -> 3.3165 | Q8: 3 | R8: 12 | S8: =F8/(J8*0.85*K8) -> 6.5865555 | T8: =G8/(J8*0.85*K8) -> 6.5865555 | U8: 6 | V8: 30 | W8: =IF(OR(M8="REVISAR",P8="REVISAR"),"SECCION INSUF.",IF(NOT(AND(M8<>"REVISAR",P8<>"REVISAR",IF(ISNUMBER(M8),N8*PI()*(O8/10)^2/4>=M8,TRUE()),IF(ISNUMBER(P8),Q8*PI()*(R8/10)^2/4>=P8,TRUE()),IF(ISNUMBER(M8),M8<=0.0163*AB8*K8,TRUE()),IF(ISNUMBER(P8),P8<=0.0163*AC8*K8,TRUE()))),"NO VERIFICA FLEX.",IF(NOT(F8<=Datos_vigas!$B$9*(0.53*SQRT(Datos_vigas!$B$5)*J8*K8+2*PI()*(U8/10)^2/4*Datos_vigas!$B$6*K8/V8)),"NO VERIF. CORTE",IF(NOT(L8>=C8*100/VLOOKUP(Y8,Datos_vigas!$A$19:$E$23,5,0)),"VERIFICAR FLECHA","VERIFICA")))) -> VERIFICA | X8: VI 09 le descarga 6.332 kg a 1,80 m del apoyo, practicamente al medio de sus 3,75 m. Esta viga no recibe losa, de modo que la puntual es casi toda su carga. Se superpone el momento isostatico P a b / L repartido 0,75 al tramo y 0,50 al apoyo, y la reaccion isostatica al corte. | Y8: Continua | Z8: Invertida | AA8: 12 | AB8: =IF(Z8="Colgante",MIN(C8*100/4,J8+16*AA8),J8) -> 15 | AC8: =IF(Z8="Invertida",MIN(C8*100/4,J8+16*AA8),J8) -> 93.75 | AD8: 6332 | AE8: 1.8 | AF8: 0 | AG8: 2.6 | AH8: 3
B9: VI 04b | C9: 3.8 | D9: =(Datos_vigas!$B$10*(VLOOKUP($A$4,Datos_vigas!$A$14:$E$15,2,0)*AF9+Datos_vigas!$B$7*J9*L9/10000+Datos_vigas!$B$16*AG9)+Datos_vigas!$B$11*VLOOKUP($A$4,Datos_vigas!$A$14:$E$15,3,0)*AF9) -> 2600.42 | F9: =VLOOKUP(Y9,Datos_vigas!$A$19:$E$23,4,0)*D9*C9+IF(OR(AD9="",AE9=""),0,AD9*MAX(AE9,C9-AE9)/C9) -> 5681.9177 | G9: =F9 -> 5681.9177 | H9: =VLOOKUP(Y9,Datos_vigas!$A$19:$E$23,2,0)*D9*C9^2+0.75*1000*IF(OR(AD9="",AE9=""),0,AD9*AE9*(C9-AE9)/C9/1000) -> 2682.2011 | I9: =IF(VLOOKUP(Y9,Datos_vigas!$A$19:$E$23,3,0)=0,"---",VLOOKUP(Y9,Datos_vigas!$A$19:$E$23,3,0)*D9*C9^2+0.5*1000*IF(OR(AD9="",AE9=""),0,AD9*AE9*(C9-AE9)/C9/1000)) -> 3755.0065 | J9: 15 | K9: =L9-AH9 -> 67 | L9: 70 | M9: =IF(NOT(ISNUMBER(H9)),"---",IF(H9<=0,"---",IF(H9*100/(Datos_vigas!$B$8*AB9*K9^2*Datos_vigas!$B$5)>=0.5,"REVISAR",MAX((1-SQRT(1-2*H9*100/(Datos_vigas!$B$8*AB9*K9^2*Datos_vigas!$B$5)))*AB9*K9*Datos_vigas!$B$5/Datos_vigas!$B$6,0.0033*J9*K9)))) -> 3.3165 | N9: 3 | O9: 12 | P9: =IF(NOT(ISNUMBER(I9)),"---",IF(I9<=0,"---",IF(I9*100/(Datos_vigas!$B$8*AC9*K9^2*Datos_vigas!$B$5)>=0.5,"REVISAR",MAX((1-SQRT(1-2*I9*100/(Datos_vigas!$B$8*AC9*K9^2*Datos_vigas!$B$5)))*AC9*K9*Datos_vigas!$B$5/Datos_vigas!$B$6,0.0033*J9*K9)))) -> 3.3165 | Q9: 3 | R9: 12 | S9: =F9/(J9*0.85*K9) -> 6.6513523 | T9: =G9/(J9*0.85*K9) -> 6.6513523 | U9: 6 | V9: 30 | W9: =IF(OR(M9="REVISAR",P9="REVISAR"),"SECCION INSUF.",IF(NOT(AND(M9<>"REVISAR",P9<>"REVISAR",IF(ISNUMBER(M9),N9*PI()*(O9/10)^2/4>=M9,TRUE()),IF(ISNUMBER(P9),Q9*PI()*(R9/10)^2/4>=P9,TRUE()),IF(ISNUMBER(M9),M9<=0.0163*AB9*K9,TRUE()),IF(ISNUMBER(P9),P9<=0.0163*AC9*K9,TRUE()))),"NO VERIFICA FLEX.",IF(NOT(F9<=Datos_vigas!$B$9*(0.53*SQRT(Datos_vigas!$B$5)*J9*K9+2*PI()*(U9/10)^2/4*Datos_vigas!$B$6*K9/V9)),"NO VERIF. CORTE",IF(NOT(L9>=C9*100/VLOOKUP(Y9,Datos_vigas!$A$19:$E$23,5,0)),"VERIFICAR FLECHA","VERIFICA")))) -> VERIFICA | Y9: Continua | Z9: Invertida | AA9: 12 | AB9: =IF(Z9="Colgante",MIN(C9*100/4,J9+16*AA9),J9) -> 15 | AC9: =IF(Z9="Invertida",MIN(C9*100/4,J9+16*AA9),J9) -> 95 | AF9: 1.549 | AG9: 2.6 | AH9: 3
B10: VI 06 | C10: 6.53 | D10: =(Datos_vigas!$B$10*(VLOOKUP($A$4,Datos_vigas!$A$14:$E$15,2,0)*AF10+Datos_vigas!$B$7*J10*L10/10000+Datos_vigas!$B$16*AG10)+Datos_vigas!$B$11*VLOOKUP($A$4,Datos_vigas!$A$14:$E$15,3,0)*AF10) -> 2600.42 | F10: =VLOOKUP(Y10,Datos_vigas!$A$19:$E$23,4,0)*D10*C10+IF(OR(AD10="",AE10=""),0,AD10*MAX(AE10,C10-AE10)/C10) -> 15234.677 | G10: =F10 -> 15234.677 | H10: =VLOOKUP(Y10,Datos_vigas!$A$19:$E$23,2,0)*D10*C10^2+0.75*1000*IF(OR(AD10="",AE10=""),0,AD10*AE10*(C10-AE10)/C10/1000) -> 10095.085 | I10: =IF(VLOOKUP(Y10,Datos_vigas!$A$19:$E$23,3,0)=0,"---",VLOOKUP(Y10,Datos_vigas!$A$19:$E$23,3,0)*D10*C10^2+0.5*1000*IF(OR(AD10="",AE10=""),0,AD10*AE10*(C10-AE10)/C10/1000)) -> 12538.174 | J10: 15 | K10: =L10-AH10 -> 67 | L10: 70 | M10: =IF(NOT(ISNUMBER(H10)),"---",IF(H10<=0,"---",IF(H10*100/(Datos_vigas!$B$8*AB10*K10^2*Datos_vigas!$B$5)>=0.5,"REVISAR",MAX((1-SQRT(1-2*H10*100/(Datos_vigas!$B$8*AB10*K10^2*Datos_vigas!$B$5)))*AB10*K10*Datos_vigas!$B$5/Datos_vigas!$B$6,0.0033*J10*K10)))) -> 4.1580931 | N10: 2 | O10: 20 | P10: =IF(NOT(ISNUMBER(I10)),"---",IF(I10<=0,"---",IF(I10*100/(Datos_vigas!$B$8*AC10*K10^2*Datos_vigas!$B$5)>=0.5,"REVISAR",MAX((1-SQRT(1-2*I10*100/(Datos_vigas!$B$8*AC10*K10^2*Datos_vigas!$B$5)))*AC10*K10*Datos_vigas!$B$5/Datos_vigas!$B$6,0.0033*J10*K10)))) -> 4.9733256 | Q10: 2 | R10: 20 | S10: =F10/(J10*0.85*K10) -> 17.83398 | T10: =G10/(J10*0.85*K10) -> 17.83398 | U10: 6 | V10: 10 | W10: =IF(OR(M10="REVISAR",P10="REVISAR"),"SECCION INSUF.",IF(NOT(AND(M10<>"REVISAR",P10<>"REVISAR",IF(ISNUMBER(M10),N10*PI()*(O10/10)^2/4>=M10,TRUE()),IF(ISNUMBER(P10),Q10*PI()*(R10/10)^2/4>=P10,TRUE()),IF(ISNUMBER(M10),M10<=0.0163*AB10*K10,TRUE()),IF(ISNUMBER(P10),P10<=0.0163*AC10*K10,TRUE()))),"NO VERIFICA FLEX.",IF(NOT(F10<=Datos_vigas!$B$9*(0.53*SQRT(Datos_vigas!$B$5)*J10*K10+2*PI()*(U10/10)^2/4*Datos_vigas!$B$6*K10/V10)),"NO VERIF. CORTE",IF(NOT(L10>=C10*100/VLOOKUP(Y10,Datos_vigas!$A$19:$E$23,5,0)),"VERIFICAR FLECHA","VERIFICA")))) -> VERIFICA | X10: Longitud total 14,00 m. Sobre su eje hay cuatro columnas: trabaja como viga continua de tres tramos de 4,10, 4,32 y 6,53 m. Se calcula con el mayor. Es el cuarto borde de la losa cruzada L07. Longitud total 14,00 m. Sobre su eje hay cuatro columnas: trabaja como viga continua de tres tramos de 4,10, 4,32 y 6,53 m. Se calcula con el mayor. Es el cuarto borde de la losa cruzada L07. VI 08b le descarga 5.954 kg a 6,00 m del extremo inferior, dentro del tramo de 6,53 m y a solo 53 cm del apoyo siguiente: aporta poco momento y mucho corte, por eso la reaccion sube de 9.764 a 15.235 kg. Se superpone el momento isostatico P a b / L repartido 0,75 al tramo y 0,50 al apoyo, y la reaccion isostatica al corte. Viga principal: recibe a VI 08b y a VI 09. VI 09 apoya a 7,95 m del extremo inferior, o sea en el tramo del medio de 4,32 m, que con esa puntual llega a 7.993 kgm y no gobierna. El tramo que gobierna es el de 6,53 m con la puntual de VI 08b. | Y10: Continua | Z10: Invertida | AA10: 12 | AB10: =IF(Z10="Colgante",MIN(C10*100/4,J10+16*AA10),J10) -> 15 | AC10: =IF(Z10="Invertida",MIN(C10*100/4,J10+16*AA10),J10) -> 163.25 | AD10: 5954 | AE10: 6 | AF10: 1.549 | AG10: 2.6 | AH10: 3
B11: VI 07a | C11: 3.37 | D11: =(Datos_vigas!$B$10*(VLOOKUP($A$4,Datos_vigas!$A$14:$E$15,2,0)*AF11+Datos_vigas!$B$7*J11*L11/10000+Datos_vigas!$B$16*AG11)+Datos_vigas!$B$11*VLOOKUP($A$4,Datos_vigas!$A$14:$E$15,3,0)*AF11) -> 1846.8 | F11: =VLOOKUP(Y11,Datos_vigas!$A$19:$E$23,4,0)*D11*C11+IF(OR(AD11="",AE11=""),0,AD11*MAX(AE11,C11-AE11)/C11) -> 3578.6367 | G11: =F11 -> 3578.6367 | H11: =VLOOKUP(Y11,Datos_vigas!$A$19:$E$23,2,0)*D11*C11^2+0.75*1000*IF(OR(AD11="",AE11=""),0,AD11*AE11*(C11-AE11)/C11/1000) -> 1498.1673 | I11: =IF(VLOOKUP(Y11,Datos_vigas!$A$19:$E$23,3,0)=0,"---",VLOOKUP(Y11,Datos_vigas!$A$19:$E$23,3,0)*D11*C11^2+0.5*1000*IF(OR(AD11="",AE11=""),0,AD11*AE11*(C11-AE11)/C11/1000)) -> 2097.3923 | J11: 15 | K11: =L11-AH11 -> 67 | L11: 70 | M11: =IF(NOT(ISNUMBER(H11)),"---",IF(H11<=0,"---",IF(H11*100/(Datos_vigas!$B$8*AB11*K11^2*Datos_vigas!$B$5)>=0.5,"REVISAR",MAX((1-SQRT(1-2*H11*100/(Datos_vigas!$B$8*AB11*K11^2*Datos_vigas!$B$5)))*AB11*K11*Datos_vigas!$B$5/Datos_vigas!$B$6,0.0033*J11*K11)))) -> 3.3165 | N11: 3 | O11: 12 | P11: =IF(NOT(ISNUMBER(I11)),"---",IF(I11<=0,"---",IF(I11*100/(Datos_vigas!$B$8*AC11*K11^2*Datos_vigas!$B$5)>=0.5,"REVISAR",MAX((1-SQRT(1-2*I11*100/(Datos_vigas!$B$8*AC11*K11^2*Datos_vigas!$B$5)))*AC11*K11*Datos_vigas!$B$5/Datos_vigas!$B$6,0.0033*J11*K11)))) -> 3.3165 | Q11: 3 | R11: 12 | S11: =F11/(J11*0.85*K11) -> 4.1892147 | T11: =G11/(J11*0.85*K11) -> 4.1892147 | U11: 6 | V11: 30 | W11: =IF(OR(M11="REVISAR",P11="REVISAR"),"SECCION INSUF.",IF(NOT(AND(M11<>"REVISAR",P11<>"REVISAR",IF(ISNUMBER(M11),N11*PI()*(O11/10)^2/4>=M11,TRUE()),IF(ISNUMBER(P11),Q11*PI()*(R11/10)^2/4>=P11,TRUE()),IF(ISNUMBER(M11),M11<=0.0163*AB11*K11,TRUE()),IF(ISNUMBER(P11),P11<=0.0163*AC11*K11,TRUE()))),"NO VERIFICA FLEX.",IF(NOT(F11<=Datos_vigas!$B$9*(0.53*SQRT(Datos_vigas!$B$5)*J11*K11+2*PI()*(U11/10)^2/4*Datos_vigas!$B$6*K11/V11)),"NO VERIF. CORTE",IF(NOT(L11>=C11*100/VLOOKUP(Y11,Datos_vigas!$A$19:$E$23,5,0)),"VERIFICAR FLECHA","VERIFICA")))) -> VERIFICA | X11: Viga de borde: recibe la reaccion de la losa excentrica y queda sometida a TORSION, no verificada en esta planilla. | Y11: Continua | Z11: Invertida | AA11: 12 | AB11: =IF(Z11="Colgante",MIN(C11*100/4,J11+16*AA11),J11) -> 15 | AC11: =IF(Z11="Invertida",MIN(C11*100/4,J11+16*AA11),J11) -> 84.25 | AF11: 0.78 | AG11: 2.6 | AH11: 3
B12: VI 07b | C12: 4.03 | D12: =(Datos_vigas!$B$10*(VLOOKUP($A$4,Datos_vigas!$A$14:$E$15,2,0)*AF12+Datos_vigas!$B$7*J12*L12/10000+Datos_vigas!$B$16*AG12)+Datos_vigas!$B$11*VLOOKUP($A$4,Datos_vigas!$A$14:$E$15,3,0)*AF12) -> 1082.4 | F12: =VLOOKUP(Y12,Datos_vigas!$A$19:$E$23,4,0)*D12*C12+IF(OR(AD12="",AE12=""),0,AD12*MAX(AE12,C12-AE12)/C12) -> 2508.1914 | G12: =F12 -> 2508.1914 | H12: =VLOOKUP(Y12,Datos_vigas!$A$19:$E$23,2,0)*D12*C12^2+0.75*1000*IF(OR(AD12="",AE12=""),0,AD12*AE12*(C12-AE12)/C12/1000) -> 1255.6787 | I12: =IF(VLOOKUP(Y12,Datos_vigas!$A$19:$E$23,3,0)=0,"---",VLOOKUP(Y12,Datos_vigas!$A$19:$E$23,3,0)*D12*C12^2+0.5*1000*IF(OR(AD12="",AE12=""),0,AD12*AE12*(C12-AE12)/C12/1000)) -> 1757.915 | J12: 15 | K12: =L12-AH12 -> 67 | L12: 70 | M12: =IF(NOT(ISNUMBER(H12)),"---",IF(H12<=0,"---",IF(H12*100/(Datos_vigas!$B$8*AB12*K12^2*Datos_vigas!$B$5)>=0.5,"REVISAR",MAX((1-SQRT(1-2*H12*100/(Datos_vigas!$B$8*AB12*K12^2*Datos_vigas!$B$5)))*AB12*K12*Datos_vigas!$B$5/Datos_vigas!$B$6,0.0033*J12*K12)))) -> 3.3165 | N12: 3 | O12: 12 | P12: =IF(NOT(ISNUMBER(I12)),"---",IF(I12<=0,"---",IF(I12*100/(Datos_vigas!$B$8*AC12*K12^2*Datos_vigas!$B$5)>=0.5,"REVISAR",MAX((1-SQRT(1-2*I12*100/(Datos_vigas!$B$8*AC12*K12^2*Datos_vigas!$B$5)))*AC12*K12*Datos_vigas!$B$5/Datos_vigas!$B$6,0.0033*J12*K12)))) -> 3.3165 | Q12: 3 | R12: 12 | S12: =F12/(J12*0.85*K12) -> 2.9361327 | T12: =G12/(J12*0.85*K12) -> 2.9361327 | U12: 6 | V12: 30 | W12: =IF(OR(M12="REVISAR",P12="REVISAR"),"SECCION INSUF.",IF(NOT(AND(M12<>"REVISAR",P12<>"REVISAR",IF(ISNUMBER(M12),N12*PI()*(O12/10)^2/4>=M12,TRUE()),IF(ISNUMBER(P12),Q12*PI()*(R12/10)^2/4>=P12,TRUE()),IF(ISNUMBER(M12),M12<=0.0163*AB12*K12,TRUE()),IF(ISNUMBER(P12),P12<=0.0163*AC12*K12,TRUE()))),"NO VERIFICA FLEX.",IF(NOT(F12<=Datos_vigas!$B$9*(0.53*SQRT(Datos_vigas!$B$5)*J12*K12+2*PI()*(U12/10)^2/4*Datos_vigas!$B$6*K12/V12)),"NO VERIF. CORTE",IF(NOT(L12>=C12*100/VLOOKUP(Y12,Datos_vigas!$A$19:$E$23,5,0)),"VERIFICAR FLECHA","VERIFICA")))) -> VERIFICA | X12: Viga de borde: recibe la reaccion de la losa excentrica y queda sometida a TORSION, no verificada en esta planilla. | Y12: Continua | Z12: Invertida | AA12: 12 | AB12: =IF(Z12="Colgante",MIN(C12*100/4,J12+16*AA12),J12) -> 15 | AC12: =IF(Z12="Invertida",MIN(C12*100/4,J12+16*AA12),J12) -> 100.75 | AF12: 0 | AG12: 2.6 | AH12: 3
B13: VI 07c | C13: 8.6 | D13: =(Datos_vigas!$B$10*(VLOOKUP($A$4,Datos_vigas!$A$14:$E$15,2,0)*AF13+Datos_vigas!$B$7*J13*L13/10000+Datos_vigas!$B$16*AG13)+Datos_vigas!$B$11*VLOOKUP($A$4,Datos_vigas!$A$14:$E$15,3,0)*AF13) -> 4718.2 | F13: =VLOOKUP(Y13,Datos_vigas!$A$19:$E$23,4,0)*D13*C13+IF(OR(AD13="",AE13=""),0,AD13*MAX(AE13,C13-AE13)/C13) -> 26369.046 | G13: =F13 -> 26369.046 | H13: =VLOOKUP(Y13,Datos_vigas!$A$19:$E$23,2,0)*D13*C13^2+0.75*1000*IF(OR(AD13="",AE13=""),0,AD13*AE13*(C13-AE13)/C13/1000) -> 27258.789 | I13: =IF(VLOOKUP(Y13,Datos_vigas!$A$19:$E$23,3,0)=0,"---",VLOOKUP(Y13,Datos_vigas!$A$19:$E$23,3,0)*D13*C13^2+0.5*1000*IF(OR(AD13="",AE13=""),0,AD13*AE13*(C13-AE13)/C13/1000)) -> 45435.457 | J13: 15 | K13: =L13-AH13 -> 64 | L13: 70 | M13: =IF(NOT(ISNUMBER(H13)),"---",IF(H13<=0,"---",IF(H13*100/(Datos_vigas!$B$8*AB13*K13^2*Datos_vigas!$B$5)>=0.5,"REVISAR",MAX((1-SQRT(1-2*H13*100/(Datos_vigas!$B$8*AB13*K13^2*Datos_vigas!$B$5)))*AB13*K13*Datos_vigas!$B$5/Datos_vigas!$B$6,0.0033*J13*K13)))) -> 13.038564 | N13: 3 | O13: 25 | P13: =IF(NOT(ISNUMBER(I13)),"---",IF(I13<=0,"---",IF(I13*100/(Datos_vigas!$B$8*AC13*K13^2*Datos_vigas!$B$5)>=0.5,"REVISAR",MAX((1-SQRT(1-2*I13*100/(Datos_vigas!$B$8*AC13*K13^2*Datos_vigas!$B$5)))*AC13*K13*Datos_vigas!$B$5/Datos_vigas!$B$6,0.0033*J13*K13)))) -> 19.055272 | Q13: 4 | R13: 25 | S13: =F13/(J13*0.85*K13) -> 32.315007 | T13: =G13/(J13*0.85*K13) -> 32.315007 | U13: 10 | V13: 15 | W13: =IF(OR(M13="REVISAR",P13="REVISAR"),"SECCION INSUF.",IF(NOT(AND(M13<>"REVISAR",P13<>"REVISAR",IF(ISNUMBER(M13),N13*PI()*(O13/10)^2/4>=M13,TRUE()),IF(ISNUMBER(P13),Q13*PI()*(R13/10)^2/4>=P13,TRUE()),IF(ISNUMBER(M13),M13<=0.0163*AB13*K13,TRUE()),IF(ISNUMBER(P13),P13<=0.0163*AC13*K13,TRUE()))),"NO VERIFICA FLEX.",IF(NOT(F13<=Datos_vigas!$B$9*(0.53*SQRT(Datos_vigas!$B$5)*J13*K13+2*PI()*(U13/10)^2/4*Datos_vigas!$B$6*K13/V13)),"NO VERIF. CORTE",IF(NOT(L13>=C13*100/VLOOKUP(Y13,Datos_vigas!$A$19:$E$23,5,0)),"VERIFICAR FLECHA","VERIFICA")))) -> VERIFICA | X13: Armadura en 2 capas (rec. 6 cm). Apoya en columna COL 02 de 15x30 y en el tabique T05b. La viga chata VCH 05 le descarga 1.735 kg a 3,60 m del apoyo. Se superpone el momento isostatico P a b / L repartido 0,75 al tramo y 0,50 al apoyo, y la reaccion isostatica al corte. Viga de borde: recibe la reaccion de la losa excentrica y queda sometida a TORSION, no verificada en esta planilla. | Y13: Empotrada-apoyada | Z13: Invertida | AA13: 12 | AB13: =IF(Z13="Colgante",MIN(C13*100/4,J13+16*AA13),J13) -> 15 | AC13: =IF(Z13="Invertida",MIN(C13*100/4,J13+16*AA13),J13) -> 207 | AD13: 1735 | AE13: 3.6 | AF13: 3.71 | AG13: 2.6 | AH13: 6
B14: VI 08a | C14: 3.65 | D14: =(Datos_vigas!$B$10*(VLOOKUP($A$4,Datos_vigas!$A$14:$E$15,2,0)*AF14+Datos_vigas!$B$7*J14*L14/10000+Datos_vigas!$B$16*AG14)+Datos_vigas!$B$11*VLOOKUP($A$4,Datos_vigas!$A$14:$E$15,3,0)*AF14) -> 2126.1 | F14: =VLOOKUP(Y14,Datos_vigas!$A$19:$E$23,4,0)*D14*C14+IF(OR(AD14="",AE14=""),0,AD14*MAX(AE14,C14-AE14)/C14) -> 4462.1524 | G14: =F14 -> 4462.1524 | H14: =VLOOKUP(Y14,Datos_vigas!$A$19:$E$23,2,0)*D14*C14^2+0.75*1000*IF(OR(AD14="",AE14=""),0,AD14*AE14*(C14-AE14)/C14/1000) -> 2023.2524 | I14: =IF(VLOOKUP(Y14,Datos_vigas!$A$19:$E$23,3,0)=0,"---",VLOOKUP(Y14,Datos_vigas!$A$19:$E$23,3,0)*D14*C14^2+0.5*1000*IF(OR(AD14="",AE14=""),0,AD14*AE14*(C14-AE14)/C14/1000)) -> 2832.4967 | J14: 15 | K14: =L14-AH14 -> 67 | L14: 70 | M14: =IF(NOT(ISNUMBER(H14)),"---",IF(H14<=0,"---",IF(H14*100/(Datos_vigas!$B$8*AB14*K14^2*Datos_vigas!$B$5)>=0.5,"REVISAR",MAX((1-SQRT(1-2*H14*100/(Datos_vigas!$B$8*AB14*K14^2*Datos_vigas!$B$5)))*AB14*K14*Datos_vigas!$B$5/Datos_vigas!$B$6,0.0033*J14*K14)))) -> 3.3165 | N14: 3 | O14: 12 | P14: =IF(NOT(ISNUMBER(I14)),"---",IF(I14<=0,"---",IF(I14*100/(Datos_vigas!$B$8*AC14*K14^2*Datos_vigas!$B$5)>=0.5,"REVISAR",MAX((1-SQRT(1-2*I14*100/(Datos_vigas!$B$8*AC14*K14^2*Datos_vigas!$B$5)))*AC14*K14*Datos_vigas!$B$5/Datos_vigas!$B$6,0.0033*J14*K14)))) -> 3.3165 | Q14: 3 | R14: 12 | S14: =F14/(J14*0.85*K14) -> 5.2234737 | T14: =G14/(J14*0.85*K14) -> 5.2234737 | U14: 6 | V14: 30 | W14: =IF(OR(M14="REVISAR",P14="REVISAR"),"SECCION INSUF.",IF(NOT(AND(M14<>"REVISAR",P14<>"REVISAR",IF(ISNUMBER(M14),N14*PI()*(O14/10)^2/4>=M14,TRUE()),IF(ISNUMBER(P14),Q14*PI()*(R14/10)^2/4>=P14,TRUE()),IF(ISNUMBER(M14),M14<=0.0163*AB14*K14,TRUE()),IF(ISNUMBER(P14),P14<=0.0163*AC14*K14,TRUE()))),"NO VERIFICA FLEX.",IF(NOT(F14<=Datos_vigas!$B$9*(0.53*SQRT(Datos_vigas!$B$5)*J14*K14+2*PI()*(U14/10)^2/4*Datos_vigas!$B$6*K14/V14)),"NO VERIF. CORTE",IF(NOT(L14>=C14*100/VLOOKUP(Y14,Datos_vigas!$A$19:$E$23,5,0)),"VERIFICAR FLECHA","VERIFICA")))) -> VERIFICA | Y14: Continua | Z14: Invertida | AA14: 12 | AB14: =IF(Z14="Colgante",MIN(C14*100/4,J14+16*AA14),J14) -> 15 | AC14: =IF(Z14="Invertida",MIN(C14*100/4,J14+16*AA14),J14) -> 91.25 | AF14: 1.065 | AG14: 2.6 | AH14: 3
B15: VI 08b | C15: 4.87 | D15: =(Datos_vigas!$B$10*(VLOOKUP($A$4,Datos_vigas!$A$14:$E$15,2,0)*AF15+Datos_vigas!$B$7*J15*L15/10000+Datos_vigas!$B$16*AG15)+Datos_vigas!$B$11*VLOOKUP($A$4,Datos_vigas!$A$14:$E$15,3,0)*AF15) -> 2126.1 | F15: =VLOOKUP(Y15,Datos_vigas!$A$19:$E$23,4,0)*D15*C15+IF(OR(AD15="",AE15=""),0,AD15*MAX(AE15,C15-AE15)/C15) -> 5953.6115 | G15: =F15 -> 5953.6115 | H15: =VLOOKUP(Y15,Datos_vigas!$A$19:$E$23,2,0)*D15*C15^2+0.75*1000*IF(OR(AD15="",AE15=""),0,AD15*AE15*(C15-AE15)/C15/1000) -> 3601.8221 | I15: =IF(VLOOKUP(Y15,Datos_vigas!$A$19:$E$23,3,0)=0,"---",VLOOKUP(Y15,Datos_vigas!$A$19:$E$23,3,0)*D15*C15^2+0.5*1000*IF(OR(AD15="",AE15=""),0,AD15*AE15*(C15-AE15)/C15/1000)) -> 5042.4501 | J15: 15 | K15: =L15-AH15 -> 67 | L15: 70 | M15: =IF(NOT(ISNUMBER(H15)),"---",IF(H15<=0,"---",IF(H15*100/(Datos_vigas!$B$8*AB15*K15^2*Datos_vigas!$B$5)>=0.5,"REVISAR",MAX((1-SQRT(1-2*H15*100/(Datos_vigas!$B$8*AB15*K15^2*Datos_vigas!$B$5)))*AB15*K15*Datos_vigas!$B$5/Datos_vigas!$B$6,0.0033*J15*K15)))) -> 3.3165 | N15: 3 | O15: 12 | P15: =IF(NOT(ISNUMBER(I15)),"---",IF(I15<=0,"---",IF(I15*100/(Datos_vigas!$B$8*AC15*K15^2*Datos_vigas!$B$5)>=0.5,"REVISAR",MAX((1-SQRT(1-2*I15*100/(Datos_vigas!$B$8*AC15*K15^2*Datos_vigas!$B$5)))*AC15*K15*Datos_vigas!$B$5/Datos_vigas!$B$6,0.0033*J15*K15)))) -> 3.3165 | Q15: 3 | R15: 12 | S15: =F15/(J15*0.85*K15) -> 6.9694018 | T15: =G15/(J15*0.85*K15) -> 6.9694018 | U15: 6 | V15: 30 | W15: =IF(OR(M15="REVISAR",P15="REVISAR"),"SECCION INSUF.",IF(NOT(AND(M15<>"REVISAR",P15<>"REVISAR",IF(ISNUMBER(M15),N15*PI()*(O15/10)^2/4>=M15,TRUE()),IF(ISNUMBER(P15),Q15*PI()*(R15/10)^2/4>=P15,TRUE()),IF(ISNUMBER(M15),M15<=0.0163*AB15*K15,TRUE()),IF(ISNUMBER(P15),P15<=0.0163*AC15*K15,TRUE()))),"NO VERIFICA FLEX.",IF(NOT(F15<=Datos_vigas!$B$9*(0.53*SQRT(Datos_vigas!$B$5)*J15*K15+2*PI()*(U15/10)^2/4*Datos_vigas!$B$6*K15/V15)),"NO VERIF. CORTE",IF(NOT(L15>=C15*100/VLOOKUP(Y15,Datos_vigas!$A$19:$E$23,5,0)),"VERIFICAR FLECHA","VERIFICA")))) -> VERIFICA | X15: Descarga en la COL 04 de 20x20 y en VI 06. | Y15: Continua | Z15: Invertida | AA15: 12 | AB15: =IF(Z15="Colgante",MIN(C15*100/4,J15+16*AA15),J15) -> 15 | AC15: =IF(Z15="Invertida",MIN(C15*100/4,J15+16*AA15),J15) -> 121.75 | AF15: 1.065 | AG15: 2.6 | AH15: 3
B16: VI 09 | C16: 4.87 | D16: =(Datos_vigas!$B$10*(VLOOKUP($A$4,Datos_vigas!$A$14:$E$15,2,0)*AF16+Datos_vigas!$B$7*J16*L16/10000+Datos_vigas!$B$16*AG16)+Datos_vigas!$B$11*VLOOKUP($A$4,Datos_vigas!$A$14:$E$15,3,0)*AF16) -> 2600.42 | F16: =VLOOKUP(Y16,Datos_vigas!$A$19:$E$23,4,0)*D16*C16+IF(OR(AD16="",AE16=""),0,AD16*MAX(AE16,C16-AE16)/C16) -> 6332.0227 | G16: =F16 -> 6332.0227 | H16: =VLOOKUP(Y16,Datos_vigas!$A$19:$E$23,2,0)*D16*C16^2+0.75*1000*IF(OR(AD16="",AE16=""),0,AD16*AE16*(C16-AE16)/C16/1000) -> 7709.2376 | I16: =IF(VLOOKUP(Y16,Datos_vigas!$A$19:$E$23,3,0)=0,"---",VLOOKUP(Y16,Datos_vigas!$A$19:$E$23,3,0)*D16*C16^2+0.5*1000*IF(OR(AD16="",AE16=""),0,AD16*AE16*(C16-AE16)/C16/1000)) -> --- | J16: 15 | K16: =L16-AH16 -> 67 | L16: 70 | M16: =IF(NOT(ISNUMBER(H16)),"---",IF(H16<=0,"---",IF(H16*100/(Datos_vigas!$B$8*AB16*K16^2*Datos_vigas!$B$5)>=0.5,"REVISAR",MAX((1-SQRT(1-2*H16*100/(Datos_vigas!$B$8*AB16*K16^2*Datos_vigas!$B$5)))*AB16*K16*Datos_vigas!$B$5/Datos_vigas!$B$6,0.0033*J16*K16)))) -> 3.3165 | N16: 3 | O16: 12 | P16: =IF(NOT(ISNUMBER(I16)),"---",IF(I16<=0,"---",IF(I16*100/(Datos_vigas!$B$8*AC16*K16^2*Datos_vigas!$B$5)>=0.5,"REVISAR",MAX((1-SQRT(1-2*I16*100/(Datos_vigas!$B$8*AC16*K16^2*Datos_vigas!$B$5)))*AC16*K16*Datos_vigas!$B$5/Datos_vigas!$B$6,0.0033*J16*K16)))) -> --- | Q16: --- | R16: --- | S16: =F16/(J16*0.85*K16) -> 7.4123766 | T16: =G16/(J16*0.85*K16) -> 7.4123766 | U16: 6 | V16: 30 | W16: =IF(OR(M16="REVISAR",P16="REVISAR"),"SECCION INSUF.",IF(NOT(AND(M16<>"REVISAR",P16<>"REVISAR",IF(ISNUMBER(M16),N16*PI()*(O16/10)^2/4>=M16,TRUE()),IF(ISNUMBER(P16),Q16*PI()*(R16/10)^2/4>=P16,TRUE()),IF(ISNUMBER(M16),M16<=0.0163*AB16*K16,TRUE()),IF(ISNUMBER(P16),P16<=0.0163*AC16*K16,TRUE()))),"NO VERIFICA FLEX.",IF(NOT(F16<=Datos_vigas!$B$9*(0.53*SQRT(Datos_vigas!$B$5)*J16*K16+2*PI()*(U16/10)^2/4*Datos_vigas!$B$6*K16/V16)),"NO VERIF. CORTE",IF(NOT(L16>=C16*100/VLOOKUP(Y16,Datos_vigas!$A$19:$E$23,5,0)),"VERIFICAR FLECHA","VERIFICA")))) -> VERIFICA | X16: Viga secundaria: sus dos extremos descargan en otras vigas, VI 04a y VI 06, no en columnas ni tabiques. | Y16: Simplemente apoyada | Z16: Invertida | AA16: 12 | AB16: =IF(Z16="Colgante",MIN(C16*100/4,J16+16*AA16),J16) -> 15 | AC16: =IF(Z16="Invertida",MIN(C16*100/4,J16+16*AA16),J16) -> 121.75 | AF16: 1.549 | AG16: 2.6 | AH16: 3
B17: VI 10a | C17: 2.55 | D17: =(Datos_vigas!$B$10*(VLOOKUP($A$4,Datos_vigas!$A$14:$E$15,2,0)*AF17+Datos_vigas!$B$7*J17*L17/10000+Datos_vigas!$B$16*AG17)+Datos_vigas!$B$11*VLOOKUP($A$4,Datos_vigas!$A$14:$E$15,3,0)*AF17) -> 1082.4 | F17: =VLOOKUP(Y17,Datos_vigas!$A$19:$E$23,4,0)*D17*C17+IF(OR(AD17="",AE17=""),0,AD17*MAX(AE17,C17-AE17)/C17) -> 1587.069 | G17: =F17 -> 1587.069 | H17: =VLOOKUP(Y17,Datos_vigas!$A$19:$E$23,2,0)*D17*C17^2+0.75*1000*IF(OR(AD17="",AE17=""),0,AD17*AE17*(C17-AE17)/C17/1000) -> 502.7462 | I17: =IF(VLOOKUP(Y17,Datos_vigas!$A$19:$E$23,3,0)=0,"---",VLOOKUP(Y17,Datos_vigas!$A$19:$E$23,3,0)*D17*C17^2+0.5*1000*IF(OR(AD17="",AE17=""),0,AD17*AE17*(C17-AE17)/C17/1000)) -> 703.8306 | J17: 15 | K17: =L17-AH17 -> 67 | L17: 70 | M17: =IF(NOT(ISNUMBER(H17)),"---",IF(H17<=0,"---",IF(H17*100/(Datos_vigas!$B$8*AB17*K17^2*Datos_vigas!$B$5)>=0.5,"REVISAR",MAX((1-SQRT(1-2*H17*100/(Datos_vigas!$B$8*AB17*K17^2*Datos_vigas!$B$5)))*AB17*K17*Datos_vigas!$B$5/Datos_vigas!$B$6,0.0033*J17*K17)))) -> 3.3165 | N17: 3 | O17: 12 | P17: =IF(NOT(ISNUMBER(I17)),"---",IF(I17<=0,"---",IF(I17*100/(Datos_vigas!$B$8*AC17*K17^2*Datos_vigas!$B$5)>=0.5,"REVISAR",MAX((1-SQRT(1-2*I17*100/(Datos_vigas!$B$8*AC17*K17^2*Datos_vigas!$B$5)))*AC17*K17*Datos_vigas!$B$5/Datos_vigas!$B$6,0.0033*J17*K17)))) -> 3.3165 | Q17: 3 | R17: 12 | S17: =F17/(J17*0.85*K17) -> 1.8578507 | T17: =G17/(J17*0.85*K17) -> 1.8578507 | U17: 6 | V17: 30 | W17: =IF(OR(M17="REVISAR",P17="REVISAR"),"SECCION INSUF.",IF(NOT(AND(M17<>"REVISAR",P17<>"REVISAR",IF(ISNUMBER(M17),N17*PI()*(O17/10)^2/4>=M17,TRUE()),IF(ISNUMBER(P17),Q17*PI()*(R17/10)^2/4>=P17,TRUE()),IF(ISNUMBER(M17),M17<=0.0163*AB17*K17,TRUE()),IF(ISNUMBER(P17),P17<=0.0163*AC17*K17,TRUE()))),"NO VERIFICA FLEX.",IF(NOT(F17<=Datos_vigas!$B$9*(0.53*SQRT(Datos_vigas!$B$5)*J17*K17+2*PI()*(U17/10)^2/4*Datos_vigas!$B$6*K17/V17)),"NO VERIF. CORTE",IF(NOT(L17>=C17*100/VLOOKUP(Y17,Datos_vigas!$A$19:$E$23,5,0)),"VERIFICAR FLECHA","VERIFICA")))) -> VERIFICA | Y17: Continua | Z17: Invertida | AA17: 12 | AB17: =IF(Z17="Colgante",MIN(C17*100/4,J17+16*AA17),J17) -> 15 | AC17: =IF(Z17="Invertida",MIN(C17*100/4,J17+16*AA17),J17) -> 63.75 | AF17: 0 | AG17: 2.6 | AH17: 3
B18: VI 10b | C18: 4 | D18: =(Datos_vigas!$B$10*(VLOOKUP($A$4,Datos_vigas!$A$14:$E$15,2,0)*AF18+Datos_vigas!$B$7*J18*L18/10000+Datos_vigas!$B$16*AG18)+Datos_vigas!$B$11*VLOOKUP($A$4,Datos_vigas!$A$14:$E$15,3,0)*AF18) -> 2870.9 | F18: =VLOOKUP(Y18,Datos_vigas!$A$19:$E$23,4,0)*D18*C18+IF(OR(AD18="",AE18=""),0,AD18*MAX(AE18,C18-AE18)/C18) -> 6603.07 | G18: =F18 -> 6603.07 | H18: =VLOOKUP(Y18,Datos_vigas!$A$19:$E$23,2,0)*D18*C18^2+0.75*1000*IF(OR(AD18="",AE18=""),0,AD18*AE18*(C18-AE18)/C18/1000) -> 3281.0942 | I18: =IF(VLOOKUP(Y18,Datos_vigas!$A$19:$E$23,3,0)=0,"---",VLOOKUP(Y18,Datos_vigas!$A$19:$E$23,3,0)*D18*C18^2+0.5*1000*IF(OR(AD18="",AE18=""),0,AD18*AE18*(C18-AE18)/C18/1000)) -> 4593.44 | J18: 15 | K18: =L18-AH18 -> 67 | L18: 70 | M18: =IF(NOT(ISNUMBER(H18)),"---",IF(H18<=0,"---",IF(H18*100/(Datos_vigas!$B$8*AB18*K18^2*Datos_vigas!$B$5)>=0.5,"REVISAR",MAX((1-SQRT(1-2*H18*100/(Datos_vigas!$B$8*AB18*K18^2*Datos_vigas!$B$5)))*AB18*K18*Datos_vigas!$B$5/Datos_vigas!$B$6,0.0033*J18*K18)))) -> 3.3165 | N18: 3 | O18: 12 | P18: =IF(NOT(ISNUMBER(I18)),"---",IF(I18<=0,"---",IF(I18*100/(Datos_vigas!$B$8*AC18*K18^2*Datos_vigas!$B$5)>=0.5,"REVISAR",MAX((1-SQRT(1-2*I18*100/(Datos_vigas!$B$8*AC18*K18^2*Datos_vigas!$B$5)))*AC18*K18*Datos_vigas!$B$5/Datos_vigas!$B$6,0.0033*J18*K18)))) -> 3.3165 | Q18: 3 | R18: 12 | S18: =F18/(J18*0.85*K18) -> 7.7296693 | T18: =G18/(J18*0.85*K18) -> 7.7296693 | U18: 6 | V18: 30 | W18: =IF(OR(M18="REVISAR",P18="REVISAR"),"SECCION INSUF.",IF(NOT(AND(M18<>"REVISAR",P18<>"REVISAR",IF(ISNUMBER(M18),N18*PI()*(O18/10)^2/4>=M18,TRUE()),IF(ISNUMBER(P18),Q18*PI()*(R18/10)^2/4>=P18,TRUE()),IF(ISNUMBER(M18),M18<=0.0163*AB18*K18,TRUE()),IF(ISNUMBER(P18),P18<=0.0163*AC18*K18,TRUE()))),"NO VERIFICA FLEX.",IF(NOT(F18<=Datos_vigas!$B$9*(0.53*SQRT(Datos_vigas!$B$5)*J18*K18+2*PI()*(U18/10)^2/4*Datos_vigas!$B$6*K18/V18)),"NO VERIF. CORTE",IF(NOT(L18>=C18*100/VLOOKUP(Y18,Datos_vigas!$A$19:$E$23,5,0)),"VERIFICAR FLECHA","VERIFICA")))) -> VERIFICA | Y18: Continua | Z18: Invertida | AA18: 12 | AB18: =IF(Z18="Colgante",MIN(C18*100/4,J18+16*AA18),J18) -> 15 | AC18: =IF(Z18="Invertida",MIN(C18*100/4,J18+16*AA18),J18) -> 100 | AF18: 1.825 | AG18: 2.6 | AH18: 3
B19: VI 10c | C19: 3.6 | D19: =(Datos_vigas!$B$10*(VLOOKUP($A$4,Datos_vigas!$A$14:$E$15,2,0)*AF19+Datos_vigas!$B$7*J19*L19/10000+Datos_vigas!$B$16*AG19)+Datos_vigas!$B$11*VLOOKUP($A$4,Datos_vigas!$A$14:$E$15,3,0)*AF19) -> 1082.4 | F19: =VLOOKUP(Y19,Datos_vigas!$A$19:$E$23,4,0)*D19*C19+IF(OR(AD19="",AE19=""),0,AD19*MAX(AE19,C19-AE19)/C19) -> 2240.568 | G19: =F19 -> 2240.568 | H19: =VLOOKUP(Y19,Datos_vigas!$A$19:$E$23,2,0)*D19*C19^2+0.75*1000*IF(OR(AD19="",AE19=""),0,AD19*AE19*(C19-AE19)/C19/1000) -> 1002.0132 | I19: =IF(VLOOKUP(Y19,Datos_vigas!$A$19:$E$23,3,0)=0,"---",VLOOKUP(Y19,Datos_vigas!$A$19:$E$23,3,0)*D19*C19^2+0.5*1000*IF(OR(AD19="",AE19=""),0,AD19*AE19*(C19-AE19)/C19/1000)) -> 1402.7904 | J19: 15 | K19: =L19-AH19 -> 67 | L19: 70 | M19: =IF(NOT(ISNUMBER(H19)),"---",IF(H19<=0,"---",IF(H19*100/(Datos_vigas!$B$8*AB19*K19^2*Datos_vigas!$B$5)>=0.5,"REVISAR",MAX((1-SQRT(1-2*H19*100/(Datos_vigas!$B$8*AB19*K19^2*Datos_vigas!$B$5)))*AB19*K19*Datos_vigas!$B$5/Datos_vigas!$B$6,0.0033*J19*K19)))) -> 3.3165 | N19: 3 | O19: 12 | P19: =IF(NOT(ISNUMBER(I19)),"---",IF(I19<=0,"---",IF(I19*100/(Datos_vigas!$B$8*AC19*K19^2*Datos_vigas!$B$5)>=0.5,"REVISAR",MAX((1-SQRT(1-2*I19*100/(Datos_vigas!$B$8*AC19*K19^2*Datos_vigas!$B$5)))*AC19*K19*Datos_vigas!$B$5/Datos_vigas!$B$6,0.0033*J19*K19)))) -> 3.3165 | Q19: 3 | R19: 12 | S19: =F19/(J19*0.85*K19) -> 2.6228481 | T19: =G19/(J19*0.85*K19) -> 2.6228481 | U19: 6 | V19: 30 | W19: =IF(OR(M19="REVISAR",P19="REVISAR"),"SECCION INSUF.",IF(NOT(AND(M19<>"REVISAR",P19<>"REVISAR",IF(ISNUMBER(M19),N19*PI()*(O19/10)^2/4>=M19,TRUE()),IF(ISNUMBER(P19),Q19*PI()*(R19/10)^2/4>=P19,TRUE()),IF(ISNUMBER(M19),M19<=0.0163*AB19*K19,TRUE()),IF(ISNUMBER(P19),P19<=0.0163*AC19*K19,TRUE()))),"NO VERIFICA FLEX.",IF(NOT(F19<=Datos_vigas!$B$9*(0.53*SQRT(Datos_vigas!$B$5)*J19*K19+2*PI()*(U19/10)^2/4*Datos_vigas!$B$6*K19/V19)),"NO VERIF. CORTE",IF(NOT(L19>=C19*100/VLOOKUP(Y19,Datos_vigas!$A$19:$E$23,5,0)),"VERIFICAR FLECHA","VERIFICA")))) -> VERIFICA | Y19: Continua | Z19: Invertida | AA19: 12 | AB19: =IF(Z19="Colgante",MIN(C19*100/4,J19+16*AA19),J19) -> 15 | AC19: =IF(Z19="Invertida",MIN(C19*100/4,J19+16*AA19),J19) -> 90 | AF19: 0 | AG19: 2.6 | AH19: 3
B20: VI 11a | C20: 7.68 | D20: =(Datos_vigas!$B$10*(VLOOKUP($A$4,Datos_vigas!$A$14:$E$15,2,0)*AF20+Datos_vigas!$B$7*J20*L20/10000+Datos_vigas!$B$16*AG20)+Datos_vigas!$B$11*VLOOKUP($A$4,Datos_vigas!$A$14:$E$15,3,0)*AF20) -> 2870.9 | F20: =VLOOKUP(Y20,Datos_vigas!$A$19:$E$23,4,0)*D20*C20+IF(OR(AD20="",AE20=""),0,AD20*MAX(AE20,C20-AE20)/C20) -> 13780.32 | G20: =F20 -> 13780.32 | H20: =VLOOKUP(Y20,Datos_vigas!$A$19:$E$23,2,0)*D20*C20^2+0.75*1000*IF(OR(AD20="",AE20=""),0,AD20*AE20*(C20-AE20)/C20/1000) -> 11905.773 | I20: =IF(VLOOKUP(Y20,Datos_vigas!$A$19:$E$23,3,0)=0,"---",VLOOKUP(Y20,Datos_vigas!$A$19:$E$23,3,0)*D20*C20^2+0.5*1000*IF(OR(AD20="",AE20=""),0,AD20*AE20*(C20-AE20)/C20/1000)) -> 21166.572 | J20: 15 | K20: =L20-AH20 -> 67 | L20: 70 | M20: =IF(NOT(ISNUMBER(H20)),"---",IF(H20<=0,"---",IF(H20*100/(Datos_vigas!$B$8*AB20*K20^2*Datos_vigas!$B$5)>=0.5,"REVISAR",MAX((1-SQRT(1-2*H20*100/(Datos_vigas!$B$8*AB20*K20^2*Datos_vigas!$B$5)))*AB20*K20*Datos_vigas!$B$5/Datos_vigas!$B$6,0.0033*J20*K20)))) -> 4.9442478 | N20: 2 | O20: 20 | P20: =IF(NOT(ISNUMBER(I20)),"---",IF(I20<=0,"---",IF(I20*100/(Datos_vigas!$B$8*AC20*K20^2*Datos_vigas!$B$5)>=0.5,"REVISAR",MAX((1-SQRT(1-2*I20*100/(Datos_vigas!$B$8*AC20*K20^2*Datos_vigas!$B$5)))*AC20*K20*Datos_vigas!$B$5/Datos_vigas!$B$6,0.0033*J20*K20)))) -> 8.4126611 | Q20: 2 | R20: 25 | S20: =F20/(J20*0.85*K20) -> 16.131484 | T20: =G20/(J20*0.85*K20) -> 16.131484 | U20: 6 | V20: 10 | W20: =IF(OR(M20="REVISAR",P20="REVISAR"),"SECCION INSUF.",IF(NOT(AND(M20<>"REVISAR",P20<>"REVISAR",IF(ISNUMBER(M20),N20*PI()*(O20/10)^2/4>=M20,TRUE()),IF(ISNUMBER(P20),Q20*PI()*(R20/10)^2/4>=P20,TRUE()),IF(ISNUMBER(M20),M20<=0.0163*AB20*K20,TRUE()),IF(ISNUMBER(P20),P20<=0.0163*AC20*K20,TRUE()))),"NO VERIFICA FLEX.",IF(NOT(F20<=Datos_vigas!$B$9*(0.53*SQRT(Datos_vigas!$B$5)*J20*K20+2*PI()*(U20/10)^2/4*Datos_vigas!$B$6*K20/V20)),"NO VERIF. CORTE",IF(NOT(L20>=C20*100/VLOOKUP(Y20,Datos_vigas!$A$19:$E$23,5,0)),"VERIFICAR FLECHA","VERIFICA")))) -> VERIFICA | X20: El plano rotula 'VI 111'; se interpreta 11a por el orden a-b-c. Sin apoyo intermedio, empotrada en tabiques. Apoya en columna COL 02 de 15x30 y en el tabique T08a. Viga de borde: recibe la reaccion de la losa excentrica y queda sometida a TORSION, no verificada en esta planilla. | Y20: Empotrada-apoyada | Z20: Invertida | AA20: 12 | AB20: =IF(Z20="Colgante",MIN(C20*100/4,J20+16*AA20),J20) -> 15 | AC20: =IF(Z20="Invertida",MIN(C20*100/4,J20+16*AA20),J20) -> 192 | AF20: 1.825 | AG20: 2.6 | AH20: 3
B21: VI 11b | C21: 3.45 | D21: =(Datos_vigas!$B$10*(VLOOKUP($A$4,Datos_vigas!$A$14:$E$15,2,0)*AF21+Datos_vigas!$B$7*J21*L21/10000+Datos_vigas!$B$16*AG21)+Datos_vigas!$B$11*VLOOKUP($A$4,Datos_vigas!$A$14:$E$15,3,0)*AF21) -> 1082.4 | F21: =VLOOKUP(Y21,Datos_vigas!$A$19:$E$23,4,0)*D21*C21+IF(OR(AD21="",AE21=""),0,AD21*MAX(AE21,C21-AE21)/C21) -> 2147.211 | G21: =F21 -> 2147.211 | H21: =VLOOKUP(Y21,Datos_vigas!$A$19:$E$23,2,0)*D21*C21^2+0.75*1000*IF(OR(AD21="",AE21=""),0,AD21*AE21*(C21-AE21)/C21/1000) -> 920.25169 | I21: =IF(VLOOKUP(Y21,Datos_vigas!$A$19:$E$23,3,0)=0,"---",VLOOKUP(Y21,Datos_vigas!$A$19:$E$23,3,0)*D21*C21^2+0.5*1000*IF(OR(AD21="",AE21=""),0,AD21*AE21*(C21-AE21)/C21/1000)) -> 1288.3266 | J21: 15 | K21: =L21-AH21 -> 67 | L21: 70 | M21: =IF(NOT(ISNUMBER(H21)),"---",IF(H21<=0,"---",IF(H21*100/(Datos_vigas!$B$8*AB21*K21^2*Datos_vigas!$B$5)>=0.5,"REVISAR",MAX((1-SQRT(1-2*H21*100/(Datos_vigas!$B$8*AB21*K21^2*Datos_vigas!$B$5)))*AB21*K21*Datos_vigas!$B$5/Datos_vigas!$B$6,0.0033*J21*K21)))) -> 3.3165 | N21: 3 | O21: 12 | P21: =IF(NOT(ISNUMBER(I21)),"---",IF(I21<=0,"---",IF(I21*100/(Datos_vigas!$B$8*AC21*K21^2*Datos_vigas!$B$5)>=0.5,"REVISAR",MAX((1-SQRT(1-2*I21*100/(Datos_vigas!$B$8*AC21*K21^2*Datos_vigas!$B$5)))*AC21*K21*Datos_vigas!$B$5/Datos_vigas!$B$6,0.0033*J21*K21)))) -> 3.3165 | Q21: 3 | R21: 12 | S21: =F21/(J21*0.85*K21) -> 2.5135628 | T21: =G21/(J21*0.85*K21) -> 2.5135628 | U21: 6 | V21: 30 | W21: =IF(OR(M21="REVISAR",P21="REVISAR"),"SECCION INSUF.",IF(NOT(AND(M21<>"REVISAR",P21<>"REVISAR",IF(ISNUMBER(M21),N21*PI()*(O21/10)^2/4>=M21,TRUE()),IF(ISNUMBER(P21),Q21*PI()*(R21/10)^2/4>=P21,TRUE()),IF(ISNUMBER(M21),M21<=0.0163*AB21*K21,TRUE()),IF(ISNUMBER(P21),P21<=0.0163*AC21*K21,TRUE()))),"NO VERIFICA FLEX.",IF(NOT(F21<=Datos_vigas!$B$9*(0.53*SQRT(Datos_vigas!$B$5)*J21*K21+2*PI()*(U21/10)^2/4*Datos_vigas!$B$6*K21/V21)),"NO VERIF. CORTE",IF(NOT(L21>=C21*100/VLOOKUP(Y21,Datos_vigas!$A$19:$E$23,5,0)),"VERIFICAR FLECHA","VERIFICA")))) -> VERIFICA | X21: Viga de borde: recibe la reaccion de la losa excentrica y queda sometida a TORSION, no verificada en esta planilla. | Y21: Continua | Z21: Invertida | AA21: 12 | AB21: =IF(Z21="Colgante",MIN(C21*100/4,J21+16*AA21),J21) -> 15 | AC21: =IF(Z21="Invertida",MIN(C21*100/4,J21+16*AA21),J21) -> 86.25 | AF21: 0 | AG21: 2.6 | AH21: 3
