Workbook

Sheet Iluminacion y ventilacion
A1: PLANILLA DE ILUMINACION Y VENTILACION
A2: Local | B2: (a) Medidas | C2: (b) Medidas | D2: (Area) Medidas | E2: Iluminacion | H2: Ventilacion | K2: VERIFICACION | L2: OBSERVACIONES
E3: Coef. | F3: Area requerida | G3: Area proyectada | H3: Coef. | I3: Area requerida | J3: Area proyectada
A4: PB
A5: 01 - Cocina / comedor | B5: 7.5 | C5: 3.5 | D5: =B5*C5 | E5: 9 | F5: =D5/E5 | G5: 16.95 | H5: i/3 | I5: =F5/3 | J5: 8.48 | K5: =IF(OR(G5="COND",J5="COND"),"COND",IF(AND(G5>=F5,J5>=I5),"CUMPLE","NO CUMPLE"))
A6: 02 - Deposito | B6: 3.8 | C6: 3.1 | D6: =B6*C6 | E6: - | F6: - | G6: - | H6: - | I6: - | J6: - | K6: NO EXIGIBLE | L6: Local no habitable: el codigo no le exige iluminacion ni ventilacion natural. Si se lo considera habitable, hay que preverle conducto.
A7: 03 - Lavadero | B7: 3.5 | C7: 1.7 | D7: =B7*C7 | E7: 9 | F7: =D7/E7 | G7: 10.5 | H7: i/3 | I7: =F7/3 | J7: 1.6 | K7: =IF(OR(G7="COND",J7="COND"),"COND",IF(AND(G7>=F7,J7>=I7),"CUMPLE","NO CUMPLE"))
A8: 06 - Living / comedor | B8: 8.4 | C8: 4 | D8: =B8*C8 | E8: 9 | F8: =D8/E8 | G8: 34.05 | H8: i/3 | I8: =F8/3 | J8: 15 | K8: =IF(OR(G8="COND",J8="COND"),"COND",IF(AND(G8>=F8,J8>=I8),"CUMPLE","NO CUMPLE"))
A9: 07 - Hall / ingreso | B9: 3.5 | C9: 2.15 | D9: =B9*C9 | E9: 9 | F9: =D9/E9 | G9: 10.5 | H9: i/3 | I9: =F9/3 | J9: 1.6 | K9: =IF(OR(G9="COND",J9="COND"),"COND",IF(AND(G9>=F9,J9>=I9),"CUMPLE","NO CUMPLE")) | L9: CORREGIDO: la planilla original repetia los valores del local 03 (0,66 y 0,22). Con 7,53 m2 corresponden 0,84 y 0,28. Cumple igual.
A10: 09 - Dormitorio suite | B10: 3.5 | C10: 3.5 | D10: =B10*C10 | E10: 9 | F10: =D10/E10 | G10: 6 | H10: i/3 | I10: =F10/3 | J10: 3 | K10: =IF(OR(G10="COND",J10="COND"),"COND",IF(AND(G10>=F10,J10>=I10),"CUMPLE","NO CUMPLE"))
A11: 10 - Bano suite | B11: 3.3 | C11: 1.7 | D11: =B11*C11 | E11: 9 | F11: =D11/E11 | G11: COND | H11: i/3 | I11: =F11/3 | J11: COND | K11: =IF(OR(G11="COND",J11="COND"),"COND",IF(AND(G11>=F11,J11>=I11),"CUMPLE","NO CUMPLE")) | L11: Sin ventana al exterior: se ventila por conducto o extraccion mecanica.
A12: 11 - Bano visita | B12: 2.4 | C12: 1.3 | D12: =B12*C12 | E12: 9 | F12: =D12/E12 | G12: COND | H12: i/3 | I12: =F12/3 | J12: COND | K12: =IF(OR(G12="COND",J12="COND"),"COND",IF(AND(G12>=F12,J12>=I12),"CUMPLE","NO CUMPLE")) | L12: Sin ventana al exterior: se ventila por conducto o extraccion mecanica.
A13: 12 - Bano exterior | B13: 1.9 | C13: 0.95 | D13: =B13*C13 | E13: 9 | F13: =D13/E13 | G13: COND | H13: i/3 | I13: =F13/3 | J13: COND | K13: =IF(OR(G13="COND",J13="COND"),"COND",IF(AND(G13>=F13,J13>=I13),"CUMPLE","NO CUMPLE")) | L13: Sin ventana al exterior: se ventila por conducto o extraccion mecanica.
A14: PA
A15: 13 - Dormitorio 1 | B15: 4.25 | C15: 4 | D15: =B15*C15 | E15: 9 | F15: =D15/E15 | G15: 8.75 | H15: i/3 | I15: =F15/3 | J15: 4.38 | K15: =IF(OR(G15="COND",J15="COND"),"COND",IF(AND(G15>=F15,J15>=I15),"CUMPLE","NO CUMPLE"))
A16: 14 - Estar / Playroom | B16: 4 | C16: 4.1 | D16: =B16*C16 | E16: 9 | F16: =D16/E16 | G16: 5 | H16: i/3 | I16: =F16/3 | J16: 5 | K16: =IF(OR(G16="COND",J16="COND"),"COND",IF(AND(G16>=F16,J16>=I16),"CUMPLE","NO CUMPLE")) | L16: La superficie abrible declarada iguala a la vidriada: supondria una carpinteria 100% abrible. En el resto de los locales la relacion es del 50%. Verificar.
A17: 15 - Dormitorio 2 | B17: 3.5 | C17: 4.05 | D17: =B17*C17 | E17: 9 | F17: =D17/E17 | G17: 3.75 | H17: i/3 | I17: =F17/3 | J17: 1.88 | K17: =IF(OR(G17="COND",J17="COND"),"COND",IF(AND(G17>=F17,J17>=I17),"CUMPLE","NO CUMPLE"))
A18: 17 - Bano | B18: 2.2 | C18: 1.6 | D18: =B18*C18 | E18: 9 | F18: =D18/E18 | G18: 1.875 | H18: i/3 | I18: =F18/3 | J18: 0.94 | K18: =IF(OR(G18="COND",J18="COND"),"COND",IF(AND(G18>=F18,J18>=I18),"CUMPLE","NO CUMPLE"))

Sheet Planilla vigas
A1: VIGAS H°A° H-21 ACERO 42/50
A2: NIVEL | B2: POSICION | C2: LUZ (m) | D2: CARGAS (kg/m) | F2: REACCIONES | H2: MOMENTO TRAMO (kgm) | I2: MOMENTO APOYO (kgm) | J2: DIMENSIONES | M2: ARMADURA TRAMO | P2: ARMADURA APOYO | S2: T (kg/cm2) | V2: ESTRIBOS | W2: VERIFICACION | X2: OBSERVACIONES | Y2: DATOS AUXILIARES
D3: p | E3: diagrama | F3: RA | G3: RB | J3: b | K3: h | L3: d | M3: cm2 | N3: n | O3: o | P3: cm2 | Q3: n | R3: o | S3: A | T3: B | U3: o | V3: SEPAR | Y3: esquema | Z3: tipo | AA3: hf losa | AB3: b ef tramo | AC3: b ef apoyo | AD3: B trib. | AE3: h muro | AF3: rec.
A4: PA | B4: VI 01a | C4: 9.9 | D4: =(Datos_vigas!$B$10*(VLOOKUP($A$4,Datos_vigas!$A$14:$E$15,2,0)*AD4+Datos_vigas!$B$7*J4*L4/10000+Datos_vigas!$B$16*AE4)+Datos_vigas!$B$11*VLOOKUP($A$4,Datos_vigas!$A$14:$E$15,3,0)*AD4) | F4: =VLOOKUP(Y4,Datos_vigas!$A$19:$E$23,4,0)*D4*C4 | G4: =F4 | H4: =VLOOKUP(Y4,Datos_vigas!$A$19:$E$23,2,0)*D4*C4^2 | I4: =IF(VLOOKUP(Y4,Datos_vigas!$A$19:$E$23,3,0)=0,"---",VLOOKUP(Y4,Datos_vigas!$A$19:$E$23,3,0)*D4*C4^2) | J4: 15 | K4: =L4-AF4 | L4: 70 | M4: =IF(NOT(ISNUMBER(H4)),"---",IF(H4<=0,"---",IF(H4*100/(Datos_vigas!$B$8*AB4*K4^2*Datos_vigas!$B$5)>=0.5,"REVISAR",MAX((1-SQRT(1-2*H4*100/(Datos_vigas!$B$8*AB4*K4^2*Datos_vigas!$B$5)))*AB4*K4*Datos_vigas!$B$5/Datos_vigas!$B$6,0.0033*J4*K4)))) | N4: 3 | O4: 12 | P4: =IF(NOT(ISNUMBER(I4)),"---",IF(I4<=0,"---",IF(I4*100/(Datos_vigas!$B$8*AC4*K4^2*Datos_vigas!$B$5)>=0.5,"REVISAR",MAX((1-SQRT(1-2*I4*100/(Datos_vigas!$B$8*AC4*K4^2*Datos_vigas!$B$5)))*AC4*K4*Datos_vigas!$B$5/Datos_vigas!$B$6,0.0033*J4*K4)))) | Q4: 2 | R4: 20 | S4: =F4/(J4*0.85*K4) | T4: =G4/(J4*0.85*K4) | U4: 6 | V4: 30 | W4: =IF(OR(M4="REVISAR",P4="REVISAR"),"SECCION INSUF.",IF(NOT(AND(M4<>"REVISAR",P4<>"REVISAR",IF(ISNUMBER(M4),N4*PI()*(O4/10)^2/4>=M4,TRUE),IF(ISNUMBER(P4),Q4*PI()*(R4/10)^2/4>=P4,TRUE),IF(ISNUMBER(M4),M4<=0.0163*AB4*K4,TRUE),IF(ISNUMBER(P4),P4<=0.0163*AC4*K4,TRUE))),"NO VERIFICA FLEX.",IF(NOT(F4<=Datos_vigas!$B$9*(0.53*SQRT(Datos_vigas!$B$5)*J4*K4+2*PI()*(U4/10)^2/4*Datos_vigas!$B$6*K4/V4)),"NO VERIF. CORTE",IF(NOT(L4>=C4*100/VLOOKUP(Y4,Datos_vigas!$A$19:$E$23,5,0)),"VERIFICAR FLECHA","VERIFICA")))) | X4: Viga de borde sobre la medianera: NO recibe losa. Solo peso propio y mamposteria. Apoya en el tabique T01a y en la columna COL 01 de 10x10. Viga de borde: recibe la reaccion de la losa excentrica y queda sometida a TORSION, no verificada en esta planilla. | Y4: Continua | Z4: Invertida | AA4: 12 | AB4: =IF(Z4="Colgante",MIN(C4*100/4,J4+16*AA4),J4) | AC4: =IF(Z4="Invertida",MIN(C4*100/4,J4+16*AA4),J4) | AD4: 0 | AE4: 2.6 | AF4: 3
B5: VI 01b | C5: 3.95 | D5: =(Datos_vigas!$B$10*(VLOOKUP($A$4,Datos_vigas!$A$14:$E$15,2,0)*AD5+Datos_vigas!$B$7*J5*L5/10000+Datos_vigas!$B$16*AE5)+Datos_vigas!$B$11*VLOOKUP($A$4,Datos_vigas!$A$14:$E$15,3,0)*AD5) | F5: =VLOOKUP(Y5,Datos_vigas!$A$19:$E$23,4,0)*D5*C5 | G5: =F5 | H5: =VLOOKUP(Y5,Datos_vigas!$A$19:$E$23,2,0)*D5*C5^2 | I5: =IF(VLOOKUP(Y5,Datos_vigas!$A$19:$E$23,3,0)=0,"---",VLOOKUP(Y5,Datos_vigas!$A$19:$E$23,3,0)*D5*C5^2) | J5: 15 | K5: =L5-AF5 | L5: 70 | M5: =IF(NOT(ISNUMBER(H5)),"---",IF(H5<=0,"---",IF(H5*100/(Datos_vigas!$B$8*AB5*K5^2*Datos_vigas!$B$5)>=0.5,"REVISAR",MAX((1-SQRT(1-2*H5*100/(Datos_vigas!$B$8*AB5*K5^2*Datos_vigas!$B$5)))*AB5*K5*Datos_vigas!$B$5/Datos_vigas!$B$6,0.0033*J5*K5)))) | N5: 3 | O5: 12 | P5: =IF(NOT(ISNUMBER(I5)),"---",IF(I5<=0,"---",IF(I5*100/(Datos_vigas!$B$8*AC5*K5^2*Datos_vigas!$B$5)>=0.5,"REVISAR",MAX((1-SQRT(1-2*I5*100/(Datos_vigas!$B$8*AC5*K5^2*Datos_vigas!$B$5)))*AC5*K5*Datos_vigas!$B$5/Datos_vigas!$B$6,0.0033*J5*K5)))) | Q5: 3 | R5: 12 | S5: =F5/(J5*0.85*K5) | T5: =G5/(J5*0.85*K5) | U5: 6 | V5: 30 | W5: =IF(OR(M5="REVISAR",P5="REVISAR"),"SECCION INSUF.",IF(NOT(AND(M5<>"REVISAR",P5<>"REVISAR",IF(ISNUMBER(M5),N5*PI()*(O5/10)^2/4>=M5,TRUE),IF(ISNUMBER(P5),Q5*PI()*(R5/10)^2/4>=P5,TRUE),IF(ISNUMBER(M5),M5<=0.0163*AB5*K5,TRUE),IF(ISNUMBER(P5),P5<=0.0163*AC5*K5,TRUE))),"NO VERIFICA FLEX.",IF(NOT(F5<=Datos_vigas!$B$9*(0.53*SQRT(Datos_vigas!$B$5)*J5*K5+2*PI()*(U5/10)^2/4*Datos_vigas!$B$6*K5/V5)),"NO VERIF. CORTE",IF(NOT(L5>=C5*100/VLOOKUP(Y5,Datos_vigas!$A$19:$E$23,5,0)),"VERIFICAR FLECHA","VERIFICA")))) | X5: Viga de borde: recibe la reaccion de la losa excentrica y queda sometida a TORSION, no verificada en esta planilla. | Y5: Continua | Z5: Invertida | AA5: 12 | AB5: =IF(Z5="Colgante",MIN(C5*100/4,J5+16*AA5),J5) | AC5: =IF(Z5="Invertida",MIN(C5*100/4,J5+16*AA5),J5) | AD5: 0 | AE5: 2.6 | AF5: 3
B6: VI 02 | C6: 9.88 | D6: =(Datos_vigas!$B$10*(VLOOKUP($A$4,Datos_vigas!$A$14:$E$15,2,0)*AD6+Datos_vigas!$B$7*J6*L6/10000+Datos_vigas!$B$16*AE6)+Datos_vigas!$B$11*VLOOKUP($A$4,Datos_vigas!$A$14:$E$15,3,0)*AD6) | F6: =VLOOKUP(Y6,Datos_vigas!$A$19:$E$23,4,0)*D6*C6 | G6: =F6 | H6: =VLOOKUP(Y6,Datos_vigas!$A$19:$E$23,2,0)*D6*C6^2 | I6: =IF(VLOOKUP(Y6,Datos_vigas!$A$19:$E$23,3,0)=0,"---",VLOOKUP(Y6,Datos_vigas!$A$19:$E$23,3,0)*D6*C6^2) | J6: 15 | K6: =L6-AF6 | L6: 70 | M6: =IF(NOT(ISNUMBER(H6)),"---",IF(H6<=0,"---",IF(H6*100/(Datos_vigas!$B$8*AB6*K6^2*Datos_vigas!$B$5)>=0.5,"REVISAR",MAX((1-SQRT(1-2*H6*100/(Datos_vigas!$B$8*AB6*K6^2*Datos_vigas!$B$5)))*AB6*K6*Datos_vigas!$B$5/Datos_vigas!$B$6,0.0033*J6*K6)))) | N6: 4 | O6: 20 | P6: =IF(NOT(ISNUMBER(I6)),"---",IF(I6<=0,"---",IF(I6*100/(Datos_vigas!$B$8*AC6*K6^2*Datos_vigas!$B$5)>=0.5,"REVISAR",MAX((1-SQRT(1-2*I6*100/(Datos_vigas!$B$8*AC6*K6^2*Datos_vigas!$B$5)))*AC6*K6*Datos_vigas!$B$5/Datos_vigas!$B$6,0.0033*J6*K6)))) | Q6: 4 | R6: 25 | S6: =F6/(J6*0.85*K6) | T6: =G6/(J6*0.85*K6) | U6: 8 | V6: 10 | W6: =IF(OR(M6="REVISAR",P6="REVISAR"),"SECCION INSUF.",IF(NOT(AND(M6<>"REVISAR",P6<>"REVISAR",IF(ISNUMBER(M6),N6*PI()*(O6/10)^2/4>=M6,TRUE),IF(ISNUMBER(P6),Q6*PI()*(R6/10)^2/4>=P6,TRUE),IF(ISNUMBER(M6),M6<=0.0163*AB6*K6,TRUE),IF(ISNUMBER(P6),P6<=0.0163*AC6*K6,TRUE))),"NO VERIFICA FLEX.",IF(NOT(F6<=Datos_vigas!$B$9*(0.53*SQRT(Datos_vigas!$B$5)*J6*K6+2*PI()*(U6/10)^2/4*Datos_vigas!$B$6*K6/V6)),"NO VERIF. CORTE",IF(NOT(L6>=C6*100/VLOOKUP(Y6,Datos_vigas!$A$19:$E$23,5,0)),"VERIFICAR FLECHA","VERIFICA")))) | X6: Armadura en 2 capas (rec. 6 cm). NO USAR TEXTO VIEJO. Recibe L03 (2,08 m) y el alero L02, computado como 0,59 m equivalentes por tener menor carga que un entrepiso. Con 9,88 m de luz y 15x60 la armadura de apoyo necesaria (25,5 cm2) supera la cuantia maxima (13,2). Apoyos confirmados en obra: tabique T07 perpendicular en el extremo superior y COL 02 en el inferior, sin apoyo intermedio. Para esta carga harian falta 15x75 (As 16,2 cm2). Verificar la seccion real construida. | Y6: Continua | Z6: Invertida | AA6: 12 | AB6: =IF(Z6="Colgante",MIN(C6*100/4,J6+16*AA6),J6) | AC6: =IF(Z6="Invertida",MIN(C6*100/4,J6+16*AA6),J6) | AD6: 2.689 | AE6: 2.6 | AF6: 6
B7: VI 03c | C7: 3.75 | D7: =(Datos_vigas!$B$10*(VLOOKUP($A$4,Datos_vigas!$A$14:$E$15,2,0)*AD7+Datos_vigas!$B$7*J7*L7/10000+Datos_vigas!$B$16*AE7)+Datos_vigas!$B$11*VLOOKUP($A$4,Datos_vigas!$A$14:$E$15,3,0)*AD7) | F7: =VLOOKUP(Y7,Datos_vigas!$A$19:$E$23,4,0)*D7*C7 | G7: =F7 | H7: =VLOOKUP(Y7,Datos_vigas!$A$19:$E$23,2,0)*D7*C7^2 | I7: =IF(VLOOKUP(Y7,Datos_vigas!$A$19:$E$23,3,0)=0,"---",VLOOKUP(Y7,Datos_vigas!$A$19:$E$23,3,0)*D7*C7^2) | J7: 15 | K7: =L7-AF7 | L7: 70 | M7: =IF(NOT(ISNUMBER(H7)),"---",IF(H7<=0,"---",IF(H7*100/(Datos_vigas!$B$8*AB7*K7^2*Datos_vigas!$B$5)>=0.5,"REVISAR",MAX((1-SQRT(1-2*H7*100/(Datos_vigas!$B$8*AB7*K7^2*Datos_vigas!$B$5)))*AB7*K7*Datos_vigas!$B$5/Datos_vigas!$B$6,0.0033*J7*K7)))) | N7: 3 | O7: 12 | P7: =IF(NOT(ISNUMBER(I7)),"---",IF(I7<=0,"---",IF(I7*100/(Datos_vigas!$B$8*AC7*K7^2*Datos_vigas!$B$5)>=0.5,"REVISAR",MAX((1-SQRT(1-2*I7*100/(Datos_vigas!$B$8*AC7*K7^2*Datos_vigas!$B$5)))*AC7*K7*Datos_vigas!$B$5/Datos_vigas!$B$6,0.0033*J7*K7)))) | Q7: 3 | R7: 12 | S7: =F7/(J7*0.85*K7) | T7: =G7/(J7*0.85*K7) | U7: 6 | V7: 30 | W7: =IF(OR(M7="REVISAR",P7="REVISAR"),"SECCION INSUF.",IF(NOT(AND(M7<>"REVISAR",P7<>"REVISAR",IF(ISNUMBER(M7),N7*PI()*(O7/10)^2/4>=M7,TRUE),IF(ISNUMBER(P7),Q7*PI()*(R7/10)^2/4>=P7,TRUE),IF(ISNUMBER(M7),M7<=0.0163*AB7*K7,TRUE),IF(ISNUMBER(P7),P7<=0.0163*AC7*K7,TRUE))),"NO VERIFICA FLEX.",IF(NOT(F7<=Datos_vigas!$B$9*(0.53*SQRT(Datos_vigas!$B$5)*J7*K7+2*PI()*(U7/10)^2/4*Datos_vigas!$B$6*K7/V7)),"NO VERIF. CORTE",IF(NOT(L7>=C7*100/VLOOKUP(Y7,Datos_vigas!$A$19:$E$23,5,0)),"VERIFICAR FLECHA","VERIFICA")))) | Y7: Continua | Z7: Invertida | AA7: 12 | AB7: =IF(Z7="Colgante",MIN(C7*100/4,J7+16*AA7),J7) | AC7: =IF(Z7="Invertida",MIN(C7*100/4,J7+16*AA7),J7) | AD7: 2.1 | AE7: 2.6 | AF7: 3
B8: VI 04a | C8: 3.75 | D8: =(Datos_vigas!$B$10*(VLOOKUP($A$4,Datos_vigas!$A$14:$E$15,2,0)*AD8+Datos_vigas!$B$7*J8*L8/10000+Datos_vigas!$B$16*AE8)+Datos_vigas!$B$11*VLOOKUP($A$4,Datos_vigas!$A$14:$E$15,3,0)*AD8) | F8: =VLOOKUP(Y8,Datos_vigas!$A$19:$E$23,4,0)*D8*C8 | G8: =F8 | H8: =VLOOKUP(Y8,Datos_vigas!$A$19:$E$23,2,0)*D8*C8^2 | I8: =IF(VLOOKUP(Y8,Datos_vigas!$A$19:$E$23,3,0)=0,"---",VLOOKUP(Y8,Datos_vigas!$A$19:$E$23,3,0)*D8*C8^2) | J8: 15 | K8: =L8-AF8 | L8: 70 | M8: =IF(NOT(ISNUMBER(H8)),"---",IF(H8<=0,"---",IF(H8*100/(Datos_vigas!$B$8*AB8*K8^2*Datos_vigas!$B$5)>=0.5,"REVISAR",MAX((1-SQRT(1-2*H8*100/(Datos_vigas!$B$8*AB8*K8^2*Datos_vigas!$B$5)))*AB8*K8*Datos_vigas!$B$5/Datos_vigas!$B$6,0.0033*J8*K8)))) | N8: 3 | O8: 12 | P8: =IF(NOT(ISNUMBER(I8)),"---",IF(I8<=0,"---",IF(I8*100/(Datos_vigas!$B$8*AC8*K8^2*Datos_vigas!$B$5)>=0.5,"REVISAR",MAX((1-SQRT(1-2*I8*100/(Datos_vigas!$B$8*AC8*K8^2*Datos_vigas!$B$5)))*AC8*K8*Datos_vigas!$B$5/Datos_vigas!$B$6,0.0033*J8*K8)))) | Q8: 3 | R8: 12 | S8: =F8/(J8*0.85*K8) | T8: =G8/(J8*0.85*K8) | U8: 6 | V8: 30 | W8: =IF(OR(M8="REVISAR",P8="REVISAR"),"SECCION INSUF.",IF(NOT(AND(M8<>"REVISAR",P8<>"REVISAR",IF(ISNUMBER(M8),N8*PI()*(O8/10)^2/4>=M8,TRUE),IF(ISNUMBER(P8),Q8*PI()*(R8/10)^2/4>=P8,TRUE),IF(ISNUMBER(M8),M8<=0.0163*AB8*K8,TRUE),IF(ISNUMBER(P8),P8<=0.0163*AC8*K8,TRUE))),"NO VERIFICA FLEX.",IF(NOT(F8<=Datos_vigas!$B$9*(0.53*SQRT(Datos_vigas!$B$5)*J8*K8+2*PI()*(U8/10)^2/4*Datos_vigas!$B$6*K8/V8)),"NO VERIF. CORTE",IF(NOT(L8>=C8*100/VLOOKUP(Y8,Datos_vigas!$A$19:$E$23,5,0)),"VERIFICAR FLECHA","VERIFICA")))) | Y8: Continua | Z8: Invertida | AA8: 12 | AB8: =IF(Z8="Colgante",MIN(C8*100/4,J8+16*AA8),J8) | AC8: =IF(Z8="Invertida",MIN(C8*100/4,J8+16*AA8),J8) | AD8: 0 | AE8: 2.6 | AF8: 3
B9: VI 04b | C9: 3.8 | D9: =(Datos_vigas!$B$10*(VLOOKUP($A$4,Datos_vigas!$A$14:$E$15,2,0)*AD9+Datos_vigas!$B$7*J9*L9/10000+Datos_vigas!$B$16*AE9)+Datos_vigas!$B$11*VLOOKUP($A$4,Datos_vigas!$A$14:$E$15,3,0)*AD9) | F9: =VLOOKUP(Y9,Datos_vigas!$A$19:$E$23,4,0)*D9*C9 | G9: =F9 | H9: =VLOOKUP(Y9,Datos_vigas!$A$19:$E$23,2,0)*D9*C9^2 | I9: =IF(VLOOKUP(Y9,Datos_vigas!$A$19:$E$23,3,0)=0,"---",VLOOKUP(Y9,Datos_vigas!$A$19:$E$23,3,0)*D9*C9^2) | J9: 15 | K9: =L9-AF9 | L9: 70 | M9: =IF(NOT(ISNUMBER(H9)),"---",IF(H9<=0,"---",IF(H9*100/(Datos_vigas!$B$8*AB9*K9^2*Datos_vigas!$B$5)>=0.5,"REVISAR",MAX((1-SQRT(1-2*H9*100/(Datos_vigas!$B$8*AB9*K9^2*Datos_vigas!$B$5)))*AB9*K9*Datos_vigas!$B$5/Datos_vigas!$B$6,0.0033*J9*K9)))) | N9: 3 | O9: 12 | P9: =IF(NOT(ISNUMBER(I9)),"---",IF(I9<=0,"---",IF(I9*100/(Datos_vigas!$B$8*AC9*K9^2*Datos_vigas!$B$5)>=0.5,"REVISAR",MAX((1-SQRT(1-2*I9*100/(Datos_vigas!$B$8*AC9*K9^2*Datos_vigas!$B$5)))*AC9*K9*Datos_vigas!$B$5/Datos_vigas!$B$6,0.0033*J9*K9)))) | Q9: 3 | R9: 12 | S9: =F9/(J9*0.85*K9) | T9: =G9/(J9*0.85*K9) | U9: 6 | V9: 30 | W9: =IF(OR(M9="REVISAR",P9="REVISAR"),"SECCION INSUF.",IF(NOT(AND(M9<>"REVISAR",P9<>"REVISAR",IF(ISNUMBER(M9),N9*PI()*(O9/10)^2/4>=M9,TRUE),IF(ISNUMBER(P9),Q9*PI()*(R9/10)^2/4>=P9,TRUE),IF(ISNUMBER(M9),M9<=0.0163*AB9*K9,TRUE),IF(ISNUMBER(P9),P9<=0.0163*AC9*K9,TRUE))),"NO VERIFICA FLEX.",IF(NOT(F9<=Datos_vigas!$B$9*(0.53*SQRT(Datos_vigas!$B$5)*J9*K9+2*PI()*(U9/10)^2/4*Datos_vigas!$B$6*K9/V9)),"NO VERIF. CORTE",IF(NOT(L9>=C9*100/VLOOKUP(Y9,Datos_vigas!$A$19:$E$23,5,0)),"VERIFICAR FLECHA","VERIFICA")))) | Y9: Continua | Z9: Invertida | AA9: 12 | AB9: =IF(Z9="Colgante",MIN(C9*100/4,J9+16*AA9),J9) | AC9: =IF(Z9="Invertida",MIN(C9*100/4,J9+16*AA9),J9) | AD9: 1.549 | AE9: 2.6 | AF9: 3
B10: VI 06 | C10: 6.53 | D10: =(Datos_vigas!$B$10*(VLOOKUP($A$4,Datos_vigas!$A$14:$E$15,2,0)*AD10+Datos_vigas!$B$7*J10*L10/10000+Datos_vigas!$B$16*AE10)+Datos_vigas!$B$11*VLOOKUP($A$4,Datos_vigas!$A$14:$E$15,3,0)*AD10) | F10: =VLOOKUP(Y10,Datos_vigas!$A$19:$E$23,4,0)*D10*C10 | G10: =F10 | H10: =VLOOKUP(Y10,Datos_vigas!$A$19:$E$23,2,0)*D10*C10^2 | I10: =IF(VLOOKUP(Y10,Datos_vigas!$A$19:$E$23,3,0)=0,"---",VLOOKUP(Y10,Datos_vigas!$A$19:$E$23,3,0)*D10*C10^2) | J10: 15 | K10: =L10-AF10 | L10: 70 | M10: =IF(NOT(ISNUMBER(H10)),"---",IF(H10<=0,"---",IF(H10*100/(Datos_vigas!$B$8*AB10*K10^2*Datos_vigas!$B$5)>=0.5,"REVISAR",MAX((1-SQRT(1-2*H10*100/(Datos_vigas!$B$8*AB10*K10^2*Datos_vigas!$B$5)))*AB10*K10*Datos_vigas!$B$5/Datos_vigas!$B$6,0.0033*J10*K10)))) | N10: 3 | O10: 12 | P10: =IF(NOT(ISNUMBER(I10)),"---",IF(I10<=0,"---",IF(I10*100/(Datos_vigas!$B$8*AC10*K10^2*Datos_vigas!$B$5)>=0.5,"REVISAR",MAX((1-SQRT(1-2*I10*100/(Datos_vigas!$B$8*AC10*K10^2*Datos_vigas!$B$5)))*AC10*K10*Datos_vigas!$B$5/Datos_vigas!$B$6,0.0033*J10*K10)))) | Q10: 2 | R10: 20 | S10: =F10/(J10*0.85*K10) | T10: =G10/(J10*0.85*K10) | U10: 6 | V10: 30 | W10: =IF(OR(M10="REVISAR",P10="REVISAR"),"SECCION INSUF.",IF(NOT(AND(M10<>"REVISAR",P10<>"REVISAR",IF(ISNUMBER(M10),N10*PI()*(O10/10)^2/4>=M10,TRUE),IF(ISNUMBER(P10),Q10*PI()*(R10/10)^2/4>=P10,TRUE),IF(ISNUMBER(M10),M10<=0.0163*AB10*K10,TRUE),IF(ISNUMBER(P10),P10<=0.0163*AC10*K10,TRUE))),"NO VERIFICA FLEX.",IF(NOT(F10<=Datos_vigas!$B$9*(0.53*SQRT(Datos_vigas!$B$5)*J10*K10+2*PI()*(U10/10)^2/4*Datos_vigas!$B$6*K10/V10)),"NO VERIF. CORTE",IF(NOT(L10>=C10*100/VLOOKUP(Y10,Datos_vigas!$A$19:$E$23,5,0)),"VERIFICAR FLECHA","VERIFICA")))) | X10: Longitud total 14,00 m. Sobre su eje hay cuatro columnas: trabaja como viga continua de tres tramos de 4,10, 4,32 y 6,53 m. Se calcula con el mayor. Es el cuarto borde de la losa cruzada L07. Longitud total 14,00 m. Sobre su eje hay cuatro columnas: trabaja como viga continua de tres tramos de 4,10, 4,32 y 6,53 m. Se calcula con el mayor. Es el cuarto borde de la losa cruzada L07. | Y10: Continua | Z10: Invertida | AA10: 12 | AB10: =IF(Z10="Colgante",MIN(C10*100/4,J10+16*AA10),J10) | AC10: =IF(Z10="Invertida",MIN(C10*100/4,J10+16*AA10),J10) | AD10: 1.549 | AE10: 2.6 | AF10: 3
B11: VI 07a | C11: 3.37 | D11: =(Datos_vigas!$B$10*(VLOOKUP($A$4,Datos_vigas!$A$14:$E$15,2,0)*AD11+Datos_vigas!$B$7*J11*L11/10000+Datos_vigas!$B$16*AE11)+Datos_vigas!$B$11*VLOOKUP($A$4,Datos_vigas!$A$14:$E$15,3,0)*AD11) | F11: =VLOOKUP(Y11,Datos_vigas!$A$19:$E$23,4,0)*D11*C11 | G11: =F11 | H11: =VLOOKUP(Y11,Datos_vigas!$A$19:$E$23,2,0)*D11*C11^2 | I11: =IF(VLOOKUP(Y11,Datos_vigas!$A$19:$E$23,3,0)=0,"---",VLOOKUP(Y11,Datos_vigas!$A$19:$E$23,3,0)*D11*C11^2) | J11: 15 | K11: =L11-AF11 | L11: 70 | M11: =IF(NOT(ISNUMBER(H11)),"---",IF(H11<=0,"---",IF(H11*100/(Datos_vigas!$B$8*AB11*K11^2*Datos_vigas!$B$5)>=0.5,"REVISAR",MAX((1-SQRT(1-2*H11*100/(Datos_vigas!$B$8*AB11*K11^2*Datos_vigas!$B$5)))*AB11*K11*Datos_vigas!$B$5/Datos_vigas!$B$6,0.0033*J11*K11)))) | N11: 3 | O11: 12 | P11: =IF(NOT(ISNUMBER(I11)),"---",IF(I11<=0,"---",IF(I11*100/(Datos_vigas!$B$8*AC11*K11^2*Datos_vigas!$B$5)>=0.5,"REVISAR",MAX((1-SQRT(1-2*I11*100/(Datos_vigas!$B$8*AC11*K11^2*Datos_vigas!$B$5)))*AC11*K11*Datos_vigas!$B$5/Datos_vigas!$B$6,0.0033*J11*K11)))) | Q11: 3 | R11: 12 | S11: =F11/(J11*0.85*K11) | T11: =G11/(J11*0.85*K11) | U11: 6 | V11: 30 | W11: =IF(OR(M11="REVISAR",P11="REVISAR"),"SECCION INSUF.",IF(NOT(AND(M11<>"REVISAR",P11<>"REVISAR",IF(ISNUMBER(M11),N11*PI()*(O11/10)^2/4>=M11,TRUE),IF(ISNUMBER(P11),Q11*PI()*(R11/10)^2/4>=P11,TRUE),IF(ISNUMBER(M11),M11<=0.0163*AB11*K11,TRUE),IF(ISNUMBER(P11),P11<=0.0163*AC11*K11,TRUE))),"NO VERIFICA FLEX.",IF(NOT(F11<=Datos_vigas!$B$9*(0.53*SQRT(Datos_vigas!$B$5)*J11*K11+2*PI()*(U11/10)^2/4*Datos_vigas!$B$6*K11/V11)),"NO VERIF. CORTE",IF(NOT(L11>=C11*100/VLOOKUP(Y11,Datos_vigas!$A$19:$E$23,5,0)),"VERIFICAR FLECHA","VERIFICA")))) | X11: Viga de borde: recibe la reaccion de la losa excentrica y queda sometida a TORSION, no verificada en esta planilla. | Y11: Continua | Z11: Invertida | AA11: 12 | AB11: =IF(Z11="Colgante",MIN(C11*100/4,J11+16*AA11),J11) | AC11: =IF(Z11="Invertida",MIN(C11*100/4,J11+16*AA11),J11) | AD11: 0.78 | AE11: 2.6 | AF11: 3
B12: VI 07b | C12: 4.03 | D12: =(Datos_vigas!$B$10*(VLOOKUP($A$4,Datos_vigas!$A$14:$E$15,2,0)*AD12+Datos_vigas!$B$7*J12*L12/10000+Datos_vigas!$B$16*AE12)+Datos_vigas!$B$11*VLOOKUP($A$4,Datos_vigas!$A$14:$E$15,3,0)*AD12) | F12: =VLOOKUP(Y12,Datos_vigas!$A$19:$E$23,4,0)*D12*C12 | G12: =F12 | H12: =VLOOKUP(Y12,Datos_vigas!$A$19:$E$23,2,0)*D12*C12^2 | I12: =IF(VLOOKUP(Y12,Datos_vigas!$A$19:$E$23,3,0)=0,"---",VLOOKUP(Y12,Datos_vigas!$A$19:$E$23,3,0)*D12*C12^2) | J12: 15 | K12: =L12-AF12 | L12: 70 | M12: =IF(NOT(ISNUMBER(H12)),"---",IF(H12<=0,"---",IF(H12*100/(Datos_vigas!$B$8*AB12*K12^2*Datos_vigas!$B$5)>=0.5,"REVISAR",MAX((1-SQRT(1-2*H12*100/(Datos_vigas!$B$8*AB12*K12^2*Datos_vigas!$B$5)))*AB12*K12*Datos_vigas!$B$5/Datos_vigas!$B$6,0.0033*J12*K12)))) | N12: 3 | O12: 12 | P12: =IF(NOT(ISNUMBER(I12)),"---",IF(I12<=0,"---",IF(I12*100/(Datos_vigas!$B$8*AC12*K12^2*Datos_vigas!$B$5)>=0.5,"REVISAR",MAX((1-SQRT(1-2*I12*100/(Datos_vigas!$B$8*AC12*K12^2*Datos_vigas!$B$5)))*AC12*K12*Datos_vigas!$B$5/Datos_vigas!$B$6,0.0033*J12*K12)))) | Q12: 3 | R12: 12 | S12: =F12/(J12*0.85*K12) | T12: =G12/(J12*0.85*K12) | U12: 6 | V12: 30 | W12: =IF(OR(M12="REVISAR",P12="REVISAR"),"SECCION INSUF.",IF(NOT(AND(M12<>"REVISAR",P12<>"REVISAR",IF(ISNUMBER(M12),N12*PI()*(O12/10)^2/4>=M12,TRUE),IF(ISNUMBER(P12),Q12*PI()*(R12/10)^2/4>=P12,TRUE),IF(ISNUMBER(M12),M12<=0.0163*AB12*K12,TRUE),IF(ISNUMBER(P12),P12<=0.0163*AC12*K12,TRUE))),"NO VERIFICA FLEX.",IF(NOT(F12<=Datos_vigas!$B$9*(0.53*SQRT(Datos_vigas!$B$5)*J12*K12+2*PI()*(U12/10)^2/4*Datos_vigas!$B$6*K12/V12)),"NO VERIF. CORTE",IF(NOT(L12>=C12*100/VLOOKUP(Y12,Datos_vigas!$A$19:$E$23,5,0)),"VERIFICAR FLECHA","VERIFICA")))) | X12: Viga de borde: recibe la reaccion de la losa excentrica y queda sometida a TORSION, no verificada en esta planilla. | Y12: Continua | Z12: Invertida | AA12: 12 | AB12: =IF(Z12="Colgante",MIN(C12*100/4,J12+16*AA12),J12) | AC12: =IF(Z12="Invertida",MIN(C12*100/4,J12+16*AA12),J12) | AD12: 0 | AE12: 2.6 | AF12: 3
B13: VI 07c | C13: 8.6 | D13: =(Datos_vigas!$B$10*(VLOOKUP($A$4,Datos_vigas!$A$14:$E$15,2,0)*AD13+Datos_vigas!$B$7*J13*L13/10000+Datos_vigas!$B$16*AE13)+Datos_vigas!$B$11*VLOOKUP($A$4,Datos_vigas!$A$14:$E$15,3,0)*AD13) | F13: =VLOOKUP(Y13,Datos_vigas!$A$19:$E$23,4,0)*D13*C13 | G13: =F13 | H13: =VLOOKUP(Y13,Datos_vigas!$A$19:$E$23,2,0)*D13*C13^2 | I13: =IF(VLOOKUP(Y13,Datos_vigas!$A$19:$E$23,3,0)=0,"---",VLOOKUP(Y13,Datos_vigas!$A$19:$E$23,3,0)*D13*C13^2) | J13: 15 | K13: =L13-AF13 | L13: 70 | M13: =IF(NOT(ISNUMBER(H13)),"---",IF(H13<=0,"---",IF(H13*100/(Datos_vigas!$B$8*AB13*K13^2*Datos_vigas!$B$5)>=0.5,"REVISAR",MAX((1-SQRT(1-2*H13*100/(Datos_vigas!$B$8*AB13*K13^2*Datos_vigas!$B$5)))*AB13*K13*Datos_vigas!$B$5/Datos_vigas!$B$6,0.0033*J13*K13)))) | N13: 4 | O13: 20 | P13: =IF(NOT(ISNUMBER(I13)),"---",IF(I13<=0,"---",IF(I13*100/(Datos_vigas!$B$8*AC13*K13^2*Datos_vigas!$B$5)>=0.5,"REVISAR",MAX((1-SQRT(1-2*I13*100/(Datos_vigas!$B$8*AC13*K13^2*Datos_vigas!$B$5)))*AC13*K13*Datos_vigas!$B$5/Datos_vigas!$B$6,0.0033*J13*K13)))) | Q13: 4 | R13: 25 | S13: =F13/(J13*0.85*K13) | T13: =G13/(J13*0.85*K13) | U13: 8 | V13: 10 | W13: =IF(OR(M13="REVISAR",P13="REVISAR"),"SECCION INSUF.",IF(NOT(AND(M13<>"REVISAR",P13<>"REVISAR",IF(ISNUMBER(M13),N13*PI()*(O13/10)^2/4>=M13,TRUE),IF(ISNUMBER(P13),Q13*PI()*(R13/10)^2/4>=P13,TRUE),IF(ISNUMBER(M13),M13<=0.0163*AB13*K13,TRUE),IF(ISNUMBER(P13),P13<=0.0163*AC13*K13,TRUE))),"NO VERIFICA FLEX.",IF(NOT(F13<=Datos_vigas!$B$9*(0.53*SQRT(Datos_vigas!$B$5)*J13*K13+2*PI()*(U13/10)^2/4*Datos_vigas!$B$6*K13/V13)),"NO VERIF. CORTE",IF(NOT(L13>=C13*100/VLOOKUP(Y13,Datos_vigas!$A$19:$E$23,5,0)),"VERIFICAR FLECHA","VERIFICA")))) | X13: Armadura en 2 capas (rec. 6 cm). Apoya en columna COL 02 de 15x30 y en el tabique T05b. Viga de borde: recibe la reaccion de la losa excentrica y queda sometida a TORSION, no verificada en esta planilla. | Y13: Empotrada-apoyada | Z13: Invertida | AA13: 12 | AB13: =IF(Z13="Colgante",MIN(C13*100/4,J13+16*AA13),J13) | AC13: =IF(Z13="Invertida",MIN(C13*100/4,J13+16*AA13),J13) | AD13: 3.71 | AE13: 2.6 | AF13: 6
B14: VI 08a | C14: 3.65 | D14: =(Datos_vigas!$B$10*(VLOOKUP($A$4,Datos_vigas!$A$14:$E$15,2,0)*AD14+Datos_vigas!$B$7*J14*L14/10000+Datos_vigas!$B$16*AE14)+Datos_vigas!$B$11*VLOOKUP($A$4,Datos_vigas!$A$14:$E$15,3,0)*AD14) | F14: =VLOOKUP(Y14,Datos_vigas!$A$19:$E$23,4,0)*D14*C14 | G14: =F14 | H14: =VLOOKUP(Y14,Datos_vigas!$A$19:$E$23,2,0)*D14*C14^2 | I14: =IF(VLOOKUP(Y14,Datos_vigas!$A$19:$E$23,3,0)=0,"---",VLOOKUP(Y14,Datos_vigas!$A$19:$E$23,3,0)*D14*C14^2) | J14: 15 | K14: =L14-AF14 | L14: 70 | M14: =IF(NOT(ISNUMBER(H14)),"---",IF(H14<=0,"---",IF(H14*100/(Datos_vigas!$B$8*AB14*K14^2*Datos_vigas!$B$5)>=0.5,"REVISAR",MAX((1-SQRT(1-2*H14*100/(Datos_vigas!$B$8*AB14*K14^2*Datos_vigas!$B$5)))*AB14*K14*Datos_vigas!$B$5/Datos_vigas!$B$6,0.0033*J14*K14)))) | N14: 3 | O14: 12 | P14: =IF(NOT(ISNUMBER(I14)),"---",IF(I14<=0,"---",IF(I14*100/(Datos_vigas!$B$8*AC14*K14^2*Datos_vigas!$B$5)>=0.5,"REVISAR",MAX((1-SQRT(1-2*I14*100/(Datos_vigas!$B$8*AC14*K14^2*Datos_vigas!$B$5)))*AC14*K14*Datos_vigas!$B$5/Datos_vigas!$B$6,0.0033*J14*K14)))) | Q14: 3 | R14: 12 | S14: =F14/(J14*0.85*K14) | T14: =G14/(J14*0.85*K14) | U14: 6 | V14: 30 | W14: =IF(OR(M14="REVISAR",P14="REVISAR"),"SECCION INSUF.",IF(NOT(AND(M14<>"REVISAR",P14<>"REVISAR",IF(ISNUMBER(M14),N14*PI()*(O14/10)^2/4>=M14,TRUE),IF(ISNUMBER(P14),Q14*PI()*(R14/10)^2/4>=P14,TRUE),IF(ISNUMBER(M14),M14<=0.0163*AB14*K14,TRUE),IF(ISNUMBER(P14),P14<=0.0163*AC14*K14,TRUE))),"NO VERIFICA FLEX.",IF(NOT(F14<=Datos_vigas!$B$9*(0.53*SQRT(Datos_vigas!$B$5)*J14*K14+2*PI()*(U14/10)^2/4*Datos_vigas!$B$6*K14/V14)),"NO VERIF. CORTE",IF(NOT(L14>=C14*100/VLOOKUP(Y14,Datos_vigas!$A$19:$E$23,5,0)),"VERIFICAR FLECHA","VERIFICA")))) | Y14: Continua | Z14: Invertida | AA14: 12 | AB14: =IF(Z14="Colgante",MIN(C14*100/4,J14+16*AA14),J14) | AC14: =IF(Z14="Invertida",MIN(C14*100/4,J14+16*AA14),J14) | AD14: 1.065 | AE14: 2.6 | AF14: 3
B15: VI 08b | C15: 4.87 | D15: =(Datos_vigas!$B$10*(VLOOKUP($A$4,Datos_vigas!$A$14:$E$15,2,0)*AD15+Datos_vigas!$B$7*J15*L15/10000+Datos_vigas!$B$16*AE15)+Datos_vigas!$B$11*VLOOKUP($A$4,Datos_vigas!$A$14:$E$15,3,0)*AD15) | F15: =VLOOKUP(Y15,Datos_vigas!$A$19:$E$23,4,0)*D15*C15 | G15: =F15 | H15: =VLOOKUP(Y15,Datos_vigas!$A$19:$E$23,2,0)*D15*C15^2 | I15: =IF(VLOOKUP(Y15,Datos_vigas!$A$19:$E$23,3,0)=0,"---",VLOOKUP(Y15,Datos_vigas!$A$19:$E$23,3,0)*D15*C15^2) | J15: 15 | K15: =L15-AF15 | L15: 70 | M15: =IF(NOT(ISNUMBER(H15)),"---",IF(H15<=0,"---",IF(H15*100/(Datos_vigas!$B$8*AB15*K15^2*Datos_vigas!$B$5)>=0.5,"REVISAR",MAX((1-SQRT(1-2*H15*100/(Datos_vigas!$B$8*AB15*K15^2*Datos_vigas!$B$5)))*AB15*K15*Datos_vigas!$B$5/Datos_vigas!$B$6,0.0033*J15*K15)))) | N15: 3 | O15: 12 | P15: =IF(NOT(ISNUMBER(I15)),"---",IF(I15<=0,"---",IF(I15*100/(Datos_vigas!$B$8*AC15*K15^2*Datos_vigas!$B$5)>=0.5,"REVISAR",MAX((1-SQRT(1-2*I15*100/(Datos_vigas!$B$8*AC15*K15^2*Datos_vigas!$B$5)))*AC15*K15*Datos_vigas!$B$5/Datos_vigas!$B$6,0.0033*J15*K15)))) | Q15: 3 | R15: 12 | S15: =F15/(J15*0.85*K15) | T15: =G15/(J15*0.85*K15) | U15: 6 | V15: 30 | W15: =IF(OR(M15="REVISAR",P15="REVISAR"),"SECCION INSUF.",IF(NOT(AND(M15<>"REVISAR",P15<>"REVISAR",IF(ISNUMBER(M15),N15*PI()*(O15/10)^2/4>=M15,TRUE),IF(ISNUMBER(P15),Q15*PI()*(R15/10)^2/4>=P15,TRUE),IF(ISNUMBER(M15),M15<=0.0163*AB15*K15,TRUE),IF(ISNUMBER(P15),P15<=0.0163*AC15*K15,TRUE))),"NO VERIFICA FLEX.",IF(NOT(F15<=Datos_vigas!$B$9*(0.53*SQRT(Datos_vigas!$B$5)*J15*K15+2*PI()*(U15/10)^2/4*Datos_vigas!$B$6*K15/V15)),"NO VERIF. CORTE",IF(NOT(L15>=C15*100/VLOOKUP(Y15,Datos_vigas!$A$19:$E$23,5,0)),"VERIFICAR FLECHA","VERIFICA")))) | Y15: Continua | Z15: Invertida | AA15: 12 | AB15: =IF(Z15="Colgante",MIN(C15*100/4,J15+16*AA15),J15) | AC15: =IF(Z15="Invertida",MIN(C15*100/4,J15+16*AA15),J15) | AD15: 1.065 | AE15: 2.6 | AF15: 3
B16: VI 09 | C16: 4.87 | D16: =(Datos_vigas!$B$10*(VLOOKUP($A$4,Datos_vigas!$A$14:$E$15,2,0)*AD16+Datos_vigas!$B$7*J16*L16/10000+Datos_vigas!$B$16*AE16)+Datos_vigas!$B$11*VLOOKUP($A$4,Datos_vigas!$A$14:$E$15,3,0)*AD16) | F16: =VLOOKUP(Y16,Datos_vigas!$A$19:$E$23,4,0)*D16*C16 | G16: =F16 | H16: =VLOOKUP(Y16,Datos_vigas!$A$19:$E$23,2,0)*D16*C16^2 | I16: =IF(VLOOKUP(Y16,Datos_vigas!$A$19:$E$23,3,0)=0,"---",VLOOKUP(Y16,Datos_vigas!$A$19:$E$23,3,0)*D16*C16^2) | J16: 15 | K16: =L16-AF16 | L16: 70 | M16: =IF(NOT(ISNUMBER(H16)),"---",IF(H16<=0,"---",IF(H16*100/(Datos_vigas!$B$8*AB16*K16^2*Datos_vigas!$B$5)>=0.5,"REVISAR",MAX((1-SQRT(1-2*H16*100/(Datos_vigas!$B$8*AB16*K16^2*Datos_vigas!$B$5)))*AB16*K16*Datos_vigas!$B$5/Datos_vigas!$B$6,0.0033*J16*K16)))) | N16: 3 | O16: 12 | P16: =IF(NOT(ISNUMBER(I16)),"---",IF(I16<=0,"---",IF(I16*100/(Datos_vigas!$B$8*AC16*K16^2*Datos_vigas!$B$5)>=0.5,"REVISAR",MAX((1-SQRT(1-2*I16*100/(Datos_vigas!$B$8*AC16*K16^2*Datos_vigas!$B$5)))*AC16*K16*Datos_vigas!$B$5/Datos_vigas!$B$6,0.0033*J16*K16)))) | Q16: --- | R16: --- | S16: =F16/(J16*0.85*K16) | T16: =G16/(J16*0.85*K16) | U16: 6 | V16: 30 | W16: =IF(OR(M16="REVISAR",P16="REVISAR"),"SECCION INSUF.",IF(NOT(AND(M16<>"REVISAR",P16<>"REVISAR",IF(ISNUMBER(M16),N16*PI()*(O16/10)^2/4>=M16,TRUE),IF(ISNUMBER(P16),Q16*PI()*(R16/10)^2/4>=P16,TRUE),IF(ISNUMBER(M16),M16<=0.0163*AB16*K16,TRUE),IF(ISNUMBER(P16),P16<=0.0163*AC16*K16,TRUE))),"NO VERIFICA FLEX.",IF(NOT(F16<=Datos_vigas!$B$9*(0.53*SQRT(Datos_vigas!$B$5)*J16*K16+2*PI()*(U16/10)^2/4*Datos_vigas!$B$6*K16/V16)),"NO VERIF. CORTE",IF(NOT(L16>=C16*100/VLOOKUP(Y16,Datos_vigas!$A$19:$E$23,5,0)),"VERIFICAR FLECHA","VERIFICA")))) | Y16: Simplemente apoyada | Z16: Invertida | AA16: 12 | AB16: =IF(Z16="Colgante",MIN(C16*100/4,J16+16*AA16),J16) | AC16: =IF(Z16="Invertida",MIN(C16*100/4,J16+16*AA16),J16) | AD16: 1.549 | AE16: 2.6 | AF16: 3
B17: VI 10a | C17: 2.55 | D17: =(Datos_vigas!$B$10*(VLOOKUP($A$4,Datos_vigas!$A$14:$E$15,2,0)*AD17+Datos_vigas!$B$7*J17*L17/10000+Datos_vigas!$B$16*AE17)+Datos_vigas!$B$11*VLOOKUP($A$4,Datos_vigas!$A$14:$E$15,3,0)*AD17) | F17: =VLOOKUP(Y17,Datos_vigas!$A$19:$E$23,4,0)*D17*C17 | G17: =F17 | H17: =VLOOKUP(Y17,Datos_vigas!$A$19:$E$23,2,0)*D17*C17^2 | I17: =IF(VLOOKUP(Y17,Datos_vigas!$A$19:$E$23,3,0)=0,"---",VLOOKUP(Y17,Datos_vigas!$A$19:$E$23,3,0)*D17*C17^2) | J17: 15 | K17: =L17-AF17 | L17: 70 | M17: =IF(NOT(ISNUMBER(H17)),"---",IF(H17<=0,"---",IF(H17*100/(Datos_vigas!$B$8*AB17*K17^2*Datos_vigas!$B$5)>=0.5,"REVISAR",MAX((1-SQRT(1-2*H17*100/(Datos_vigas!$B$8*AB17*K17^2*Datos_vigas!$B$5)))*AB17*K17*Datos_vigas!$B$5/Datos_vigas!$B$6,0.0033*J17*K17)))) | N17: 3 | O17: 12 | P17: =IF(NOT(ISNUMBER(I17)),"---",IF(I17<=0,"---",IF(I17*100/(Datos_vigas!$B$8*AC17*K17^2*Datos_vigas!$B$5)>=0.5,"REVISAR",MAX((1-SQRT(1-2*I17*100/(Datos_vigas!$B$8*AC17*K17^2*Datos_vigas!$B$5)))*AC17*K17*Datos_vigas!$B$5/Datos_vigas!$B$6,0.0033*J17*K17)))) | Q17: 3 | R17: 12 | S17: =F17/(J17*0.85*K17) | T17: =G17/(J17*0.85*K17) | U17: 6 | V17: 30 | W17: =IF(OR(M17="REVISAR",P17="REVISAR"),"SECCION INSUF.",IF(NOT(AND(M17<>"REVISAR",P17<>"REVISAR",IF(ISNUMBER(M17),N17*PI()*(O17/10)^2/4>=M17,TRUE),IF(ISNUMBER(P17),Q17*PI()*(R17/10)^2/4>=P17,TRUE),IF(ISNUMBER(M17),M17<=0.0163*AB17*K17,TRUE),IF(ISNUMBER(P17),P17<=0.0163*AC17*K17,TRUE))),"NO VERIFICA FLEX.",IF(NOT(F17<=Datos_vigas!$B$9*(0.53*SQRT(Datos_vigas!$B$5)*J17*K17+2*PI()*(U17/10)^2/4*Datos_vigas!$B$6*K17/V17)),"NO VERIF. CORTE",IF(NOT(L17>=C17*100/VLOOKUP(Y17,Datos_vigas!$A$19:$E$23,5,0)),"VERIFICAR FLECHA","VERIFICA")))) | Y17: Continua | Z17: Invertida | AA17: 12 | AB17: =IF(Z17="Colgante",MIN(C17*100/4,J17+16*AA17),J17) | AC17: =IF(Z17="Invertida",MIN(C17*100/4,J17+16*AA17),J17) | AD17: 0 | AE17: 2.6 | AF17: 3
B18: VI 10b | C18: 4 | D18: =(Datos_vigas!$B$10*(VLOOKUP($A$4,Datos_vigas!$A$14:$E$15,2,0)*AD18+Datos_vigas!$B$7*J18*L18/10000+Datos_vigas!$B$16*AE18)+Datos_vigas!$B$11*VLOOKUP($A$4,Datos_vigas!$A$14:$E$15,3,0)*AD18) | F18: =VLOOKUP(Y18,Datos_vigas!$A$19:$E$23,4,0)*D18*C18 | G18: =F18 | H18: =VLOOKUP(Y18,Datos_vigas!$A$19:$E$23,2,0)*D18*C18^2 | I18: =IF(VLOOKUP(Y18,Datos_vigas!$A$19:$E$23,3,0)=0,"---",VLOOKUP(Y18,Datos_vigas!$A$19:$E$23,3,0)*D18*C18^2) | J18: 15 | K18: =L18-AF18 | L18: 70 | M18: =IF(NOT(ISNUMBER(H18)),"---",IF(H18<=0,"---",IF(H18*100/(Datos_vigas!$B$8*AB18*K18^2*Datos_vigas!$B$5)>=0.5,"REVISAR",MAX((1-SQRT(1-2*H18*100/(Datos_vigas!$B$8*AB18*K18^2*Datos_vigas!$B$5)))*AB18*K18*Datos_vigas!$B$5/Datos_vigas!$B$6,0.0033*J18*K18)))) | N18: 3 | O18: 12 | P18: =IF(NOT(ISNUMBER(I18)),"---",IF(I18<=0,"---",IF(I18*100/(Datos_vigas!$B$8*AC18*K18^2*Datos_vigas!$B$5)>=0.5,"REVISAR",MAX((1-SQRT(1-2*I18*100/(Datos_vigas!$B$8*AC18*K18^2*Datos_vigas!$B$5)))*AC18*K18*Datos_vigas!$B$5/Datos_vigas!$B$6,0.0033*J18*K18)))) | Q18: 3 | R18: 12 | S18: =F18/(J18*0.85*K18) | T18: =G18/(J18*0.85*K18) | U18: 6 | V18: 30 | W18: =IF(OR(M18="REVISAR",P18="REVISAR"),"SECCION INSUF.",IF(NOT(AND(M18<>"REVISAR",P18<>"REVISAR",IF(ISNUMBER(M18),N18*PI()*(O18/10)^2/4>=M18,TRUE),IF(ISNUMBER(P18),Q18*PI()*(R18/10)^2/4>=P18,TRUE),IF(ISNUMBER(M18),M18<=0.0163*AB18*K18,TRUE),IF(ISNUMBER(P18),P18<=0.0163*AC18*K18,TRUE))),"NO VERIFICA FLEX.",IF(NOT(F18<=Datos_vigas!$B$9*(0.53*SQRT(Datos_vigas!$B$5)*J18*K18+2*PI()*(U18/10)^2/4*Datos_vigas!$B$6*K18/V18)),"NO VERIF. CORTE",IF(NOT(L18>=C18*100/VLOOKUP(Y18,Datos_vigas!$A$19:$E$23,5,0)),"VERIFICAR FLECHA","VERIFICA")))) | Y18: Continua | Z18: Invertida | AA18: 12 | AB18: =IF(Z18="Colgante",MIN(C18*100/4,J18+16*AA18),J18) | AC18: =IF(Z18="Invertida",MIN(C18*100/4,J18+16*AA18),J18) | AD18: 1.825 | AE18: 2.6 | AF18: 3
B19: VI 10c | C19: 3.6 | D19: =(Datos_vigas!$B$10*(VLOOKUP($A$4,Datos_vigas!$A$14:$E$15,2,0)*AD19+Datos_vigas!$B$7*J19*L19/10000+Datos_vigas!$B$16*AE19)+Datos_vigas!$B$11*VLOOKUP($A$4,Datos_vigas!$A$14:$E$15,3,0)*AD19) | F19: =VLOOKUP(Y19,Datos_vigas!$A$19:$E$23,4,0)*D19*C19 | G19: =F19 | H19: =VLOOKUP(Y19,Datos_vigas!$A$19:$E$23,2,0)*D19*C19^2 | I19: =IF(VLOOKUP(Y19,Datos_vigas!$A$19:$E$23,3,0)=0,"---",VLOOKUP(Y19,Datos_vigas!$A$19:$E$23,3,0)*D19*C19^2) | J19: 15 | K19: =L19-AF19 | L19: 70 | M19: =IF(NOT(ISNUMBER(H19)),"---",IF(H19<=0,"---",IF(H19*100/(Datos_vigas!$B$8*AB19*K19^2*Datos_vigas!$B$5)>=0.5,"REVISAR",MAX((1-SQRT(1-2*H19*100/(Datos_vigas!$B$8*AB19*K19^2*Datos_vigas!$B$5)))*AB19*K19*Datos_vigas!$B$5/Datos_vigas!$B$6,0.0033*J19*K19)))) | N19: 3 | O19: 12 | P19: =IF(NOT(ISNUMBER(I19)),"---",IF(I19<=0,"---",IF(I19*100/(Datos_vigas!$B$8*AC19*K19^2*Datos_vigas!$B$5)>=0.5,"REVISAR",MAX((1-SQRT(1-2*I19*100/(Datos_vigas!$B$8*AC19*K19^2*Datos_vigas!$B$5)))*AC19*K19*Datos_vigas!$B$5/Datos_vigas!$B$6,0.0033*J19*K19)))) | Q19: 3 | R19: 12 | S19: =F19/(J19*0.85*K19) | T19: =G19/(J19*0.85*K19) | U19: 6 | V19: 30 | W19: =IF(OR(M19="REVISAR",P19="REVISAR"),"SECCION INSUF.",IF(NOT(AND(M19<>"REVISAR",P19<>"REVISAR",IF(ISNUMBER(M19),N19*PI()*(O19/10)^2/4>=M19,TRUE),IF(ISNUMBER(P19),Q19*PI()*(R19/10)^2/4>=P19,TRUE),IF(ISNUMBER(M19),M19<=0.0163*AB19*K19,TRUE),IF(ISNUMBER(P19),P19<=0.0163*AC19*K19,TRUE))),"NO VERIFICA FLEX.",IF(NOT(F19<=Datos_vigas!$B$9*(0.53*SQRT(Datos_vigas!$B$5)*J19*K19+2*PI()*(U19/10)^2/4*Datos_vigas!$B$6*K19/V19)),"NO VERIF. CORTE",IF(NOT(L19>=C19*100/VLOOKUP(Y19,Datos_vigas!$A$19:$E$23,5,0)),"VERIFICAR FLECHA","VERIFICA")))) | Y19: Continua | Z19: Invertida | AA19: 12 | AB19: =IF(Z19="Colgante",MIN(C19*100/4,J19+16*AA19),J19) | AC19: =IF(Z19="Invertida",MIN(C19*100/4,J19+16*AA19),J19) | AD19: 0 | AE19: 2.6 | AF19: 3
B20: VI 11a | C20: 7.68 | D20: =(Datos_vigas!$B$10*(VLOOKUP($A$4,Datos_vigas!$A$14:$E$15,2,0)*AD20+Datos_vigas!$B$7*J20*L20/10000+Datos_vigas!$B$16*AE20)+Datos_vigas!$B$11*VLOOKUP($A$4,Datos_vigas!$A$14:$E$15,3,0)*AD20) | F20: =VLOOKUP(Y20,Datos_vigas!$A$19:$E$23,4,0)*D20*C20 | G20: =F20 | H20: =VLOOKUP(Y20,Datos_vigas!$A$19:$E$23,2,0)*D20*C20^2 | I20: =IF(VLOOKUP(Y20,Datos_vigas!$A$19:$E$23,3,0)=0,"---",VLOOKUP(Y20,Datos_vigas!$A$19:$E$23,3,0)*D20*C20^2) | J20: 15 | K20: =L20-AF20 | L20: 70 | M20: =IF(NOT(ISNUMBER(H20)),"---",IF(H20<=0,"---",IF(H20*100/(Datos_vigas!$B$8*AB20*K20^2*Datos_vigas!$B$5)>=0.5,"REVISAR",MAX((1-SQRT(1-2*H20*100/(Datos_vigas!$B$8*AB20*K20^2*Datos_vigas!$B$5)))*AB20*K20*Datos_vigas!$B$5/Datos_vigas!$B$6,0.0033*J20*K20)))) | N20: 2 | O20: 20 | P20: =IF(NOT(ISNUMBER(I20)),"---",IF(I20<=0,"---",IF(I20*100/(Datos_vigas!$B$8*AC20*K20^2*Datos_vigas!$B$5)>=0.5,"REVISAR",MAX((1-SQRT(1-2*I20*100/(Datos_vigas!$B$8*AC20*K20^2*Datos_vigas!$B$5)))*AC20*K20*Datos_vigas!$B$5/Datos_vigas!$B$6,0.0033*J20*K20)))) | Q20: 2 | R20: 25 | S20: =F20/(J20*0.85*K20) | T20: =G20/(J20*0.85*K20) | U20: 6 | V20: 10 | W20: =IF(OR(M20="REVISAR",P20="REVISAR"),"SECCION INSUF.",IF(NOT(AND(M20<>"REVISAR",P20<>"REVISAR",IF(ISNUMBER(M20),N20*PI()*(O20/10)^2/4>=M20,TRUE),IF(ISNUMBER(P20),Q20*PI()*(R20/10)^2/4>=P20,TRUE),IF(ISNUMBER(M20),M20<=0.0163*AB20*K20,TRUE),IF(ISNUMBER(P20),P20<=0.0163*AC20*K20,TRUE))),"NO VERIFICA FLEX.",IF(NOT(F20<=Datos_vigas!$B$9*(0.53*SQRT(Datos_vigas!$B$5)*J20*K20+2*PI()*(U20/10)^2/4*Datos_vigas!$B$6*K20/V20)),"NO VERIF. CORTE",IF(NOT(L20>=C20*100/VLOOKUP(Y20,Datos_vigas!$A$19:$E$23,5,0)),"VERIFICAR FLECHA","VERIFICA")))) | X20: El plano rotula 'VI 111'; se interpreta 11a por el orden a-b-c. Sin apoyo intermedio, empotrada en tabiques. Apoya en columna COL 02 de 15x30 y en el tabique T08a. Viga de borde: recibe la reaccion de la losa excentrica y queda sometida a TORSION, no verificada en esta planilla. | Y20: Empotrada-apoyada | Z20: Invertida | AA20: 12 | AB20: =IF(Z20="Colgante",MIN(C20*100/4,J20+16*AA20),J20) | AC20: =IF(Z20="Invertida",MIN(C20*100/4,J20+16*AA20),J20) | AD20: 1.825 | AE20: 2.6 | AF20: 3
B21: VI 11b | C21: 3.45 | D21: =(Datos_vigas!$B$10*(VLOOKUP($A$4,Datos_vigas!$A$14:$E$15,2,0)*AD21+Datos_vigas!$B$7*J21*L21/10000+Datos_vigas!$B$16*AE21)+Datos_vigas!$B$11*VLOOKUP($A$4,Datos_vigas!$A$14:$E$15,3,0)*AD21) | F21: =VLOOKUP(Y21,Datos_vigas!$A$19:$E$23,4,0)*D21*C21 | G21: =F21 | H21: =VLOOKUP(Y21,Datos_vigas!$A$19:$E$23,2,0)*D21*C21^2 | I21: =IF(VLOOKUP(Y21,Datos_vigas!$A$19:$E$23,3,0)=0,"---",VLOOKUP(Y21,Datos_vigas!$A$19:$E$23,3,0)*D21*C21^2) | J21: 15 | K21: =L21-AF21 | L21: 70 | M21: =IF(NOT(ISNUMBER(H21)),"---",IF(H21<=0,"---",IF(H21*100/(Datos_vigas!$B$8*AB21*K21^2*Datos_vigas!$B$5)>=0.5,"REVISAR",MAX((1-SQRT(1-2*H21*100/(Datos_vigas!$B$8*AB21*K21^2*Datos_vigas!$B$5)))*AB21*K21*Datos_vigas!$B$5/Datos_vigas!$B$6,0.0033*J21*K21)))) | N21: 3 | O21: 12 | P21: =IF(NOT(ISNUMBER(I21)),"---",IF(I21<=0,"---",IF(I21*100/(Datos_vigas!$B$8*AC21*K21^2*Datos_vigas!$B$5)>=0.5,"REVISAR",MAX((1-SQRT(1-2*I21*100/(Datos_vigas!$B$8*AC21*K21^2*Datos_vigas!$B$5)))*AC21*K21*Datos_vigas!$B$5/Datos_vigas!$B$6,0.0033*J21*K21)))) | Q21: 3 | R21: 12 | S21: =F21/(J21*0.85*K21) | T21: =G21/(J21*0.85*K21) | U21: 6 | V21: 30 | W21: =IF(OR(M21="REVISAR",P21="REVISAR"),"SECCION INSUF.",IF(NOT(AND(M21<>"REVISAR",P21<>"REVISAR",IF(ISNUMBER(M21),N21*PI()*(O21/10)^2/4>=M21,TRUE),IF(ISNUMBER(P21),Q21*PI()*(R21/10)^2/4>=P21,TRUE),IF(ISNUMBER(M21),M21<=0.0163*AB21*K21,TRUE),IF(ISNUMBER(P21),P21<=0.0163*AC21*K21,TRUE))),"NO VERIFICA FLEX.",IF(NOT(F21<=Datos_vigas!$B$9*(0.53*SQRT(Datos_vigas!$B$5)*J21*K21+2*PI()*(U21/10)^2/4*Datos_vigas!$B$6*K21/V21)),"NO VERIF. CORTE",IF(NOT(L21>=C21*100/VLOOKUP(Y21,Datos_vigas!$A$19:$E$23,5,0)),"VERIFICAR FLECHA","VERIFICA")))) | X21: Viga de borde: recibe la reaccion de la losa excentrica y queda sometida a TORSION, no verificada en esta planilla. | Y21: Continua | Z21: Invertida | AA21: 12 | AB21: =IF(Z21="Colgante",MIN(C21*100/4,J21+16*AA21),J21) | AC21: =IF(Z21="Invertida",MIN(C21*100/4,J21+16*AA21),J21) | AD21: 0 | AE21: 2.6 | AF21: 3
B22: VI 11c | C22: 5.02 | D22: =(Datos_vigas!$B$10*(VLOOKUP($A$4,Datos_vigas!$A$14:$E$15,2,0)*AD22+Datos_vigas!$B$7*J22*L22/10000+Datos_vigas!$B$16*AE22)+Datos_vigas!$B$11*VLOOKUP($A$4,Datos_vigas!$A$14:$E$15,3,0)*AD22) | F22: =VLOOKUP(Y22,Datos_vigas!$A$19:$E$23,4,0)*D22*C22 | G22: =F22 | H22: =VLOOKUP(Y22,Datos_vigas!$A$19:$E$23,2,0)*D22*C22^2 | I22: =IF(VLOOKUP(Y22,Datos_vigas!$A$19:$E$23,3,0)=0,"---",VLOOKUP(Y22,Datos_vigas!$A$19:$E$23,3,0)*D22*C22^2) | J22: 15 | K22: =L22-AF22 | L22: 70 | M22: =IF(NOT(ISNUMBER(H22)),"---",IF(H22<=0,"---",IF(H22*100/(Datos_vigas!$B$8*AB22*K22^2*Datos_vigas!$B$5)>=0.5,"REVISAR",MAX((1-SQRT(1-2*H22*100/(Datos_vigas!$B$8*AB22*K22^2*Datos_vigas!$B$5)))*AB22*K22*Datos_vigas!$B$5/Datos_vigas!$B$6,0.0033*J22*K22)))) | N22: 3 | O22: 12 | P22: =IF(NOT(ISNUMBER(I22)),"---",IF(I22<=0,"---",IF(I22*100/(Datos_vigas!$B$8*AC22*K22^2*Datos_vigas!$B$5)>=0.5,"REVISAR",MAX((1-SQRT(1-2*I22*100/(Datos_vigas!$B$8*AC22*K22^2*Datos_vigas!$B$5)))*AC22*K22*Datos_vigas!$B$5/Datos_vigas!$B$6,0.0033*J22*K22)))) | Q22: 3 | R22: 12 | S22: =F22/(J22*0.85*K22) | T22: =G22/(J22*0.85*K22) | U22: 6 | V22: 30 | W22: =IF(OR(M22="REVISAR",P22="REVISAR"),"SECCION INSUF.",IF(NOT(AND(M22<>"REVISAR",P22<>"REVISAR",IF(ISNUMBER(M22),N22*PI()*(O22/10)^2/4>=M22,TRUE),IF(ISNUMBER(P22),Q22*PI()*(R22/10)^2/4>=P22,TRUE),IF(ISNUMBER(M22),M22<=0.0163*AB22*K22,TRUE),IF(ISNUMBER(P22),P22<=0.0163*AC22*K22,TRUE))),"NO VERIFICA FLEX.",IF(NOT(F22<=Datos_vigas!$B$9*(0.53*SQRT(Datos_vigas!$B$5)*J22*K22+2*PI()*(U22/10)^2/4*Datos_vigas!$B$6*K22/V22)),"NO VERIF. CORTE",IF(NOT(L22>=C22*100/VLOOKUP(Y22,Datos_vigas!$A$19:$E$23,5,0)),"VERIFICAR FLECHA","VERIFICA")))) | X22: Viga de borde: recibe la reaccion de la losa excentrica y queda sometida a TORSION, no verificada en esta planilla. | Y22: Continua | Z22: Invertida | AA22: 12 | AB22: =IF(Z22="Colgante",MIN(C22*100/4,J22+16*AA22),J22) | AC22: =IF(Z22="Invertida",MIN(C22*100/4,J22+16*AA22),J22) | AD22: 1.549 | AE22: 2.6 | AF22: 3
B23: VCH 03a | C23: 3.71 | D23: =(Datos_vigas!$B$10*(VLOOKUP($A$4,Datos_vigas!$A$14:$E$15,2,0)*AD23+Datos_vigas!$B$7*J23*L23/10000+Datos_vigas!$B$16*AE23)+Datos_vigas!$B$11*VLOOKUP($A$4,Datos_vigas!$A$14:$E$15,3,0)*AD23) | F23: =VLOOKUP(Y23,Datos_vigas!$A$19:$E$23,4,0)*D23*C23 | G23: =F23 | H23: =VLOOKUP(Y23,Datos_vigas!$A$19:$E$23,2,0)*D23*C23^2 | I23: =IF(VLOOKUP(Y23,Datos_vigas!$A$19:$E$23,3,0)=0,"---",VLOOKUP(Y23,Datos_vigas!$A$19:$E$23,3,0)*D23*C23^2) | J23: 40 | K23: =L23-AF23 | L23: 13 | M23: =IF(NOT(ISNUMBER(H23)),"---",IF(H23<=0,"---",IF(H23*100/(Datos_vigas!$B$8*AB23*K23^2*Datos_vigas!$B$5)>=0.5,"REVISAR",MAX((1-SQRT(1-2*H23*100/(Datos_vigas!$B$8*AB23*K23^2*Datos_vigas!$B$5)))*AB23*K23*Datos_vigas!$B$5/Datos_vigas!$B$6,0.0033*J23*K23)))) | N23: 8 | O23: 12 | P23: =IF(NOT(ISNUMBER(I23)),"---",IF(I23<=0,"---",IF(I23*100/(Datos_vigas!$B$8*AC23*K23^2*Datos_vigas!$B$5)>=0.5,"REVISAR",MAX((1-SQRT(1-2*I23*100/(Datos_vigas!$B$8*AC23*K23^2*Datos_vigas!$B$5)))*AC23*K23*Datos_vigas!$B$5/Datos_vigas!$B$6,0.0033*J23*K23)))) | Q23: 5 | R23: 6 | S23: =F23/(J23*0.85*K23) | T23: =G23/(J23*0.85*K23) | U23: 12 | V23: 5 | W23: =IF(OR(M23="REVISAR",P23="REVISAR"),"SECCION INSUF.",IF(NOT(AND(M23<>"REVISAR",P23<>"REVISAR",IF(ISNUMBER(M23),N23*PI()*(O23/10)^2/4>=M23,TRUE),IF(ISNUMBER(P23),Q23*PI()*(R23/10)^2/4>=P23,TRUE),IF(ISNUMBER(M23),M23<=0.0163*AB23*K23,TRUE),IF(ISNUMBER(P23),P23<=0.0163*AC23*K23,TRUE))),"NO VERIFICA FLEX.",IF(NOT(F23<=Datos_vigas!$B$9*(0.53*SQRT(Datos_vigas!$B$5)*J23*K23+2*PI()*(U23/10)^2/4*Datos_vigas!$B$6*K23/V23)),"NO VERIF. CORTE",IF(NOT(L23>=C23*100/VLOOKUP(Y23,Datos_vigas!$A$19:$E$23,5,0)),"VERIFICAR FLECHA","VERIFICA")))) | X23: Excede cuantia maxima y no llega a la altura minima por flecha. Revisar el ancho tributario real. Separacion de estribos menor a 10 cm: revisar constructividad. | Y23: Continua | Z23: Colgante | AA23: 12 | AB23: =IF(Z23="Colgante",MIN(C23*100/4,J23+16*AA23),J23) | AC23: =IF(Z23="Invertida",MIN(C23*100/4,J23+16*AA23),J23) | AD23: 2.1 | AE23: 2.6 | AF23: 3
B24: VCH 03b | C24: 2.13 | D24: =(Datos_vigas!$B$10*(VLOOKUP($A$4,Datos_vigas!$A$14:$E$15,2,0)*AD24+Datos_vigas!$B$7*J24*L24/10000+Datos_vigas!$B$16*AE24)+Datos_vigas!$B$11*VLOOKUP($A$4,Datos_vigas!$A$14:$E$15,3,0)*AD24) | F24: =VLOOKUP(Y24,Datos_vigas!$A$19:$E$23,4,0)*D24*C24 | G24: =F24 | H24: =VLOOKUP(Y24,Datos_vigas!$A$19:$E$23,2,0)*D24*C24^2 | I24: =IF(VLOOKUP(Y24,Datos_vigas!$A$19:$E$23,3,0)=0,"---",VLOOKUP(Y24,Datos_vigas!$A$19:$E$23,3,0)*D24*C24^2) | J24: 40 | K24: =L24-AF24 | L24: 13 | M24: =IF(NOT(ISNUMBER(H24)),"---",IF(H24<=0,"---",IF(H24*100/(Datos_vigas!$B$8*AB24*K24^2*Datos_vigas!$B$5)>=0.5,"REVISAR",MAX((1-SQRT(1-2*H24*100/(Datos_vigas!$B$8*AB24*K24^2*Datos_vigas!$B$5)))*AB24*K24*Datos_vigas!$B$5/Datos_vigas!$B$6,0.0033*J24*K24)))) | N24: 10 | O24: 6 | P24: =IF(NOT(ISNUMBER(I24)),"---",IF(I24<=0,"---",IF(I24*100/(Datos_vigas!$B$8*AC24*K24^2*Datos_vigas!$B$5)>=0.5,"REVISAR",MAX((1-SQRT(1-2*I24*100/(Datos_vigas!$B$8*AC24*K24^2*Datos_vigas!$B$5)))*AC24*K24*Datos_vigas!$B$5/Datos_vigas!$B$6,0.0033*J24*K24)))) | Q24: 8 | R24: 8 | S24: =F24/(J24*0.85*K24) | T24: =G24/(J24*0.85*K24) | U24: 12 | V24: 5 | W24: =IF(OR(M24="REVISAR",P24="REVISAR"),"SECCION INSUF.",IF(NOT(AND(M24<>"REVISAR",P24<>"REVISAR",IF(ISNUMBER(M24),N24*PI()*(O24/10)^2/4>=M24,TRUE),IF(ISNUMBER(P24),Q24*PI()*(R24/10)^2/4>=P24,TRUE),IF(ISNUMBER(M24),M24<=0.0163*AB24*K24,TRUE),IF(ISNUMBER(P24),P24<=0.0163*AC24*K24,TRUE))),"NO VERIFICA FLEX.",IF(NOT(F24<=Datos_vigas!$B$9*(0.53*SQRT(Datos_vigas!$B$5)*J24*K24+2*PI()*(U24/10)^2/4*Datos_vigas!$B$6*K24/V24)),"NO VERIF. CORTE",IF(NOT(L24>=C24*100/VLOOKUP(Y24,Datos_vigas!$A$19:$E$23,5,0)),"VERIFICAR FLECHA","VERIFICA")))) | X24: Separacion de estribos menor a 10 cm: revisar constructividad. | Y24: Continua | Z24: Colgante | AA24: 12 | AB24: =IF(Z24="Colgante",MIN(C24*100/4,J24+16*AA24),J24) | AC24: =IF(Z24="Invertida",MIN(C24*100/4,J24+16*AA24),J24) | AD24: 2.1 | AE24: 2.6 | AF24: 3
B25: VCH 05 | C25: 3.71 | D25: =(Datos_vigas!$B$10*(VLOOKUP($A$4,Datos_vigas!$A$14:$E$15,2,0)*AD25+Datos_vigas!$B$7*J25*L25/10000+Datos_vigas!$B$16*AE25)+Datos_vigas!$B$11*VLOOKUP($A$4,Datos_vigas!$A$14:$E$15,3,0)*AD25) | F25: =VLOOKUP(Y25,Datos_vigas!$A$19:$E$23,4,0)*D25*C25 | G25: =F25 | H25: =VLOOKUP(Y25,Datos_vigas!$A$19:$E$23,2,0)*D25*C25^2 | I25: =IF(VLOOKUP(Y25,Datos_vigas!$A$19:$E$23,3,0)=0,"---",VLOOKUP(Y25,Datos_vigas!$A$19:$E$23,3,0)*D25*C25^2) | J25: 12 | K25: =L25-AF25 | L25: 45 | M25: =IF(NOT(ISNUMBER(H25)),"---",IF(H25<=0,"---",IF(H25*100/(Datos_vigas!$B$8*AB25*K25^2*Datos_vigas!$B$5)>=0.5,"REVISAR",MAX((1-SQRT(1-2*H25*100/(Datos_vigas!$B$8*AB25*K25^2*Datos_vigas!$B$5)))*AB25*K25*Datos_vigas!$B$5/Datos_vigas!$B$6,0.0033*J25*K25)))) | N25: 2 | O25: 12 | P25: =IF(NOT(ISNUMBER(I25)),"---",IF(I25<=0,"---",IF(I25*100/(Datos_vigas!$B$8*AC25*K25^2*Datos_vigas!$B$5)>=0.5,"REVISAR",MAX((1-SQRT(1-2*I25*100/(Datos_vigas!$B$8*AC25*K25^2*Datos_vigas!$B$5)))*AC25*K25*Datos_vigas!$B$5/Datos_vigas!$B$6,0.0033*J25*K25)))) | Q25: --- | R25: --- | S25: =F25/(J25*0.85*K25) | T25: =G25/(J25*0.85*K25) | U25: 6 | V25: 20 | W25: =IF(OR(M25="REVISAR",P25="REVISAR"),"SECCION INSUF.",IF(NOT(AND(M25<>"REVISAR",P25<>"REVISAR",IF(ISNUMBER(M25),N25*PI()*(O25/10)^2/4>=M25,TRUE),IF(ISNUMBER(P25),Q25*PI()*(R25/10)^2/4>=P25,TRUE),IF(ISNUMBER(M25),M25<=0.0163*AB25*K25,TRUE),IF(ISNUMBER(P25),P25<=0.0163*AC25*K25,TRUE))),"NO VERIFICA FLEX.",IF(NOT(F25<=Datos_vigas!$B$9*(0.53*SQRT(Datos_vigas!$B$5)*J25*K25+2*PI()*(U25/10)^2/4*Datos_vigas!$B$6*K25/V25)),"NO VERIF. CORTE",IF(NOT(L25>=C25*100/VLOOKUP(Y25,Datos_vigas!$A$19:$E$23,5,0)),"VERIFICAR FLECHA","VERIFICA")))) | Y25: Simplemente apoyada | Z25: Colgante | AA25: 12 | AB25: =IF(Z25="Colgante",MIN(C25*100/4,J25+16*AA25),J25) | AC25: =IF(Z25="Invertida",MIN(C25*100/4,J25+16*AA25),J25) | AD25: 0 | AE25: 2.6 | AF25: 3
A26: TECHO | B26: VI 12 | C26: 9.9 | D26: =(Datos_vigas!$B$10*(VLOOKUP($A$26,Datos_vigas!$A$14:$E$15,2,0)*AD26+Datos_vigas!$B$7*J26*L26/10000+Datos_vigas!$B$16*AE26)+Datos_vigas!$B$11*VLOOKUP($A$26,Datos_vigas!$A$14:$E$15,3,0)*AD26) | F26: =VLOOKUP(Y26,Datos_vigas!$A$19:$E$23,4,0)*D26*C26 | G26: =F26 | H26: =VLOOKUP(Y26,Datos_vigas!$A$19:$E$23,2,0)*D26*C26^2 | I26: =IF(VLOOKUP(Y26,Datos_vigas!$A$19:$E$23,3,0)=0,"---",VLOOKUP(Y26,Datos_vigas!$A$19:$E$23,3,0)*D26*C26^2) | J26: 15 | K26: =L26-AF26 | L26: 70 | M26: =IF(NOT(ISNUMBER(H26)),"---",IF(H26<=0,"---",IF(H26*100/(Datos_vigas!$B$8*AB26*K26^2*Datos_vigas!$B$5)>=0.5,"REVISAR",MAX((1-SQRT(1-2*H26*100/(Datos_vigas!$B$8*AB26*K26^2*Datos_vigas!$B$5)))*AB26*K26*Datos_vigas!$B$5/Datos_vigas!$B$6,0.0033*J26*K26)))) | N26: 2 | O26: 25 | P26: =IF(NOT(ISNUMBER(I26)),"---",IF(I26<=0,"---",IF(I26*100/(Datos_vigas!$B$8*AC26*K26^2*Datos_vigas!$B$5)>=0.5,"REVISAR",MAX((1-SQRT(1-2*I26*100/(Datos_vigas!$B$8*AC26*K26^2*Datos_vigas!$B$5)))*AC26*K26*Datos_vigas!$B$5/Datos_vigas!$B$6,0.0033*J26*K26)))) | Q26: 2 | R26: 25 | S26: =F26/(J26*0.85*K26) | T26: =G26/(J26*0.85*K26) | U26: 6 | V26: 15 | W26: =IF(OR(M26="REVISAR",P26="REVISAR"),"SECCION INSUF.",IF(NOT(AND(M26<>"REVISAR",P26<>"REVISAR",IF(ISNUMBER(M26),N26*PI()*(O26/10)^2/4>=M26,TRUE),IF(ISNUMBER(P26),Q26*PI()*(R26/10)^2/4>=P26,TRUE),IF(ISNUMBER(M26),M26<=0.0163*AB26*K26,TRUE),IF(ISNUMBER(P26),P26<=0.0163*AC26*K26,TRUE))),"NO VERIFICA FLEX.",IF(NOT(F26<=Datos_vigas!$B$9*(0.53*SQRT(Datos_vigas!$B$5)*J26*K26+2*PI()*(U26/10)^2/4*Datos_vigas!$B$6*K26/V26)),"NO VERIF. CORTE",IF(NOT(L26>=C26*100/VLOOKUP(Y26,Datos_vigas!$A$19:$E$23,5,0)),"VERIFICAR FLECHA","VERIFICA")))) | Y26: Continua | Z26: Invertida | AA26: 12 | AB26: =IF(Z26="Colgante",MIN(C26*100/4,J26+16*AA26),J26) | AC26: =IF(Z26="Invertida",MIN(C26*100/4,J26+16*AA26),J26) | AD26: 2.1 | AE26: 1 | AF26: 3
B27: VI 13a | C27: 6 | D27: =(Datos_vigas!$B$10*(VLOOKUP($A$26,Datos_vigas!$A$14:$E$15,2,0)*AD27+Datos_vigas!$B$7*J27*L27/10000+Datos_vigas!$B$16*AE27)+Datos_vigas!$B$11*VLOOKUP($A$26,Datos_vigas!$A$14:$E$15,3,0)*AD27) | F27: =VLOOKUP(Y27,Datos_vigas!$A$19:$E$23,4,0)*D27*C27 | G27: =F27 | H27: =VLOOKUP(Y27,Datos_vigas!$A$19:$E$23,2,0)*D27*C27^2 | I27: =IF(VLOOKUP(Y27,Datos_vigas!$A$19:$E$23,3,0)=0,"---",VLOOKUP(Y27,Datos_vigas!$A$19:$E$23,3,0)*D27*C27^2) | J27: 15 | K27: =L27-AF27 | L27: 70 | M27: =IF(NOT(ISNUMBER(H27)),"---",IF(H27<=0,"---",IF(H27*100/(Datos_vigas!$B$8*AB27*K27^2*Datos_vigas!$B$5)>=0.5,"REVISAR",MAX((1-SQRT(1-2*H27*100/(Datos_vigas!$B$8*AB27*K27^2*Datos_vigas!$B$5)))*AB27*K27*Datos_vigas!$B$5/Datos_vigas!$B$6,0.0033*J27*K27)))) | N27: 2 | O27: 16 | P27: =IF(NOT(ISNUMBER(I27)),"---",IF(I27<=0,"---",IF(I27*100/(Datos_vigas!$B$8*AC27*K27^2*Datos_vigas!$B$5)>=0.5,"REVISAR",MAX((1-SQRT(1-2*I27*100/(Datos_vigas!$B$8*AC27*K27^2*Datos_vigas!$B$5)))*AC27*K27*Datos_vigas!$B$5/Datos_vigas!$B$6,0.0033*J27*K27)))) | Q27: 2 | R27: 20 | S27: =F27/(J27*0.85*K27) | T27: =G27/(J27*0.85*K27) | U27: 6 | V27: 15 | W27: =IF(OR(M27="REVISAR",P27="REVISAR"),"SECCION INSUF.",IF(NOT(AND(M27<>"REVISAR",P27<>"REVISAR",IF(ISNUMBER(M27),N27*PI()*(O27/10)^2/4>=M27,TRUE),IF(ISNUMBER(P27),Q27*PI()*(R27/10)^2/4>=P27,TRUE),IF(ISNUMBER(M27),M27<=0.0163*AB27*K27,TRUE),IF(ISNUMBER(P27),P27<=0.0163*AC27*K27,TRUE))),"NO VERIFICA FLEX.",IF(NOT(F27<=Datos_vigas!$B$9*(0.53*SQRT(Datos_vigas!$B$5)*J27*K27+2*PI()*(U27/10)^2/4*Datos_vigas!$B$6*K27/V27)),"NO VERIF. CORTE",IF(NOT(L27>=C27*100/VLOOKUP(Y27,Datos_vigas!$A$19:$E$23,5,0)),"VERIFICAR FLECHA","VERIFICA")))) | Y27: Continua | Z27: Invertida | AA27: 12 | AB27: =IF(Z27="Colgante",MIN(C27*100/4,J27+16*AA27),J27) | AC27: =IF(Z27="Invertida",MIN(C27*100/4,J27+16*AA27),J27) | AD27: 3.799 | AE27: 1 | AF27: 3
B28: VI 13b | C28: 3.75 | D28: =(Datos_vigas!$B$10*(VLOOKUP($A$26,Datos_vigas!$A$14:$E$15,2,0)*AD28+Datos_vigas!$B$7*J28*L28/10000+Datos_vigas!$B$16*AE28)+Datos_vigas!$B$11*VLOOKUP($A$26,Datos_vigas!$A$14:$E$15,3,0)*AD28) | F28: =VLOOKUP(Y28,Datos_vigas!$A$19:$E$23,4,0)*D28*C28 | G28: =F28 | H28: =VLOOKUP(Y28,Datos_vigas!$A$19:$E$23,2,0)*D28*C28^2 | I28: =IF(VLOOKUP(Y28,Datos_vigas!$A$19:$E$23,3,0)=0,"---",VLOOKUP(Y28,Datos_vigas!$A$19:$E$23,3,0)*D28*C28^2) | J28: 15 | K28: =L28-AF28 | L28: 70 | M28: =IF(NOT(ISNUMBER(H28)),"---",IF(H28<=0,"---",IF(H28*100/(Datos_vigas!$B$8*AB28*K28^2*Datos_vigas!$B$5)>=0.5,"REVISAR",MAX((1-SQRT(1-2*H28*100/(Datos_vigas!$B$8*AB28*K28^2*Datos_vigas!$B$5)))*AB28*K28*Datos_vigas!$B$5/Datos_vigas!$B$6,0.0033*J28*K28)))) | N28: 3 | O28: 12 | P28: =IF(NOT(ISNUMBER(I28)),"---",IF(I28<=0,"---",IF(I28*100/(Datos_vigas!$B$8*AC28*K28^2*Datos_vigas!$B$5)>=0.5,"REVISAR",MAX((1-SQRT(1-2*I28*100/(Datos_vigas!$B$8*AC28*K28^2*Datos_vigas!$B$5)))*AC28*K28*Datos_vigas!$B$5/Datos_vigas!$B$6,0.0033*J28*K28)))) | Q28: 3 | R28: 12 | S28: =F28/(J28*0.85*K28) | T28: =G28/(J28*0.85*K28) | U28: 6 | V28: 30 | W28: =IF(OR(M28="REVISAR",P28="REVISAR"),"SECCION INSUF.",IF(NOT(AND(M28<>"REVISAR",P28<>"REVISAR",IF(ISNUMBER(M28),N28*PI()*(O28/10)^2/4>=M28,TRUE),IF(ISNUMBER(P28),Q28*PI()*(R28/10)^2/4>=P28,TRUE),IF(ISNUMBER(M28),M28<=0.0163*AB28*K28,TRUE),IF(ISNUMBER(P28),P28<=0.0163*AC28*K28,TRUE))),"NO VERIFICA FLEX.",IF(NOT(F28<=Datos_vigas!$B$9*(0.53*SQRT(Datos_vigas!$B$5)*J28*K28+2*PI()*(U28/10)^2/4*Datos_vigas!$B$6*K28/V28)),"NO VERIF. CORTE",IF(NOT(L28>=C28*100/VLOOKUP(Y28,Datos_vigas!$A$19:$E$23,5,0)),"VERIFICAR FLECHA","VERIFICA")))) | Y28: Continua | Z28: Invertida | AA28: 12 | AB28: =IF(Z28="Colgante",MIN(C28*100/4,J28+16*AA28),J28) | AC28: =IF(Z28="Invertida",MIN(C28*100/4,J28+16*AA28),J28) | AD28: 2.1 | AE28: 1 | AF28: 3
B29: VI 14 | C29: 6 | D29: =(Datos_vigas!$B$10*(VLOOKUP($A$26,Datos_vigas!$A$14:$E$15,2,0)*AD29+Datos_vigas!$B$7*J29*L29/10000+Datos_vigas!$B$16*AE29)+Datos_vigas!$B$11*VLOOKUP($A$26,Datos_vigas!$A$14:$E$15,3,0)*AD29) | F29: =VLOOKUP(Y29,Datos_vigas!$A$19:$E$23,4,0)*D29*C29 | G29: =F29 | H29: =VLOOKUP(Y29,Datos_vigas!$A$19:$E$23,2,0)*D29*C29^2 | I29: =IF(VLOOKUP(Y29,Datos_vigas!$A$19:$E$23,3,0)=0,"---",VLOOKUP(Y29,Datos_vigas!$A$19:$E$23,3,0)*D29*C29^2) | J29: 15 | K29: =L29-AF29 | L29: 70 | M29: =IF(NOT(ISNUMBER(H29)),"---",IF(H29<=0,"---",IF(H29*100/(Datos_vigas!$B$8*AB29*K29^2*Datos_vigas!$B$5)>=0.5,"REVISAR",MAX((1-SQRT(1-2*H29*100/(Datos_vigas!$B$8*AB29*K29^2*Datos_vigas!$B$5)))*AB29*K29*Datos_vigas!$B$5/Datos_vigas!$B$6,0.0033*J29*K29)))) | N29: 3 | O29: 12 | P29: =IF(NOT(ISNUMBER(I29)),"---",IF(I29<=0,"---",IF(I29*100/(Datos_vigas!$B$8*AC29*K29^2*Datos_vigas!$B$5)>=0.5,"REVISAR",MAX((1-SQRT(1-2*I29*100/(Datos_vigas!$B$8*AC29*K29^2*Datos_vigas!$B$5)))*AC29*K29*Datos_vigas!$B$5/Datos_vigas!$B$6,0.0033*J29*K29)))) | Q29: 3 | R29: 12 | S29: =F29/(J29*0.85*K29) | T29: =G29/(J29*0.85*K29) | U29: 6 | V29: 30 | W29: =IF(OR(M29="REVISAR",P29="REVISAR"),"SECCION INSUF.",IF(NOT(AND(M29<>"REVISAR",P29<>"REVISAR",IF(ISNUMBER(M29),N29*PI()*(O29/10)^2/4>=M29,TRUE),IF(ISNUMBER(P29),Q29*PI()*(R29/10)^2/4>=P29,TRUE),IF(ISNUMBER(M29),M29<=0.0163*AB29*K29,TRUE),IF(ISNUMBER(P29),P29<=0.0163*AC29*K29,TRUE))),"NO VERIFICA FLEX.",IF(NOT(F29<=Datos_vigas!$B$9*(0.53*SQRT(Datos_vigas!$B$5)*J29*K29+2*PI()*(U29/10)^2/4*Datos_vigas!$B$6*K29/V29)),"NO VERIF. CORTE",IF(NOT(L29>=C29*100/VLOOKUP(Y29,Datos_vigas!$A$19:$E$23,5,0)),"VERIFICAR FLECHA","VERIFICA")))) | Y29: Continua | Z29: Invertida | AA29: 12 | AB29: =IF(Z29="Colgante",MIN(C29*100/4,J29+16*AA29),J29) | AC29: =IF(Z29="Invertida",MIN(C29*100/4,J29+16*AA29),J29) | AD29: 1.699 | AE29: 1 | AF29: 3
B30: VI 15a | C30: 4.03 | D30: =(Datos_vigas!$B$10*(VLOOKUP($A$26,Datos_vigas!$A$14:$E$15,2,0)*AD30+Datos_vigas!$B$7*J30*L30/10000+Datos_vigas!$B$16*AE30)+Datos_vigas!$B$11*VLOOKUP($A$26,Datos_vigas!$A$14:$E$15,3,0)*AD30) | F30: =VLOOKUP(Y30,Datos_vigas!$A$19:$E$23,4,0)*D30*C30 | G30: =F30 | H30: =VLOOKUP(Y30,Datos_vigas!$A$19:$E$23,2,0)*D30*C30^2 | I30: =IF(VLOOKUP(Y30,Datos_vigas!$A$19:$E$23,3,0)=0,"---",VLOOKUP(Y30,Datos_vigas!$A$19:$E$23,3,0)*D30*C30^2) | J30: 15 | K30: =L30-AF30 | L30: 70 | M30: =IF(NOT(ISNUMBER(H30)),"---",IF(H30<=0,"---",IF(H30*100/(Datos_vigas!$B$8*AB30*K30^2*Datos_vigas!$B$5)>=0.5,"REVISAR",MAX((1-SQRT(1-2*H30*100/(Datos_vigas!$B$8*AB30*K30^2*Datos_vigas!$B$5)))*AB30*K30*Datos_vigas!$B$5/Datos_vigas!$B$6,0.0033*J30*K30)))) | N30: 3 | O30: 12 | P30: =IF(NOT(ISNUMBER(I30)),"---",IF(I30<=0,"---",IF(I30*100/(Datos_vigas!$B$8*AC30*K30^2*Datos_vigas!$B$5)>=0.5,"REVISAR",MAX((1-SQRT(1-2*I30*100/(Datos_vigas!$B$8*AC30*K30^2*Datos_vigas!$B$5)))*AC30*K30*Datos_vigas!$B$5/Datos_vigas!$B$6,0.0033*J30*K30)))) | Q30: 3 | R30: 12 | S30: =F30/(J30*0.85*K30) | T30: =G30/(J30*0.85*K30) | U30: 6 | V30: 30 | W30: =IF(OR(M30="REVISAR",P30="REVISAR"),"SECCION INSUF.",IF(NOT(AND(M30<>"REVISAR",P30<>"REVISAR",IF(ISNUMBER(M30),N30*PI()*(O30/10)^2/4>=M30,TRUE),IF(ISNUMBER(P30),Q30*PI()*(R30/10)^2/4>=P30,TRUE),IF(ISNUMBER(M30),M30<=0.0163*AB30*K30,TRUE),IF(ISNUMBER(P30),P30<=0.0163*AC30*K30,TRUE))),"NO VERIFICA FLEX.",IF(NOT(F30<=Datos_vigas!$B$9*(0.53*SQRT(Datos_vigas!$B$5)*J30*K30+2*PI()*(U30/10)^2/4*Datos_vigas!$B$6*K30/V30)),"NO VERIF. CORTE",IF(NOT(L30>=C30*100/VLOOKUP(Y30,Datos_vigas!$A$19:$E$23,5,0)),"VERIFICAR FLECHA","VERIFICA")))) | X30: Viga de borde: recibe la reaccion de la losa excentrica y queda sometida a TORSION, no verificada en esta planilla. | Y30: Continua | Z30: Invertida | AA30: 12 | AB30: =IF(Z30="Colgante",MIN(C30*100/4,J30+16*AA30),J30) | AC30: =IF(Z30="Invertida",MIN(C30*100/4,J30+16*AA30),J30) | AD30: 0 | AE30: 1 | AF30: 3
B31: VI 15b | C31: 4.85 | D31: =(Datos_vigas!$B$10*(VLOOKUP($A$26,Datos_vigas!$A$14:$E$15,2,0)*AD31+Datos_vigas!$B$7*J31*L31/10000+Datos_vigas!$B$16*AE31)+Datos_vigas!$B$11*VLOOKUP($A$26,Datos_vigas!$A$14:$E$15,3,0)*AD31) | F31: =VLOOKUP(Y31,Datos_vigas!$A$19:$E$23,4,0)*D31*C31 | G31: =F31 | H31: =VLOOKUP(Y31,Datos_vigas!$A$19:$E$23,2,0)*D31*C31^2 | I31: =IF(VLOOKUP(Y31,Datos_vigas!$A$19:$E$23,3,0)=0,"---",VLOOKUP(Y31,Datos_vigas!$A$19:$E$23,3,0)*D31*C31^2) | J31: 15 | K31: =L31-AF31 | L31: 70 | M31: =IF(NOT(ISNUMBER(H31)),"---",IF(H31<=0,"---",IF(H31*100/(Datos_vigas!$B$8*AB31*K31^2*Datos_vigas!$B$5)>=0.5,"REVISAR",MAX((1-SQRT(1-2*H31*100/(Datos_vigas!$B$8*AB31*K31^2*Datos_vigas!$B$5)))*AB31*K31*Datos_vigas!$B$5/Datos_vigas!$B$6,0.0033*J31*K31)))) | N31: 3 | O31: 12 | P31: =IF(NOT(ISNUMBER(I31)),"---",IF(I31<=0,"---",IF(I31*100/(Datos_vigas!$B$8*AC31*K31^2*Datos_vigas!$B$5)>=0.5,"REVISAR",MAX((1-SQRT(1-2*I31*100/(Datos_vigas!$B$8*AC31*K31^2*Datos_vigas!$B$5)))*AC31*K31*Datos_vigas!$B$5/Datos_vigas!$B$6,0.0033*J31*K31)))) | Q31: 3 | R31: 12 | S31: =F31/(J31*0.85*K31) | T31: =G31/(J31*0.85*K31) | U31: 6 | V31: 30 | W31: =IF(OR(M31="REVISAR",P31="REVISAR"),"SECCION INSUF.",IF(NOT(AND(M31<>"REVISAR",P31<>"REVISAR",IF(ISNUMBER(M31),N31*PI()*(O31/10)^2/4>=M31,TRUE),IF(ISNUMBER(P31),Q31*PI()*(R31/10)^2/4>=P31,TRUE),IF(ISNUMBER(M31),M31<=0.0163*AB31*K31,TRUE),IF(ISNUMBER(P31),P31<=0.0163*AC31*K31,TRUE))),"NO VERIFICA FLEX.",IF(NOT(F31<=Datos_vigas!$B$9*(0.53*SQRT(Datos_vigas!$B$5)*J31*K31+2*PI()*(U31/10)^2/4*Datos_vigas!$B$6*K31/V31)),"NO VERIF. CORTE",IF(NOT(L31>=C31*100/VLOOKUP(Y31,Datos_vigas!$A$19:$E$23,5,0)),"VERIFICAR FLECHA","VERIFICA")))) | X31: Viga de borde: recibe la reaccion de la losa excentrica y queda sometida a TORSION, no verificada en esta planilla. | Y31: Continua | Z31: Invertida | AA31: 12 | AB31: =IF(Z31="Colgante",MIN(C31*100/4,J31+16*AA31),J31) | AC31: =IF(Z31="Invertida",MIN(C31*100/4,J31+16*AA31),J31) | AD31: 1.699 | AE31: 1 | AF31: 3
